Workbook
Name CECCZ: 'User Inputs and DR Shed Results'!#REF!
Name CEUSLargeOffice: 'Climate Zones'!#REF!
Name CEUSRetail: 'Climate Zones'!#REF!
Name CEUSSmallOffice: 'Climate Zones'!#REF!
Name CompressorOnly: 'User Inputs and DR Shed Results'!#REF!
Name CycleAvailPerc: 'User Inputs and DR Shed Results'!#REF!
Name CZ12CycleOnOff: 'LoadShed Database'!#REF!
Name CZ12TempReset: 'LoadShed Database'!#REF!
Name CZ13CycleOnOff: 'LoadShed Database'!#REF!
Name CZ13TempReset: 'LoadShed Database'!#REF!
Name DutyCycleMinutes: 'User Inputs and DR Shed Results'!#REF!
Name HvacDR: 'User Inputs and DR Shed Results'!#REF!
Name LargeOffice: 'Climate Zones'!#REF!
Name Retail: 'Climate Zones'!#REF!
Name SelectedEquations: 'Cycle Calculation'!#REF!
Name SmallOffice: 'Climate Zones'!#REF!
Name NamedRange1: 'LoadShed Database'!$A$3:$P$85
Name CZ04TempReset: #REF!
Name BuildingType: 'User Inputs and DR Shed Results'!$B$5
Name HOUSchoolTempReset: #REF!
Name CZ03CycleOnOff: 'LoadShed Database'!$A$87:$J$106
Name AvailPerc: 'User Inputs and DR Shed Results'!$B$26
Name TempResetDegrees: 'User Inputs and DR Shed Results'!$B$28
Name GTALoadShed: 'LoadShed Database'!$A$3:$P$85
Name HvacDRTYPE: 'Category Lists'!$N$4:$N$5
Name CITYCZ: 'User Inputs and DR Shed Results'!$B$14
Name BuildingVintage: 'User Inputs and DR Shed Results'!$B$6
Name CZ03TempReset: 'LoadShed Database'!$A$2:$J$85
Name NewCustomer: 'User Inputs and DR Shed Results'!$B$9
Name PGECZ: 'User Inputs and DR Shed Results'!$B$13
Name TempReset: shed_database!$B$2:$P$139
Name CZ04CycleOnOff: #REF!
Name ASHRAECZ: 'User Inputs and DR Shed Results'!$B$13
Name PrecoolDegrees: 'User Inputs and DR Shed Results'!$B$27
Name SASchoolTempReset: #REF!

Sheet Welcome to DR Tool
B1: ADR Estimation Tool Framework
B27: Instructions for LBNL ADR Tool V1.0:
B28: This tool provides DR shed magnitudes for a range of OATs for one of the major DR strategies: 1) HVAC Temp Reset (Precool with Zone Temp Setback).
B29: Step 1: Copy 15-min electricity meter data into the "IDAR Meter Data" sheet. First column is date and time in format "MM/DD/YYYY HH:MM". Second column is meter demand in units of kW in any number format.
B30: Step 2: In the "User Inputs and DR Shed Results" sheet's "ADR Site Description" block: 1. Enter the site name (if desired), 2. Select building type--Office or Retail, 3. Select HVAC type--Rooftop unit(s) or Central Plant and 4. Enter the site's zip code.
B31: Step 3:If HVAC temp reset is strategy of intereset, in the "User Inputs and DR Shed Results" sheet's "HVAC Temp Reset DR Shed Capacity Calculation": 1. Enter the percent of the floor area of the building for which the HVAC temp reset will be applied (0-100), 2. Select the "Precool Period Temp Offset"; either 0 or -2 °F, and 3. Select the "DR Event Period Temp Offset", either 2, 4, or 6 °F.
B32: Estimated kW sheds are calculated in tables and figures in "User Inputs and DR Shed Results".
B33: Temperature ranges shown in HVAC Temp Reset DR Shed Estimates (kW) are Peak Outside Air Temperatures on weekdays in the following ranges: 1 (60-65°F), 2 (65-70°F), 3 (70-75°F), 4 (75-80°F), 5 (80-85°F), 6 (85-90°F), and 7 (Above 90°F).
B35: Note: Only weekdays are selected for DR shed calculations. Weekends, holidays and ADR days in 2018 (if customer has enrolled into 2015 ADR programs) are excluded.

Sheet User Inputs and DR Shed Results
A2: User Inputs
A3: ADR Site Description | B3: Data | C3: Note
A4: Name | B4: Example
A5: Building Type | B5: Office
A6: Building Vintage | B6: Post1980
A7: HVAC Type | B7: Rooftop Unit | C7: RTU Duty Cycling is also available for HVAC Type " Rooftop Unit".
A8: Zipcode | B8: 1778
A9: NewCustomers | B9: Yes
A10: Peak Demand (kW) | B10: 240 | C10: Input from User
A12: County | B12: =IFERROR(VLOOKUP($B$8,'Climate Zones'!$A:$C,2,0),"") -> MIDDLESEX
A13: ASHRAE Climate Zone | B13: =IFERROR(VLOOKUP($B$8,'Climate Zones'!$A:$C,3,0),"") -> 5A
A14: City Zone | B14: =IFERROR(VLOOKUP($B$8,'Climate Zones'!$A:$D,4,0),"") -> n/a
A15: Building Type and Size | B15: =IF(B5="Office",IF(B10<200,"SmallOffice",IF(AND(B10>=200,B10<500),"MediumOffice",IF(B10>=500,"LargeOffice"))),IF(B10="Retail","Retail","SecondarySchool")) -> MediumOffice
A17: User Input of OAT and kW during the DR Event Hours
A18: Hours | B18: OAT (F) | C18: Meter kW
A19: 1 | B19: 100 | C19: 200
A20: 2 | B20: 98 | C20: 230
A21: 3 | B21: 87 | C21: 240
A22: 4 | B22: 87 | C22: 230
A24: DR Shed Results of HVAC Temperature Setpoint Reset
A25: HVAC Temp Reset DR Shed Capacity Calculation
A26: Percent of Bldg Floor Area that Temp Reset will Apply (0-100) | B26: 100
A27: Precool Period Temp Offset (°F) | B27: 0
A28: DR Event Period Temp Offset (°F) | B28: 2
A29: Average DR Potential (kW) | B29: =AVERAGE(C36:C38)*AvailPerc/100 -> 34.248599
A30: Min DR Potential (kW) | B30: =MIN(C36:C38)*AvailPerc/100 -> 25.069574
A31: Max DR Potential (kW) | B31: =MAX(C36:C38)*AvailPerc/100 -> 38.8455
A34: Estimated kW Shed during the DR Event Hours
A35: Hours | B35: OAT (F) | C35: Estimated kW Shed | D35: Estimated DR% | E35: Estimated DR_W/ft2
A36: =A19 -> 1 | B36: =B19 -> 100 | C36: ='GTA Calculation'!P3 -> 38.830724 | D36: ='GTA Calculation'!O3 -> 0.19415362 | E36: ='GTA Calculation'!Q3 -> 0.66305901
A37: =A20 -> 2 | B37: =B20 -> 98 | C37: ='GTA Calculation'!P4 -> 38.8455 | D37: ='GTA Calculation'!O4 -> 0.16889348 | E37: ='GTA Calculation'!Q4 -> 0.5514793
A38: =A21 -> 3 | B38: =B21 -> 87 | C38: ='GTA Calculation'!P5 -> 25.069574 | D38: ='GTA Calculation'!O5 -> 0.10445656 | E38: ='GTA Calculation'!Q5 -> 0.33907924
A39: =A22 -> 4 | B39: =B22 -> 87 | C39: ='GTA Calculation'!P6 -> 18.335575 | D39: ='GTA Calculation'!O6 -> 0.079719893 | E39: ='GTA Calculation'!Q6 -> 0.22691376

Sheet Option-2 VAV GTA, SP Reset (AHU
A1: DR strategy: VAV Global Temperature Adjustment and Static Pressure Reset | O1: Space Temperatures at 50% RH | P1: Air Density (lbm/ft^3) | Q1: Enthalpy (btu/lbm)
A2: user inputs | B2: post-inputs | C2: default input | D2: NO change | O2: 69 | P2: 0.0747 | Q2: 24.77
O3: 70 | P3: 0.0746 | Q3: 25.3
A4: Data Collection Table | E4: Typical Centrifugal Fan Efficiencies | O4: 71 | P4: 0.0744 | Q4: 25.84
A5: Field data needed (from audit) | B5: Data | C5: Data Sources | E5: Fan Type | F5: Small | G5: Large | O5: 72 | P5: 0.0743 | Q5: 26.39
A6: AHU Max Airflow (CFM) | B6: 140000 | C6: Blueprint, on site engineer, facility manager | E6: Forward curved | F6: 0.45 | G6: 0.5 | O6: 73 | P6: 0.0741 | Q6: 26.95
A7: Supply Fan Motor HP | B7: 200 | C7: Nameplate | E7: Backward curve or air-foil | F7: 0.5 | G7: 0.8 | O7: 74 | P7: 0.0739 | Q7: 27.52
A8: Total SF Static Pressure (in H2O) | B8: 4.25 | C8: Blueprint, on site engineer, facility manager | O8: 75 | P8: 0.0738 | Q8: 28.1
A9: External Static Pressure (in H2O) | B9: 2 | C9: Blueprint, on site engineer, facility manager | O9: 76 | P9: 0.0736 | Q9: 28.7
A10: Reset Static Pressure Value (in H2O) | B10: 4 | C10: Blueprint, on site engineer, facility manager | O10: 77 | P10: 0.0735 | Q10: 29.3
A11: Fan Efficiency | B11: 0.55 | C11: Fan specification, table to the right
A12: Motor Efficiency | B12: 0.917 | C12: Nameplate or EPAct Tables | F12: Packaged AC Unit Tons
A13: Cooling coil leaving air temperature (F) | B13: 53.5 | C13: Design blueprint | G13: CFM | H13: Motor Hp | I13: Motor Eff. | J13: Sensible Space Tons | K13: Total Space Tons | L13: OA min
A14: Normal space temp setting (F) | B14: 72 | C14: On-site engineer or facility manager | F14: RTU-1 | G14: 70000 | H14: =50*2 -> 100 | I14: 0.917 | J14: 160.66667 | K14: =2155/12 -> 179.58333 | L14: 17500
A15: Reset space temp setting (F) | B15: 76 | C15: On-site engineer or facility manager | F15: RTU-2 | G15: 70000 | H15: =50*2 -> 100 | I15: 0.917 | J15: 160.66667 | K15: =2155/12 -> 179.58333 | L15: 17500
A16: % reduction per degree | B16: 0.025 | C16: A "given" that is empirically derived | F16: Total | G16: =SUM(G14:G15) -> 140000 | H16: =SUM(H14:H15) -> 200 | J16: =SUM(J14:J15) -> 321.33333 | K16: =SUM(K14:K15) -> 359.16667 | L16: =SUM(L14:L15) -> 35000
A17: AC Unit Total Capacity (tons) | B17: =K16 -> 359.16667 | C17: On-site engineer or facility manager
A18: AC efficiency (kW/ton) | B18: =L23 -> 1.230148 | C18: On-site engineer or facility manager
A19: AC load factor (CSSB) | B19: 0.75 | C19: Plant operator, Interval data | F19: Packaged AC Unit Efficiency
A20: Air system minimum OSA (%) | B20: 0.25 | C20: On-site engineer or facility manager | G20: Comp RLA | H20: Fan FLA | I20: Tons | J20: Comp kW | K20: Cond kW | L20: kW/Ton
A21: % Return Air | B21: =1-B20 -> 0.75 | C21: Calculated: 100% - % OSA | F21: RTU-1 | G21: =2*60.4+2*75.9 -> 272.6 | H21: =2*37.2 -> 74.4 | I21: =K14 -> 179.58333 | J21: =460*G21*1.73/1000*0.8 -> 173.54806 | K21: =460*H21*1.73/1000*0.8 -> 47.366016 | L21: =(K21+J21)/I21 -> 1.230148
A22: Additional Field Data | B22: Data | C22: Data Sources | F22: RTU-2 | G22: =2*60.4+2*75.9 -> 272.6 | H22: =2*37.2 -> 74.4 | I22: =K15 -> 179.58333 | J22: =460*G22*1.73/1000*0.8 -> 173.54806 | K22: =460*H22*1.73/1000*0.8 -> 47.366016 | L22: =(K22+J22)/I22 -> 1.230148
A23: Size of conditioned space (sq ft) | B23: 140000 | C23: Blueprints, Google Maps, Facility Personnel | F23: Total | G23: =SUM(G21:G22) -> 545.2 | H23: =SUM(H21:H22) -> 148.8 | I23: =SUM(I21:I22) -> 359.16667 | J23: =SUM(J21:J22) -> 347.09613 | K23: =SUM(K21:K22) -> 94.732032 | L23: =(K23+J23)/I23 -> 1.230148
A24: Height of conditioned space (ft) | B24: 8 | C24: Blueprints, Facility Personnel
A25: Air Density @ 72 F, 50% RH | B25: 0.0743 | C25: Psychrometric chart, lbm/ft3
A26: Enthalpy @ 72 F, 50% RH | B26: 26.39 | C26: Psychrometric chart, Btu/lbm
A27: Density @ 76 F, 50% RH | B27: 0.0736 | C27: Psychrometric chart, lbm/ft3 | F27: Space Temperatures at 50% RH | G27: Air Density (lbm/ft^3) | H27: Enthalpy (btu/lbm)
A28: Enthalpy @76 F, 50% RH | B28: 28.7 | C28: Psychrometric chart, Btu/lbm | F28: 69 | G28: 0.0747 | H28: 24.77
F29: 70 | G29: 0.0746 | H29: 25.3
F30: 71 | G30: 0.0744 | H30: 25.84
A31: Calculate Reduced CFM | F31: 72 | G31: 0.0743 | H31: 26.39
F32: 73 | G32: 0.0741 | H32: 26.95
A33: Btuh for Normal Space Temp = | B33: CFM x Delta-T x 1.08 | F33: 74 | G33: 0.0739 | H33: 27.52
A34: Normal State: Btuh for Normal Space Temp (72F) = | B34: =B6*(B14-B13)*1.08 -> 2797200 | C34: =B34/12000 -> 233.1 | F34: 75 | G34: 0.0738 | H34: 28.1
F35: 76 | G35: 0.0736 | H35: 28.7
A36: CFM for Reset Space Temp = | B36: Btuh / (Delta-T x 1.08) | F36: 77 | G36: 0.0735 | H36: 29.3
A37: CFM for Reset Space Temp = | B37: =B34/(1.08*(B15-B13)) -> 115111.11
A39: CFM Reduction from Space Temp Adjust | B39: =1-(B37/B6) -> 0.17777778
A42: Calculate Reduced kW from CFM Reduction (SP handled next)
A44: Air Power kW = | B44: CFM x SP x 0.747
...

Sheet Category Lists
A2: Facility Type | D2: Dim % | F2: Y/N | H2: Precool °F | J2: Reset °F | L2: Duty Cycle | N2: HVAC DR Type | P2: HVAC Type | R2: PreviousDR | T2: Building Vintage
A4: Office | B4: OFF | D4: 20 | F4: Yes | H4: 0 | J4: 2 | L4: 15 | N4: HVAC Temp Reset | P4: Rooftop Unit | R4: Yes | T4: Pre1980
A5: Retail | B5: RETL | D5: 30 | F5: No | H5: -2 | J5: 3 | L5: 20 | N5: Duty Cycle | R5: No | T5: Post1980
D6: 40 | J6: 4 | L6: 30
J7: 5
J8: 6

Sheet LoadShed Database
B1: Massachusetts - ASHRAE - 5A
B2: SmallOffice | C2: MA | E2: OAT<=75°F | G2: 75°F<=OAT<95°F | I2: OAT>=95°F | K2: OAT<=75°F | M2: 75°F<=OAT<95°F | O2: OAT>=95°F
A3: Case ID | B3: Precool (°F) | C3: Temp Reset (°F) | D3: DR Event Hour (2PM to 6PM) | E3: Equation_Slope | F3: Equation_Intercept | G3: Equation_Slope | H3: Equation_Intercept | I3: Equation_Slope | J3: Equation_Intercept | K3: Equation_Slope | L3: Equation_Intercept | M3: Equation_Slope | N3: Equation_Intercept | O3: Equation_Slope | P3: Equation_Intercept
A4: =$C$2&$B$2& B4& C4&D4 -> MASmallOffice021 | B4: 0 | C4: 2 | D4: 1 | E4: 0.28821123 | F4: -10.79282 | G4: -0.10025999 | H4: 17.753688 | I4: 0 | J4: 0 | K4: 0.010569397 | L4: -0.4842187 | M4: 0.0014050839 | N4: 0.18911278 | O4: 0 | P4: 0
A5: =$C$2&$B$2& B5& C5&D5 -> MASmallOffice022 | B5: 0 | C5: 2 | D5: 2 | E5: 0.18461831 | F5: -5.5830399 | G5: -0.049340154 | H5: 11.125807 | I5: 0 | J5: 0 | K5: 0.0074081378 | L5: -0.31789758 | M5: 0.0019342865 | N5: 0.067976962 | O5: 0 | P5: 0
A6: =$C$2&$B$2& B6& C6&D6 -> MASmallOffice023 | B6: 0 | C6: 2 | D6: 3 | E6: 0.15028536 | F6: -3.9833062 | G6: -0.06851423 | H6: 11.808513 | I6: 0 | J6: 0 | K6: 0.0062388616 | L6: -0.25760568 | M6: 0.001250219 | N6: 0.096342548 | O6: 0 | P6: 0
A7: =$C$2&$B$2& B7& C7&D7 -> MASmallOffice024 | B7: 0 | C7: 2 | D7: 4 | E7: 0.34796811 | F7: -16.356483 | G7: -0.124068 | H7: 17.567449 | I7: 0 | J7: 0 | K7: 0.0087923579 | L7: -0.4465373 | M7: 0.0014686568 | N7: 0.073873614 | O7: 0 | P7: 0
A8: =$C$2&$B$2& B8& C8&D8 -> MASmallOffice031 | B8: 0 | C8: 3 | D8: 1 | E8: 0.5494904 | F8: -24.43133 | G8: -0.12571887 | H8: 24.312254 | I8: 0 | J8: 0 | K8: 0.018433141 | L8: -0.9076205 | M8: 0.0027014213 | N8: 0.22577174 | O8: 0 | P8: 0
A9: =$C$2&$B$2& B9& C9&D9 -> MASmallOffice032 | B9: 0 | C9: 3 | D9: 2 | E9: 0.3395693 | F9: -12.946343 | G9: -0.053118791 | H9: 14.972655 | I9: 0 | J9: 0 | K9: 0.012424821 | L9: -0.57338184 | M9: 0.0034889588 | N9: 0.053947666 | O9: 0 | P9: 0
A10: =$C$2&$B$2& B10& C10&D10 -> MASmallOffice033 | B10: 0 | C10: 3 | D10: 3 | E10: 0.26943507 | F10: -9.1657656 | G10: -0.094421888 | H10: 17.049712 | I10: 0 | J10: 0 | K10: 0.010311908 | L10: -0.45563168 | M10: 0.0020873835 | N10: 0.12790911 | O10: 0 | P10: 0
A11: =$C$2&$B$2& B11& C11&D11 -> MASmallOffice034 | B11: 0 | C11: 3 | D11: 4 | E11: 0.55741478 | F11: -27.317078 | G11: -0.19219191 | H11: 26.831369 | I11: 0 | J11: 0 | K11: 0.013762027 | L11: -0.71535078 | M11: 0.0020706682 | N11: 0.12119987 | O11: 0 | P11: 0
A12: =$C$2&$B$2& B12& C12&D12 -> MASmallOffice041 | B12: 0 | C12: 4 | D12: 1 | E12: 0.83902331 | F12: -40.66216 | G12: -0.0123793 | H12: 20.073836 | I12: 0 | J12: 0 | K12: 0.026878471 | L12: -1.3872016 | M12: 0.008435118 | N12: -0.081708184 | O12: 0 | P12: 0
A13: =$C$2&$B$2& B13& C13&D13 -> MASmallOffice042 | B13: 0 | C13: 4 | D13: 2 | E13: 0.52840786 | F13: -22.931013 | G13: -0.040691144 | H13: 17.4457 | I13: 0 | J13: 0 | K13: 0.018140717 | L13: -0.88409907 | M13: 0.005468751 | N13: 0.0037040941 | O13: 0 | P13: 0
A14: =$C$2&$B$2& B14& C14&D14 -> MASmallOffice043 | B14: 0 | C14: 4 | D14: 3 | E14: 0.43155249 | F14: -17.498856 | G14: -0.10693749 | H14: 21.184314 | I14: 0 | J14: 0 | K14: 0.015318752 | L14: -0.72249414 | M14: 0.0032656139 | N14: 0.13127866 | O14: 0 | P14: 0
A15: =$C$2&$B$2& B15& C15&D15 -> MASmallOffice044 | B15: 0 | C15: 4 | D15: 4 | E15: 0.77563375 | F15: -39.176523 | G15: -0.24271192 | H15: 34.61536 | I15: 0 | J15: 0 | K15: 0.018837084 | L15: -0.99694865 | M15: 0.002985883 | N15: 0.14199397 | O15: 0 | P15: 0
... A43: =$C$2&$B$2& B43& C43&D43 -> MASmallOffice-264 | B43: -2 | C43: 6 | D43: 4 | E43: 1.3203731 | F43: -70.389087 | G43: -0.30326894 | H43: 48.004503 | I43: 0 | J43: 0 | K43: 0.031166125 | L43: -1.707715 | M43: 0.0058535027 | N43: 0.1287646 | O43: 0 | P43: 0
B44: MediumOffice | E44: OAT<=75°F | G44: 75°F<=OAT<95°F | I44: OAT>=95°F | K44: OAT<=75°F | M44: 75°F<=OAT<95°F | O44: OAT>=95°F
A45: Case ID | B45: Precool (°F) | C45: Temp Reset (°F) | D45: DR Event Hour | E45: Equation_Slope | F45: Equation_Intercept | G45: Equation_Slope | H45: Equation_Intercept | I45: Equation_Slope | J45: Equation_Intercept | K45: Equation_Slope | L45: Equation_Intercept | M45: Equation_Slope | N45: Equation_Intercept | O45: Equation_Slope | P45: Equation_Intercept
A46: =$C$2&$B$44& B46& C46&D46 -> MAMediumOffice021 | B46: 0 | C46: 2 | D46: 1 | E46: 0.18420911 | F46: -11.378267 | G46: 0.67482956 | H46: -48.067594 | I46: 0 | J46: 0 | K46: 0.00466623 | L46: -0.27525381 | M46: 0.02401971 | N46: -1.738912 | O46: 0 | P46: 0
A47: =$C$2&$B$44& B47& C47&D47 -> MAMediumOffice022 | B47: 0 | C47: 2 | D47: 2 | E47: 0.20084993 | F47: -11.955881 | G47: 0.57600708 | H47: -39.559346 | I47: 0 | J47: 0 | K47: 0.005419852 | L47: -0.31982299 | M47: 0.020036085 | N47: -1.412057 | O47: 0 | P47: 0
A48: =$C$2&$B$44& B48& C48&D48 -> MAMediumOffice023 | B48: 0 | C48: 2 | D48: 3 | E48: 0.21857673 | F48: -12.839549 | G48: 0.54745263 | H48: -37.182723 | I48: 0 | J48: 0 | K48: 0.0061879733 | L48: -0.35760201 | M48: 0.019650201 | N48: -1.3704882 | O48: 0 | P48: 0
A49: =$C$2&$B$44& B49& C49&D49 -> MAMediumOffice024 | B49: 0 | C49: 2 | D49: 4 | E49: 0.1182332 | F49: -7.3471989 | G49: 0.47611389 | H49: -33.449919 | I49: 0 | J49: 0 | K49: 0.0019996008 | L49: -0.10594209 | M49: 0.015025252 | N49: -1.0802832 | O49: 0 | P49: 0
A50: =$C$2&$B$44& B50& C50&D50 -> MAMediumOffice031 | B50: 0 | C50: 3 | D50: 1 | E50: 0.18933403 | F50: -11.684031 | G50: 0.78028783 | H50: -56.054924 | I50: 0 | J50: 0 | K50: 0.0047979295 | L50: -0.28313585 | M50: 0.027554533 | N50: -2.0078862 | O50: 0 | P50: 0
A51: =$C$2&$B$44& B51& C51&D51 -> MAMediumOffice032 | B51: 0 | C51: 3 | D51: 2 | E51: 0.20695318 | F51: -12.327024 | G51: 0.73397514 | H51: -51.442832 | I51: 0 | J51: 0 | K51: 0.0055780021 | L51: -0.32945054 | M51: 0.025237189 | N51: -1.8048141 | O51: 0 | P51: 0
A52: =$C$2&$B$44& B52& C52&D52 -> MAMediumOffice033 | B52: 0 | C52: 3 | D52: 3 | E52: 0.22529175 | F52: -13.243677 | G52: 0.74604324 | H52: -52.015307 | I52: 0 | J52: 0 | K52: 0.0063679423 | L52: -0.3684395 | M52: 0.026256672 | N52: -1.8659392 | O52: 0 | P52: 0
A53: =$C$2&$B$44& B53& C53&D53 -> MAMediumOffice034 | B53: 0 | C53: 3 | D53: 4 | E53: 0.12420995 | F53: -7.7002499 | G53: 0.59338819 | H53: -42.155899 | I53: 0 | J53: 0 | K53: 0.0021333685 | L53: -0.11385905 | M53: 0.018524422 | N53: -1.3423941 | O53: 0 | P53: 0
A54: =$C$2&$B$44& B54& C54&D54 -> MAMediumOffice041 | B54: 0 | C54: 4 | D54: 1 | E54: 0.18985891 | F54: -11.715881 | G54: 0.81690408 | H54: -58.86689 | I54: 0 | J54: 0 | K54: 0.0048110359 | L54: -0.28393119 | M54: 0.028776523 | N54: -2.1020408 | O54: 0 | P54: 0
A55: =$C$2&$B$44& B55& C55&D55 -> MAMediumOffice042 | B55: 0 | C55: 4 | D55: 2 | E55: 0.20748329 | F55: -12.359092 | G55: 0.79866775 | H55: -56.409024 | I55: 0 | J55: 0 | K55: 0.0055913541 | L55: -0.33025836 | M55: 0.027375319 | N55: -1.9692884 | O55: 0 | P55: 0
A56: =$C$2&$B$44& B56& C56&D56 -> MAMediumOffice043 | B56: 0 | C56: 4 | D56: 3 | E56: 0.22625642 | F56: -13.302636 | G56: 0.82905926 | H56: -58.322143 | I56: 0 | J56: 0 | K56: 0.0063935554 | L56: -0.37000461 | M56: 0.029016999 | N56: -2.0761491 | O56: 0 | P56: 0
A57: =$C$2&$B$44& B57& C57&D57 -> MAMediumOffice044 | B57: 0 | C57: 4 | D57: 4 | E57: 0.1255593 | F57: -7.7817352 | G57: 0.65894122 | H57: -47.045138 | I57: 0 | J57: 0 | K57: 0.0021621342 | L57: -0.11559524 | M57: 0.020391825 | N57: -1.4827595 | O57: 0 | P57: 0
... A85: =$C$2&$B$44& B85& C85&D85 -> MAMediumOffice-264 | B85: -2 | C85: 6 | D85: 4 | E85: 0.11506962 | F85: -6.809406 | G85: 0.73756895 | H85: -52.964821 | I85: 0 | J85: 0 | K85: 0.0025728967 | L85: -0.14239896 | M85: 0.022595896 | N85: -1.649698 | O85: 0 | P85: 0
B87: SmallOffice | C87: CZ03 | E87: OAT<=75°F | G87: 75°F<=OAT<95°F | I87: OAT>=95°F
A88: Case ID | B88: Duty Cycle (minutes off/hr) | C88: CompressorOnly | D88: DR Event Hour (2PM to 6PM) | E88: Equation_Slope | F88: Equation_Intercept | G88: Equation_Slope | H88: Equation_Intercept | I88: Equation_Slope | J88: Equation_Intercept
A89: =$B$87&$C$2&B89&C89&D89 -> SmallOfficeMACycleYes1 | B89: Cycle | C89: Yes | D89: 1 | E89: 0.75697147 | F89: -34.889875 | G89: 0.50820922 | H89: -16.558269 | I89: 0 | J89: 0
A90: =$B$87&$C$2&B90&C90&D90 -> SmallOfficeMACycleYes2 | B90: Cycle | C90: Yes | D90: 2 | E90: 0.80036279 | F90: -37.022101 | G90: 0.53292825 | H90: -17.998064 | I90: 0 | J90: 0
A91: =$B$87&$C$2&B91&C91&D91 -> SmallOfficeMACycleYes3 | B91: Cycle | C91: Yes | D91: 3 | E91: 0.73820294 | F91: -32.227329 | G91: 0.52386122 | H91: -17.163002 | I91: 0 | J91: 0
A92: =$B$87&$C$2&B92&C92&D92 -> SmallOfficeMACycleYes4 | B92: Cycle | C92: Yes | D92: 4 | E92: 0.88021945 | F92: -40.562207 | G92: 0.067125288 | H92: 21.111265 | I92: 0 | J92: 0
A93: =$B$87&$C$2&B93&C93&D93 -> SmallOfficeMACycleNo1 | B93: Cycle | C93: No | D93: 1 | E93: 0.60836197 | F93: -8.4081421 | G93: 0.40843701 | H93: 6.3245822 | I93: 0 | J93: 0
A94: =$B$87&$C$2&B94&C94&D94 -> SmallOfficeMACycleNo2 | B94: Cycle | C94: No | D94: 2 | E94: 0.64323466 | F94: -10.121767 | G94: 0.42830317 | H94: 5.1674492 | I94: 0 | J94: 0
A95: =$B$87&$C$2&B95&C95&D95 -> SmallOfficeMACycleNo3 | B95: Cycle | C95: No | D95: 3 | E95: 0.5932781 | F95: -6.2683101 | G95: 0.4210162 | H95: 5.8385708 | I95: 0 | J95: 0
...

Sheet Climate Zones
A1: ZIP | B1: COUNTY_NAME | C1: ASHRAE_ZONE | D1: COUNTY | E1: CZ_ZONE
A2: 2351 | B2: PLYMOUTH | C2: 5A | D2: n/a
A3: 2018 | B3: PLYMOUTH | C3: 5A | D3: n/a
A4: 1720 | B4: MIDDLESEX | C4: 5A | D4: n/a
A5: 2743 | B5: BRISTOL | C5: 5A | D5: n/a
A6: 1220 | B6: BERKSHIRE | C6: 5A | D6: n/a
A7: 1001 | B7: HAMPDEN | C7: 5A | D7: n/a
A8: 2134 | B8: SUFFOLK | C8: 5A | D8: n/a
A9: 1913 | B9: ESSEX | C9: 5A | D9: n/a
A10: 1002 | B10: HAMPSHIRE | C10: 5A | D10: n/a
A11: 1003 | B11: HAMPSHIRE | C11: 5A | D11: n/a
A12: 1004 | B12: HAMPSHIRE | C12: 5A | D12: n/a
A13: 1810 | B13: ESSEX | C13: 5A | D13: n/a
... A666: 2675 | B666: BARNSTABLE | C666: 5A | D666: n/a

Sheet Cycle Calculation
A1: ='User Inputs and DR Shed Results'!B15 -> MediumOffice | B1: =CECCZ -> #NAME? | G1: Duty Cycle (minutes off/hr) | H1: =CompressorOnly -> #NAME?
A2: Date | B2: TempRange | C2: hour | D2: power | E2: oat | F2: range | G2: Cycle | H2: =DutyCycleMinutes -> #NAME? | I2: DR% | J2: DR (kW)
B3: =#REF! -> #REF! | C3: 1 | D3: =#REF! -> #REF! | E3: =#REF! -> #REF! | F3: =IF(E3<75,1,IF(AND(E3>=75, E3<95),2,IF(E3>=95,3))) -> #REF! | G3: =IF($B$1="CZ03",VLOOKUP($A$1&CECCZ&$G$2&CompressorOnly&$C3,CZ03CycleOnOff,7,0),IF($B$1="CZ04",VLOOKUP($A$1&CECCZ&$G$2&CompressorOnly&$C3,CZ04CycleOnOff,7,0),IF(CECCZ="CZ12",VLOOKUP($A$1&CECCZ&$G$2&CompressorOnly&$C3,CZ12CycleOnOff,7,0),IF(CECCZ="CZ13",VLOOKUP($A$1&CECCZ&$G$2&CompressorOnly&$C3,CZ13CycleOnOff,7,0))))) -> #NAME? | H3: =IF(CECCZ="CZ03",VLOOKUP($A$1&CECCZ&$G$2&CompressorOnly&$C3,CZ03CycleOnOff,8,0),IF(CECCZ="CZ04",VLOOKUP($A$1&CECCZ&$G$2&CompressorOnly&$C3,CZ04CycleOnOff,8,0),IF(CECCZ="CZ12",VLOOKUP($A$1&CECCZ&$G$2&CompressorOnly&$C3,CZ12CycleOnOff,8,0),IF(CECCZ="CZ13",VLOOKUP($A$1&CECCZ&$G$2&CompressorOnly&$C3,CZ13CycleOnOff,8,0))))) -> #NAME? | I3: =(E3*G3+H3)/100*DutyCycleMinutes/60 -> #REF! | J3: =I3*D3 -> #REF!
B4: =#REF! -> #REF! | C4: 1 | D4: =#REF! -> #REF! | E4: =#REF! -> #REF! | F4: =IF(E4<75,1,IF(AND(E4>=75, E4<95),2,IF(E4>=95,3))) -> #REF! | G4: =IF($B$1="CZ03",VLOOKUP($A$1&CECCZ&$G$2&CompressorOnly&$C4,CZ03CycleOnOff,7,0),IF($B$1="CZ04",VLOOKUP($A$1&CECCZ&$G$2&CompressorOnly&$C4,CZ04CycleOnOff,7,0),IF(CECCZ="CZ12",VLOOKUP($A$1&CECCZ&$G$2&CompressorOnly&$C4,CZ12CycleOnOff,7,0),IF(CECCZ="CZ13",VLOOKUP($A$1&CECCZ&$G$2&CompressorOnly&$C4,CZ13CycleOnOff,7,0))))) -> #NAME? | H4: =IF(CECCZ="CZ03",VLOOKUP($A$1&CECCZ&$G$2&CompressorOnly&$C4,CZ03CycleOnOff,8,0),IF(CECCZ="CZ04",VLOOKUP($A$1&CECCZ&$G$2&CompressorOnly&$C4,CZ04CycleOnOff,8,0),IF(CECCZ="CZ12",VLOOKUP($A$1&CECCZ&$G$2&CompressorOnly&$C4,CZ12CycleOnOff,8,0),IF(CECCZ="CZ13",VLOOKUP($A$1&CECCZ&$G$2&CompressorOnly&$C4,CZ13CycleOnOff,8,0))))) -> #NAME? | I4: =(E4*G4+H4)/100*DutyCycleMinutes/60 -> #REF! | J4: =I4*D4 -> #REF!
B5: =#REF! -> #REF! | C5: 1 | D5: =#REF! -> #REF! | E5: =#REF! -> #REF! | F5: =IF(E5<75,1,IF(AND(E5>=75, E5<95),2,IF(E5>=95,3))) -> #REF! | G5: =IF($B$1="CZ03",VLOOKUP($A$1&CECCZ&$G$2&CompressorOnly&$C5,CZ03CycleOnOff,7,0),IF($B$1="CZ04",VLOOKUP($A$1&CECCZ&$G$2&CompressorOnly&$C5,CZ04CycleOnOff,7,0),IF(CECCZ="CZ12",VLOOKUP($A$1&CECCZ&$G$2&CompressorOnly&$C5,CZ12CycleOnOff,7,0),IF(CECCZ="CZ13",VLOOKUP($A$1&CECCZ&$G$2&CompressorOnly&$C5,CZ13CycleOnOff,7,0))))) -> #NAME? | H5: =IF(CECCZ="CZ03",VLOOKUP($A$1&CECCZ&$G$2&CompressorOnly&$C5,CZ03CycleOnOff,8,0),IF(CECCZ="CZ04",VLOOKUP($A$1&CECCZ&$G$2&CompressorOnly&$C5,CZ04CycleOnOff,8,0),IF(CECCZ="CZ12",VLOOKUP($A$1&CECCZ&$G$2&CompressorOnly&$C5,CZ12CycleOnOff,8,0),IF(CECCZ="CZ13",VLOOKUP($A$1&CECCZ&$G$2&CompressorOnly&$C5,CZ13CycleOnOff,8,0))))) -> #NAME? | I5: =(E5*G5+H5)/100*DutyCycleMinutes/60 -> #REF! | J5: =I5*D5 -> #REF!
B6: =#REF! -> #REF! | C6: 1 | D6: =#REF! -> #REF! | E6: =#REF! -> #REF! | F6: =IF(E6<75,1,IF(AND(E6>=75, E6<95),2,IF(E6>=95,3))) -> #REF! | G6: =IF($B$1="CZ03",VLOOKUP($A$1&CECCZ&$G$2&CompressorOnly&$C6,CZ03CycleOnOff,7,0),IF($B$1="CZ04",VLOOKUP($A$1&CECCZ&$G$2&CompressorOnly&$C6,CZ04CycleOnOff,7,0),IF(CECCZ="CZ12",VLOOKUP($A$1&CECCZ&$G$2&CompressorOnly&$C6,CZ12CycleOnOff,7,0),IF(CECCZ="CZ13",VLOOKUP($A$1&CECCZ&$G$2&CompressorOnly&$C6,CZ13CycleOnOff,7,0))))) -> #NAME? | H6: =IF(CECCZ="CZ03",VLOOKUP($A$1&CECCZ&$G$2&CompressorOnly&$C6,CZ03CycleOnOff,8,0),IF(CECCZ="CZ04",VLOOKUP($A$1&CECCZ&$G$2&CompressorOnly&$C6,CZ04CycleOnOff,8,0),IF(CECCZ="CZ12",VLOOKUP($A$1&CECCZ&$G$2&CompressorOnly&$C6,CZ12CycleOnOff,8,0),IF(CECCZ="CZ13",VLOOKUP($A$1&CECCZ&$G$2&CompressorOnly&$C6,CZ13CycleOnOff,8,0))))) -> #NAME? | I6: =(E6*G6+H6)/100*DutyCycleMinutes/60 -> #REF! | J6: =I6*D6 -> #REF!
B7: =#REF! -> #REF! | C7: 2 | D7: =#REF! -> #REF! | E7: =#REF! -> #REF! | F7: =IF(E7<75,1,IF(AND(E7>=75, E7<95),2,IF(E7>=95,3))) -> #REF! | G7: =IF($B$1="CZ03",VLOOKUP($A$1&CECCZ&$G$2&CompressorOnly&$C7,CZ03CycleOnOff,7,0),IF($B$1="CZ04",VLOOKUP($A$1&CECCZ&$G$2&CompressorOnly&$C7,CZ04CycleOnOff,7,0),IF(CECCZ="CZ12",VLOOKUP($A$1&CECCZ&$G$2&CompressorOnly&$C7,CZ12CycleOnOff,7,0),IF(CECCZ="CZ13",VLOOKUP($A$1&CECCZ&$G$2&CompressorOnly&$C7,CZ13CycleOnOff,7,0))))) -> #NAME? | H7: =IF(CECCZ="CZ03",VLOOKUP($A$1&CECCZ&$G$2&CompressorOnly&$C7,CZ03CycleOnOff,8,0),IF(CECCZ="CZ04",VLOOKUP($A$1&CECCZ&$G$2&CompressorOnly&$C7,CZ04CycleOnOff,8,0),IF(CECCZ="CZ12",VLOOKUP($A$1&CECCZ&$G$2&CompressorOnly&$C7,CZ12CycleOnOff,8,0),IF(CECCZ="CZ13",VLOOKUP($A$1&CECCZ&$G$2&CompressorOnly&$C7,CZ13CycleOnOff,8,0))))) -> #NAME? | I7: =(E7*G7+H7)/100*DutyCycleMinutes/60 -> #REF! | J7: =I7*D7 -> #REF!
B8: =#REF! -> #REF! | C8: 2 | D8: =#REF! -> #REF! | E8: =#REF! -> #REF! | F8: =IF(E8<75,1,IF(AND(E8>=75, E8<95),2,IF(E8>=95,3))) -> #REF! | G8: =IF($B$1="CZ03",VLOOKUP($A$1&CECCZ&$G$2&CompressorOnly&$C8,CZ03CycleOnOff,7,0),IF($B$1="CZ04",VLOOKUP($A$1&CECCZ&$G$2&CompressorOnly&$C8,CZ04CycleOnOff,7,0),IF(CECCZ="CZ12",VLOOKUP($A$1&CECCZ&$G$2&CompressorOnly&$C8,CZ12CycleOnOff,7,0),IF(CECCZ="CZ13",VLOOKUP($A$1&CECCZ&$G$2&CompressorOnly&$C8,CZ13CycleOnOff,7,0))))) -> #NAME? | H8: =IF(CECCZ="CZ03",VLOOKUP($A$1&CECCZ&$G$2&CompressorOnly&$C8,CZ03CycleOnOff,8,0),IF(CECCZ="CZ04",VLOOKUP($A$1&CECCZ&$G$2&CompressorOnly&$C8,CZ04CycleOnOff,8,0),IF(CECCZ="CZ12",VLOOKUP($A$1&CECCZ&$G$2&CompressorOnly&$C8,CZ12CycleOnOff,8,0),IF(CECCZ="CZ13",VLOOKUP($A$1&CECCZ&$G$2&CompressorOnly&$C8,CZ13CycleOnOff,8,0))))) -> #NAME? | I8: =(E8*G8+H8)/100*DutyCycleMinutes/60 -> #REF! | J8: =I8*D8 -> #REF!
B9: =#REF! -> #REF! | C9: 2 | D9: =#REF! -> #REF! | E9: =#REF! -> #REF! | F9: =IF(E9<75,1,IF(AND(E9>=75, E9<95),2,IF(E9>=95,3))) -> #REF! | G9: =IF($B$1="CZ03",VLOOKUP($A$1&CECCZ&$G$2&CompressorOnly&$C9,CZ03CycleOnOff,7,0),IF($B$1="CZ04",VLOOKUP($A$1&CECCZ&$G$2&CompressorOnly&$C9,CZ04CycleOnOff,7,0),IF(CECCZ="CZ12",VLOOKUP($A$1&CECCZ&$G$2&CompressorOnly&$C9,CZ12CycleOnOff,7,0),IF(CECCZ="CZ13",VLOOKUP($A$1&CECCZ&$G$2&CompressorOnly&$C9,CZ13CycleOnOff,7,0))))) -> #NAME? | H9: =IF(CECCZ="CZ03",VLOOKUP($A$1&CECCZ&$G$2&CompressorOnly&$C9,CZ03CycleOnOff,8,0),IF(CECCZ="CZ04",VLOOKUP($A$1&CECCZ&$G$2&CompressorOnly&$C9,CZ04CycleOnOff,8,0),IF(CECCZ="CZ12",VLOOKUP($A$1&CECCZ&$G$2&CompressorOnly&$C9,CZ12CycleOnOff,8,0),IF(CECCZ="CZ13",VLOOKUP($A$1&CECCZ&$G$2&CompressorOnly&$C9,CZ13CycleOnOff,8,0))))) -> #NAME? | I9: =(E9*G9+H9)/100*DutyCycleMinutes/60 -> #REF! | J9: =I9*D9 -> #REF!
B10: =#REF! -> #REF! | C10: 2 | D10: =#REF! -> #REF! | E10: =#REF! -> #REF! | F10: =IF(E10<75,1,IF(AND(E10>=75, E10<95),2,IF(E10>=95,3))) -> #REF! | G10: =IF($B$1="CZ03",VLOOKUP($A$1&CECCZ&$G$2&CompressorOnly&$C10,CZ03CycleOnOff,7,0),IF($B$1="CZ04",VLOOKUP($A$1&CECCZ&$G$2&CompressorOnly&$C10,CZ04CycleOnOff,7,0),IF(CECCZ="CZ12",VLOOKUP($A$1&CECCZ&$G$2&CompressorOnly&$C10,CZ12CycleOnOff,7,0),IF(CECCZ="CZ13",VLOOKUP($A$1&CECCZ&$G$2&CompressorOnly&$C10,CZ13CycleOnOff,7,0))))) -> #NAME? | H10: =IF(CECCZ="CZ03",VLOOKUP($A$1&CECCZ&$G$2&CompressorOnly&$C10,CZ03CycleOnOff,8,0),IF(CECCZ="CZ04",VLOOKUP($A$1&CECCZ&$G$2&CompressorOnly&$C10,CZ04CycleOnOff,8,0),IF(CECCZ="CZ12",VLOOKUP($A$1&CECCZ&$G$2&CompressorOnly&$C10,CZ12CycleOnOff,8,0),IF(CECCZ="CZ13",VLOOKUP($A$1&CECCZ&$G$2&CompressorOnly&$C10,CZ13CycleOnOff,8,0))))) -> #NAME? | I10: =(E10*G10+H10)/100*DutyCycleMinutes/60 -> #REF! | J10: =I10*D10 -> #REF!
B11: =#REF! -> #REF! | C11: 3 | D11: =#REF! -> #REF! | E11: =#REF! -> #REF! | F11: =IF(E11<75,1,IF(AND(E11>=75, E11<95),2,IF(E11>=95,3))) -> #REF! | G11: =IF($B$1="CZ03",VLOOKUP($A$1&CECCZ&$G$2&CompressorOnly&$C11,CZ03CycleOnOff,7,0),IF($B$1="CZ04",VLOOKUP($A$1&CECCZ&$G$2&CompressorOnly&$C11,CZ04CycleOnOff,7,0),IF(CECCZ="CZ12",VLOOKUP($A$1&CECCZ&$G$2&CompressorOnly&$C11,CZ12CycleOnOff,7,0),IF(CECCZ="CZ13",VLOOKUP($A$1&CECCZ&$G$2&CompressorOnly&$C11,CZ13CycleOnOff,7,0))))) -> #NAME? | H11: =IF(CECCZ="CZ03",VLOOKUP($A$1&CECCZ&$G$2&CompressorOnly&$C11,CZ03CycleOnOff,8,0),IF(CECCZ="CZ04",VLOOKUP($A$1&CECCZ&$G$2&CompressorOnly&$C11,CZ04CycleOnOff,8,0),IF(CECCZ="CZ12",VLOOKUP($A$1&CECCZ&$G$2&CompressorOnly&$C11,CZ12CycleOnOff,8,0),IF(CECCZ="CZ13",VLOOKUP($A$1&CECCZ&$G$2&CompressorOnly&$C11,CZ13CycleOnOff,8,0))))) -> #NAME? | I11: =(E11*G11+H11)/100*DutyCycleMinutes/60 -> #REF! | J11: =I11*D11 -> #REF!
B12: =#REF! -> #REF! | C12: 3 | D12: =#REF! -> #REF! | E12: =#REF! -> #REF! | F12: =IF(E12<75,1,IF(AND(E12>=75, E12<95),2,IF(E12>=95,3))) -> #REF! | G12: =IF($B$1="CZ03",VLOOKUP($A$1&CECCZ&$G$2&CompressorOnly&$C12,CZ03CycleOnOff,7,0),IF($B$1="CZ04",VLOOKUP($A$1&CECCZ&$G$2&CompressorOnly&$C12,CZ04CycleOnOff,7,0),IF(CECCZ="CZ12",VLOOKUP($A$1&CECCZ&$G$2&CompressorOnly&$C12,CZ12CycleOnOff,7,0),IF(CECCZ="CZ13",VLOOKUP($A$1&CECCZ&$G$2&CompressorOnly&$C12,CZ13CycleOnOff,7,0))))) -> #NAME? | H12: =IF(CECCZ="CZ03",VLOOKUP($A$1&CECCZ&$G$2&CompressorOnly&$C12,CZ03CycleOnOff,8,0),IF(CECCZ="CZ04",VLOOKUP($A$1&CECCZ&$G$2&CompressorOnly&$C12,CZ04CycleOnOff,8,0),IF(CECCZ="CZ12",VLOOKUP($A$1&CECCZ&$G$2&CompressorOnly&$C12,CZ12CycleOnOff,8,0),IF(CECCZ="CZ13",VLOOKUP($A$1&CECCZ&$G$2&CompressorOnly&$C12,CZ13CycleOnOff,8,0))))) -> #NAME? | I12: =(E12*G12+H12)/100*DutyCycleMinutes/60 -> #REF! | J12: =I12*D12 -> #REF!
B13: =#REF! -> #REF! | C13: 3 | D13: =#REF! -> #REF! | E13: =#REF! -> #REF! | F13: =IF(E13<75,1,IF(AND(E13>=75, E13<95),2,IF(E13>=95,3))) -> #REF! | G13: =IF($B$1="CZ03",VLOOKUP($A$1&CECCZ&$G$2&CompressorOnly&$C13,CZ03CycleOnOff,7,0),IF($B$1="CZ04",VLOOKUP($A$1&CECCZ&$G$2&CompressorOnly&$C13,CZ04CycleOnOff,7,0),IF(CECCZ="CZ12",VLOOKUP($A$1&CECCZ&$G$2&CompressorOnly&$C13,CZ12CycleOnOff,7,0),IF(CECCZ="CZ13",VLOOKUP($A$1&CECCZ&$G$2&CompressorOnly&$C13,CZ13CycleOnOff,7,0))))) -> #NAME? | H13: =IF(CECCZ="CZ03",VLOOKUP($A$1&CECCZ&$G$2&CompressorOnly&$C13,CZ03CycleOnOff,8,0),IF(CECCZ="CZ04",VLOOKUP($A$1&CECCZ&$G$2&CompressorOnly&$C13,CZ04CycleOnOff,8,0),IF(CECCZ="CZ12",VLOOKUP($A$1&CECCZ&$G$2&CompressorOnly&$C13,CZ12CycleOnOff,8,0),IF(CECCZ="CZ13",VLOOKUP($A$1&CECCZ&$G$2&CompressorOnly&$C13,CZ13CycleOnOff,8,0))))) -> #NAME? | I13: =(E13*G13+H13)/100*DutyCycleMinutes/60 -> #REF! | J13: =I13*D13 -> #REF!
B14: =#REF! -> #REF! | C14: 3 | D14: =#REF! -> #REF! | E14: =#REF! -> #REF! | F14: =IF(E14<75,1,IF(AND(E14>=75, E14<95),2,IF(E14>=95,3))) -> #REF! | G14: =IF($B$1="CZ03",VLOOKUP($A$1&CECCZ&$G$2&CompressorOnly&$C14,CZ03CycleOnOff,7,0),IF($B$1="CZ04",VLOOKUP($A$1&CECCZ&$G$2&CompressorOnly&$C14,CZ04CycleOnOff,7,0),IF(CECCZ="CZ12",VLOOKUP($A$1&CECCZ&$G$2&CompressorOnly&$C14,CZ12CycleOnOff,7,0),IF(CECCZ="CZ13",VLOOKUP($A$1&CECCZ&$G$2&CompressorOnly&$C14,CZ13CycleOnOff,7,0))))) -> #NAME? | H14: =IF(CECCZ="CZ03",VLOOKUP($A$1&CECCZ&$G$2&CompressorOnly&$C14,CZ03CycleOnOff,8,0),IF(CECCZ="CZ04",VLOOKUP($A$1&CECCZ&$G$2&CompressorOnly&$C14,CZ04CycleOnOff,8,0),IF(CECCZ="CZ12",VLOOKUP($A$1&CECCZ&$G$2&CompressorOnly&$C14,CZ12CycleOnOff,8,0),IF(CECCZ="CZ13",VLOOKUP($A$1&CECCZ&$G$2&CompressorOnly&$C14,CZ13CycleOnOff,8,0))))) -> #NAME? | I14: =(E14*G14+H14)/100*DutyCycleMinutes/60 -> #REF! | J14: =I14*D14 -> #REF!
... B18: =#REF! -> #REF! | C18: 4 | D18: =#REF! -> #REF! | E18: =#REF! -> #REF! | F18: =IF(E18<75,1,IF(AND(E18>=75, E18<95),2,IF(E18>=95,3))) -> #REF! | G18: =IF($B$1="CZ03",VLOOKUP($A$1&CECCZ&$G$2&CompressorOnly&$C18,CZ03CycleOnOff,7,0),IF($B$1="CZ04",VLOOKUP($A$1&CECCZ&$G$2&CompressorOnly&$C18,CZ04CycleOnOff,7,0),IF(CECCZ="CZ12",VLOOKUP($A$1&CECCZ&$G$2&CompressorOnly&$C18,CZ12CycleOnOff,7,0),IF(CECCZ="CZ13",VLOOKUP($A$1&CECCZ&$G$2&CompressorOnly&$C18,CZ13CycleOnOff,7,0))))) -> #NAME? | H18: =IF(CECCZ="CZ03",VLOOKUP($A$1&CECCZ&$G$2&CompressorOnly&$C18,CZ03CycleOnOff,8,0),IF(CECCZ="CZ04",VLOOKUP($A$1&CECCZ&$G$2&CompressorOnly&$C18,CZ04CycleOnOff,8,0),IF(CECCZ="CZ12",VLOOKUP($A$1&CECCZ&$G$2&CompressorOnly&$C18,CZ12CycleOnOff,8,0),IF(CECCZ="CZ13",VLOOKUP($A$1&CECCZ&$G$2&CompressorOnly&$C18,CZ13CycleOnOff,8,0))))) -> #NAME? | I18: =(E18*G18+H18)/100*DutyCycleMinutes/60 -> #REF! | J18: =I18*D18 -> #REF!
G20: Duty Cycle (minutes off/hr) | H20: =CompressorOnly -> #NAME?
B21: TempRange | C21: hour | D21: power | E21: oat | F21: range | G21: Cycle | H21: =DutyCycleMinutes -> #NAME? | I21: DR% | J21: DR (kW)
B22: =#REF! -> #REF! | C22: 1 | D22: =#REF! -> #REF! | E22: =#REF! -> #REF! | F22: =IF(E22<75,1,IF(AND(E22>=75, E22<95),2,IF(E22>=95,3))) -> #REF! | G22: =IF($B$1="CZ03",VLOOKUP($A$1&CECCZ&$G$2&CompressorOnly&$C22,CZ03CycleOnOff,7,0),IF($B$1="CZ04",VLOOKUP($A$1&CECCZ&$G$2&CompressorOnly&$C22,CZ04CycleOnOff,7,0),IF(CECCZ="CZ12",VLOOKUP($A$1&CECCZ&$G$2&CompressorOnly&$C22,CZ12CycleOnOff,7,0),IF(CECCZ="CZ13",VLOOKUP($A$1&CECCZ&$G$2&CompressorOnly&$C22,CZ13CycleOnOff,7,0))))) -> #NAME? | H22: =IF(CECCZ="CZ03",VLOOKUP($A$1&CECCZ&$G$2&CompressorOnly&$C22,CZ03CycleOnOff,8,0),IF(CECCZ="CZ04",VLOOKUP($A$1&CECCZ&$G$2&CompressorOnly&$C22,CZ04CycleOnOff,8,0),IF(CECCZ="CZ12",VLOOKUP($A$1&CECCZ&$G$2&CompressorOnly&$C22,CZ12CycleOnOff,8,0),IF(CECCZ="CZ13",VLOOKUP($A$1&CECCZ&$G$2&CompressorOnly&$C22,CZ13CycleOnOff,8,0))))) -> #NAME? | I22: =(E22*G22+H22)/100*DutyCycleMinutes/60 -> #REF! | J22: =I22*D22 -> #REF!
B23: =#REF! -> #REF! | C23: 1 | D23: =#REF! -> #REF! | E23: =#REF! -> #REF! | F23: =IF(E23<75,1,IF(AND(E23>=75, E23<95),2,IF(E23>=95,3))) -> #REF! | G23: =IF($B$1="CZ03",VLOOKUP($A$1&CECCZ&$G$2&CompressorOnly&$C23,CZ03CycleOnOff,7,0),IF($B$1="CZ04",VLOOKUP($A$1&CECCZ&$G$2&CompressorOnly&$C23,CZ04CycleOnOff,7,0),IF(CECCZ="CZ12",VLOOKUP($A$1&CECCZ&$G$2&CompressorOnly&$C23,CZ12CycleOnOff,7,0),IF(CECCZ="CZ13",VLOOKUP($A$1&CECCZ&$G$2&CompressorOnly&$C23,CZ13CycleOnOff,7,0))))) -> #NAME? | H23: =IF(CECCZ="CZ03",VLOOKUP($A$1&CECCZ&$G$2&CompressorOnly&$C23,CZ03CycleOnOff,8,0),IF(CECCZ="CZ04",VLOOKUP($A$1&CECCZ&$G$2&CompressorOnly&$C23,CZ04CycleOnOff,8,0),IF(CECCZ="CZ12",VLOOKUP($A$1&CECCZ&$G$2&CompressorOnly&$C23,CZ12CycleOnOff,8,0),IF(CECCZ="CZ13",VLOOKUP($A$1&CECCZ&$G$2&CompressorOnly&$C23,CZ13CycleOnOff,8,0))))) -> #NAME? | I23: =(E23*G23+H23)/100*DutyCycleMinutes/60 -> #REF! | J23: =I23*D23 -> #REF!
B24: =#REF! -> #REF! | C24: 1 | D24: =#REF! -> #REF! | E24: =#REF! -> #REF! | F24: =IF(E24<75,1,IF(AND(E24>=75, E24<95),2,IF(E24>=95,3))) -> #REF! | G24: =IF($B$1="CZ03",VLOOKUP($A$1&CECCZ&$G$2&CompressorOnly&$C24,CZ03CycleOnOff,7,0),IF($B$1="CZ04",VLOOKUP($A$1&CECCZ&$G$2&CompressorOnly&$C24,CZ04CycleOnOff,7,0),IF(CECCZ="CZ12",VLOOKUP($A$1&CECCZ&$G$2&CompressorOnly&$C24,CZ12CycleOnOff,7,0),IF(CECCZ="CZ13",VLOOKUP($A$1&CECCZ&$G$2&CompressorOnly&$C24,CZ13CycleOnOff,7,0))))) -> #NAME? | H24: =IF(CECCZ="CZ03",VLOOKUP($A$1&CECCZ&$G$2&CompressorOnly&$C24,CZ03CycleOnOff,8,0),IF(CECCZ="CZ04",VLOOKUP($A$1&CECCZ&$G$2&CompressorOnly&$C24,CZ04CycleOnOff,8,0),IF(CECCZ="CZ12",VLOOKUP($A$1&CECCZ&$G$2&CompressorOnly&$C24,CZ12CycleOnOff,8,0),IF(CECCZ="CZ13",VLOOKUP($A$1&CECCZ&$G$2&CompressorOnly&$C24,CZ13CycleOnOff,8,0))))) -> #NAME? | I24: =(E24*G24+H24)/100*DutyCycleMinutes/60 -> #REF! | J24: =I24*D24 -> #REF!
B25: =#REF! -> #REF! | C25: 1 | D25: =#REF! -> #REF! | E25: =#REF! -> #REF! | F25: =IF(E25<75,1,IF(AND(E25>=75, E25<95),2,IF(E25>=95,3))) -> #REF! | G25: =IF($B$1="CZ03",VLOOKUP($A$1&CECCZ&$G$2&CompressorOnly&$C25,CZ03CycleOnOff,7,0),IF($B$1="CZ04",VLOOKUP($A$1&CECCZ&$G$2&CompressorOnly&$C25,CZ04CycleOnOff,7,0),IF(CECCZ="CZ12",VLOOKUP($A$1&CECCZ&$G$2&CompressorOnly&$C25,CZ12CycleOnOff,7,0),IF(CECCZ="CZ13",VLOOKUP($A$1&CECCZ&$G$2&CompressorOnly&$C25,CZ13CycleOnOff,7,0))))) -> #NAME? | H25: =IF(CECCZ="CZ03",VLOOKUP($A$1&CECCZ&$G$2&CompressorOnly&$C25,CZ03CycleOnOff,8,0),IF(CECCZ="CZ04",VLOOKUP($A$1&CECCZ&$G$2&CompressorOnly&$C25,CZ04CycleOnOff,8,0),IF(CECCZ="CZ12",VLOOKUP($A$1&CECCZ&$G$2&CompressorOnly&$C25,CZ12CycleOnOff,8,0),IF(CECCZ="CZ13",VLOOKUP($A$1&CECCZ&$G$2&CompressorOnly&$C25,CZ13CycleOnOff,8,0))))) -> #NAME? | I25: =(E25*G25+H25)/100*DutyCycleMinutes/60 -> #REF! | J25: =I25*D25 -> #REF!
B26: =#REF! -> #REF! | C26: 2 | D26: =#REF! -> #REF! | E26: =#REF! -> #REF! | F26: =IF(E26<75,1,IF(AND(E26>=75, E26<95),2,IF(E26>=95,3))) -> #REF! | G26: =IF($B$1="CZ03",VLOOKUP($A$1&CECCZ&$G$2&CompressorOnly&$C26,CZ03CycleOnOff,7,0),IF($B$1="CZ04",VLOOKUP($A$1&CECCZ&$G$2&CompressorOnly&$C26,CZ04CycleOnOff,7,0),IF(CECCZ="CZ12",VLOOKUP($A$1&CECCZ&$G$2&CompressorOnly&$C26,CZ12CycleOnOff,7,0),IF(CECCZ="CZ13",VLOOKUP($A$1&CECCZ&$G$2&CompressorOnly&$C26,CZ13CycleOnOff,7,0))))) -> #NAME? | H26: =IF(CECCZ="CZ03",VLOOKUP($A$1&CECCZ&$G$2&CompressorOnly&$C26,CZ03CycleOnOff,8,0),IF(CECCZ="CZ04",VLOOKUP($A$1&CECCZ&$G$2&CompressorOnly&$C26,CZ04CycleOnOff,8,0),IF(CECCZ="CZ12",VLOOKUP($A$1&CECCZ&$G$2&CompressorOnly&$C26,CZ12CycleOnOff,8,0),IF(CECCZ="CZ13",VLOOKUP($A$1&CECCZ&$G$2&CompressorOnly&$C26,CZ13CycleOnOff,8,0))))) -> #NAME? | I26: =(E26*G26+H26)/100*DutyCycleMinutes/60 -> #REF! | J26: =I26*D26 -> #REF!
B27: =#REF! -> #REF! | C27: 2 | D27: =#REF! -> #REF! | E27: =#REF! -> #REF! | F27: =IF(E27<75,1,IF(AND(E27>=75, E27<95),2,IF(E27>=95,3))) -> #REF! | G27: =IF($B$1="CZ03",VLOOKUP($A$1&CECCZ&$G$2&CompressorOnly&$C27,CZ03CycleOnOff,7,0),IF($B$1="CZ04",VLOOKUP($A$1&CECCZ&$G$2&CompressorOnly&$C27,CZ04CycleOnOff,7,0),IF(CECCZ="CZ12",VLOOKUP($A$1&CECCZ&$G$2&CompressorOnly&$C27,CZ12CycleOnOff,7,0),IF(CECCZ="CZ13",VLOOKUP($A$1&CECCZ&$G$2&CompressorOnly&$C27,CZ13CycleOnOff,7,0))))) -> #NAME? | H27: =IF(CECCZ="CZ03",VLOOKUP($A$1&CECCZ&$G$2&CompressorOnly&$C27,CZ03CycleOnOff,8,0),IF(CECCZ="CZ04",VLOOKUP($A$1&CECCZ&$G$2&CompressorOnly&$C27,CZ04CycleOnOff,8,0),IF(CECCZ="CZ12",VLOOKUP($A$1&CECCZ&$G$2&CompressorOnly&$C27,CZ12CycleOnOff,8,0),IF(CECCZ="CZ13",VLOOKUP($A$1&CECCZ&$G$2&CompressorOnly&$C27,CZ13CycleOnOff,8,0))))) -> #NAME? | I27: =(E27*G27+H27)/100*DutyCycleMinutes/60 -> #REF! | J27: =I27*D27 -> #REF!
B28: =#REF! -> #REF! | C28: 2 | D28: =#REF! -> #REF! | E28: =#REF! -> #REF! | F28: =IF(E28<75,1,IF(AND(E28>=75, E28<95),2,IF(E28>=95,3))) -> #REF! | G28: =IF($B$1="CZ03",VLOOKUP($A$1&CECCZ&$G$2&CompressorOnly&$C28,CZ03CycleOnOff,7,0),IF($B$1="CZ04",VLOOKUP($A$1&CECCZ&$G$2&CompressorOnly&$C28,CZ04CycleOnOff,7,0),IF(CECCZ="CZ12",VLOOKUP($A$1&CECCZ&$G$2&CompressorOnly&$C28,CZ12CycleOnOff,7,0),IF(CECCZ="CZ13",VLOOKUP($A$1&CECCZ&$G$2&CompressorOnly&$C28,CZ13CycleOnOff,7,0))))) -> #NAME? | H28: =IF(CECCZ="CZ03",VLOOKUP($A$1&CECCZ&$G$2&CompressorOnly&$C28,CZ03CycleOnOff,8,0),IF(CECCZ="CZ04",VLOOKUP($A$1&CECCZ&$G$2&CompressorOnly&$C28,CZ04CycleOnOff,8,0),IF(CECCZ="CZ12",VLOOKUP($A$1&CECCZ&$G$2&CompressorOnly&$C28,CZ12CycleOnOff,8,0),IF(CECCZ="CZ13",VLOOKUP($A$1&CECCZ&$G$2&CompressorOnly&$C28,CZ13CycleOnOff,8,0))))) -> #NAME? | I28: =(E28*G28+H28)/100*DutyCycleMinutes/60 -> #REF! | J28: =I28*D28 -> #REF!
B29: =#REF! -> #REF! | C29: 2 | D29: =#REF! -> #REF! | E29: =#REF! -> #REF! | F29: =IF(E29<75,1,IF(AND(E29>=75, E29<95),2,IF(E29>=95,3))) -> #REF! | G29: =IF($B$1="CZ03",VLOOKUP($A$1&CECCZ&$G$2&CompressorOnly&$C29,CZ03CycleOnOff,7,0),IF($B$1="CZ04",VLOOKUP($A$1&CECCZ&$G$2&CompressorOnly&$C29,CZ04CycleOnOff,7,0),IF(CECCZ="CZ12",VLOOKUP($A$1&CECCZ&$G$2&CompressorOnly&$C29,CZ12CycleOnOff,7,0),IF(CECCZ="CZ13",VLOOKUP($A$1&CECCZ&$G$2&CompressorOnly&$C29,CZ13CycleOnOff,7,0))))) -> #NAME? | H29: =IF(CECCZ="CZ03",VLOOKUP($A$1&CECCZ&$G$2&CompressorOnly&$C29,CZ03CycleOnOff,8,0),IF(CECCZ="CZ04",VLOOKUP($A$1&CECCZ&$G$2&CompressorOnly&$C29,CZ04CycleOnOff,8,0),IF(CECCZ="CZ12",VLOOKUP($A$1&CECCZ&$G$2&CompressorOnly&$C29,CZ12CycleOnOff,8,0),IF(CECCZ="CZ13",VLOOKUP($A$1&CECCZ&$G$2&CompressorOnly&$C29,CZ13CycleOnOff,8,0))))) -> #NAME? | I29: =(E29*G29+H29)/100*DutyCycleMinutes/60 -> #REF! | J29: =I29*D29 -> #REF!
B30: =#REF! -> #REF! | C30: 3 | D30: =#REF! -> #REF! | E30: =#REF! -> #REF! | F30: =IF(E30<75,1,IF(AND(E30>=75, E30<95),2,IF(E30>=95,3))) -> #REF! | G30: =IF($B$1="CZ03",VLOOKUP($A$1&CECCZ&$G$2&CompressorOnly&$C30,CZ03CycleOnOff,7,0),IF($B$1="CZ04",VLOOKUP($A$1&CECCZ&$G$2&CompressorOnly&$C30,CZ04CycleOnOff,7,0),IF(CECCZ="CZ12",VLOOKUP($A$1&CECCZ&$G$2&CompressorOnly&$C30,CZ12CycleOnOff,7,0),IF(CECCZ="CZ13",VLOOKUP($A$1&CECCZ&$G$2&CompressorOnly&$C30,CZ13CycleOnOff,7,0))))) -> #NAME? | H30: =IF(CECCZ="CZ03",VLOOKUP($A$1&CECCZ&$G$2&CompressorOnly&$C30,CZ03CycleOnOff,8,0),IF(CECCZ="CZ04",VLOOKUP($A$1&CECCZ&$G$2&CompressorOnly&$C30,CZ04CycleOnOff,8,0),IF(CECCZ="CZ12",VLOOKUP($A$1&CECCZ&$G$2&CompressorOnly&$C30,CZ12CycleOnOff,8,0),IF(CECCZ="CZ13",VLOOKUP($A$1&CECCZ&$G$2&CompressorOnly&$C30,CZ13CycleOnOff,8,0))))) -> #NAME? | I30: =(E30*G30+H30)/100*DutyCycleMinutes/60 -> #REF! | J30: =I30*D30 -> #REF!
B31: =#REF! -> #REF! | C31: 3 | D31: =#REF! -> #REF! | E31: =#REF! -> #REF! | F31: =IF(E31<75,1,IF(AND(E31>=75, E31<95),2,IF(E31>=95,3))) -> #REF! | G31: =IF($B$1="CZ03",VLOOKUP($A$1&CECCZ&$G$2&CompressorOnly&$C31,CZ03CycleOnOff,7,0),IF($B$1="CZ04",VLOOKUP($A$1&CECCZ&$G$2&CompressorOnly&$C31,CZ04CycleOnOff,7,0),IF(CECCZ="CZ12",VLOOKUP($A$1&CECCZ&$G$2&CompressorOnly&$C31,CZ12CycleOnOff,7,0),IF(CECCZ="CZ13",VLOOKUP($A$1&CECCZ&$G$2&CompressorOnly&$C31,CZ13CycleOnOff,7,0))))) -> #NAME? | H31: =IF(CECCZ="CZ03",VLOOKUP($A$1&CECCZ&$G$2&CompressorOnly&$C31,CZ03CycleOnOff,8,0),IF(CECCZ="CZ04",VLOOKUP($A$1&CECCZ&$G$2&CompressorOnly&$C31,CZ04CycleOnOff,8,0),IF(CECCZ="CZ12",VLOOKUP($A$1&CECCZ&$G$2&CompressorOnly&$C31,CZ12CycleOnOff,8,0),IF(CECCZ="CZ13",VLOOKUP($A$1&CECCZ&$G$2&CompressorOnly&$C31,CZ13CycleOnOff,8,0))))) -> #NAME? | I31: =(E31*G31+H31)/100*DutyCycleMinutes/60 -> #REF! | J31: =I31*D31 -> #REF!
B32: =#REF! -> #REF! | C32: 3 | D32: =#REF! -> #REF! | E32: =#REF! -> #REF! | F32: =IF(E32<75,1,IF(AND(E32>=75, E32<95),2,IF(E32>=95,3))) -> #REF! | G32: =IF($B$1="CZ03",VLOOKUP($A$1&CECCZ&$G$2&CompressorOnly&$C32,CZ03CycleOnOff,7,0),IF($B$1="CZ04",VLOOKUP($A$1&CECCZ&$G$2&CompressorOnly&$C32,CZ04CycleOnOff,7,0),IF(CECCZ="CZ12",VLOOKUP($A$1&CECCZ&$G$2&CompressorOnly&$C32,CZ12CycleOnOff,7,0),IF(CECCZ="CZ13",VLOOKUP($A$1&CECCZ&$G$2&CompressorOnly&$C32,CZ13CycleOnOff,7,0))))) -> #NAME? | H32: =IF(CECCZ="CZ03",VLOOKUP($A$1&CECCZ&$G$2&CompressorOnly&$C32,CZ03CycleOnOff,8,0),IF(CECCZ="CZ04",VLOOKUP($A$1&CECCZ&$G$2&CompressorOnly&$C32,CZ04CycleOnOff,8,0),IF(CECCZ="CZ12",VLOOKUP($A$1&CECCZ&$G$2&CompressorOnly&$C32,CZ12CycleOnOff,8,0),IF(CECCZ="CZ13",VLOOKUP($A$1&CECCZ&$G$2&CompressorOnly&$C32,CZ13CycleOnOff,8,0))))) -> #NAME? | I32: =(E32*G32+H32)/100*DutyCycleMinutes/60 -> #REF! | J32: =I32*D32 -> #REF!
B33: =#REF! -> #REF! | C33: 3 | D33: =#REF! -> #REF! | E33: =#REF! -> #REF! | F33: =IF(E33<75,1,IF(AND(E33>=75, E33<95),2,IF(E33>=95,3))) -> #REF! | G33: =IF($B$1="CZ03",VLOOKUP($A$1&CECCZ&$G$2&CompressorOnly&$C33,CZ03CycleOnOff,7,0),IF($B$1="CZ04",VLOOKUP($A$1&CECCZ&$G$2&CompressorOnly&$C33,CZ04CycleOnOff,7,0),IF(CECCZ="CZ12",VLOOKUP($A$1&CECCZ&$G$2&CompressorOnly&$C33,CZ12CycleOnOff,7,0),IF(CECCZ="CZ13",VLOOKUP($A$1&CECCZ&$G$2&CompressorOnly&$C33,CZ13CycleOnOff,7,0))))) -> #NAME? | H33: =IF(CECCZ="CZ03",VLOOKUP($A$1&CECCZ&$G$2&CompressorOnly&$C33,CZ03CycleOnOff,8,0),IF(CECCZ="CZ04",VLOOKUP($A$1&CECCZ&$G$2&CompressorOnly&$C33,CZ04CycleOnOff,8,0),IF(CECCZ="CZ12",VLOOKUP($A$1&CECCZ&$G$2&CompressorOnly&$C33,CZ12CycleOnOff,8,0),IF(CECCZ="CZ13",VLOOKUP($A$1&CECCZ&$G$2&CompressorOnly&$C33,CZ13CycleOnOff,8,0))))) -> #NAME? | I33: =(E33*G33+H33)/100*DutyCycleMinutes/60 -> #REF! | J33: =I33*D33 -> #REF!
... B37: =#REF! -> #REF! | C37: 4 | D37: =#REF! -> #REF! | E37: =#REF! -> #REF! | F37: =IF(E37<75,1,IF(AND(E37>=75, E37<95),2,IF(E37>=95,3))) -> #REF! | G37: =IF($B$1="CZ03",VLOOKUP($A$1&CECCZ&$G$2&CompressorOnly&$C37,CZ03CycleOnOff,7,0),IF($B$1="CZ04",VLOOKUP($A$1&CECCZ&$G$2&CompressorOnly&$C37,CZ04CycleOnOff,7,0),IF(CECCZ="CZ12",VLOOKUP($A$1&CECCZ&$G$2&CompressorOnly&$C37,CZ12CycleOnOff,7,0),IF(CECCZ="CZ13",VLOOKUP($A$1&CECCZ&$G$2&CompressorOnly&$C37,CZ13CycleOnOff,7,0))))) -> #NAME? | H37: =IF(CECCZ="CZ03",VLOOKUP($A$1&CECCZ&$G$2&CompressorOnly&$C37,CZ03CycleOnOff,8,0),IF(CECCZ="CZ04",VLOOKUP($A$1&CECCZ&$G$2&CompressorOnly&$C37,CZ04CycleOnOff,8,0),IF(CECCZ="CZ12",VLOOKUP($A$1&CECCZ&$G$2&CompressorOnly&$C37,CZ12CycleOnOff,8,0),IF(CECCZ="CZ13",VLOOKUP($A$1&CECCZ&$G$2&CompressorOnly&$C37,CZ13CycleOnOff,8,0))))) -> #NAME? | I37: =(E37*G37+H37)/100*DutyCycleMinutes/60 -> #REF! | J37: =I37*D37 -> #REF!
G39: Duty Cycle (minutes off/hr) | H39: =CompressorOnly -> #NAME?
B40: TempRange | C40: hour | D40: power | E40: oat | F40: range | G40: Cycle | H40: =DutyCycleMinutes -> #NAME? | I40: DR% | J40: DR (kW)
B41: =#REF! -> #REF! | C41: 1 | D41: =#REF! -> #REF! | E41: =#REF! -> #REF! | F41: =IF(E41<75,1,IF(AND(E41>=75, E41<95),2,IF(E41>=95,3))) -> #REF! | G41: =IF($B$1="CZ03",VLOOKUP($A$1&CECCZ&$G$2&CompressorOnly&$C41,CZ03CycleOnOff,7,0),IF($B$1="CZ04",VLOOKUP($A$1&CECCZ&$G$2&CompressorOnly&$C41,CZ04CycleOnOff,7,0),IF(CECCZ="CZ12",VLOOKUP($A$1&CECCZ&$G$2&CompressorOnly&$C41,CZ12CycleOnOff,7,0),IF(CECCZ="CZ13",VLOOKUP($A$1&CECCZ&$G$2&CompressorOnly&$C41,CZ13CycleOnOff,7,0))))) -> #NAME? | H41: =IF(CECCZ="CZ03",VLOOKUP($A$1&CECCZ&$G$2&CompressorOnly&$C41,CZ03CycleOnOff,8,0),IF(CECCZ="CZ04",VLOOKUP($A$1&CECCZ&$G$2&CompressorOnly&$C41,CZ04CycleOnOff,8,0),IF(CECCZ="CZ12",VLOOKUP($A$1&CECCZ&$G$2&CompressorOnly&$C41,CZ12CycleOnOff,8,0),IF(CECCZ="CZ13",VLOOKUP($A$1&CECCZ&$G$2&CompressorOnly&$C41,CZ13CycleOnOff,8,0))))) -> #NAME? | I41: =(E41*G41+H41)/100*DutyCycleMinutes/60 -> #REF! | J41: =I41*D41 -> #REF!
B42: =#REF! -> #REF! | C42: 1 | D42: =#REF! -> #REF! | E42: =#REF! -> #REF! | F42: =IF(E42<75,1,IF(AND(E42>=75, E42<95),2,IF(E42>=95,3))) -> #REF! | G42: =IF($B$1="CZ03",VLOOKUP($A$1&CECCZ&$G$2&CompressorOnly&$C42,CZ03CycleOnOff,7,0),IF($B$1="CZ04",VLOOKUP($A$1&CECCZ&$G$2&CompressorOnly&$C42,CZ04CycleOnOff,7,0),IF(CECCZ="CZ12",VLOOKUP($A$1&CECCZ&$G$2&CompressorOnly&$C42,CZ12CycleOnOff,7,0),IF(CECCZ="CZ13",VLOOKUP($A$1&CECCZ&$G$2&CompressorOnly&$C42,CZ13CycleOnOff,7,0))))) -> #NAME? | H42: =IF(CECCZ="CZ03",VLOOKUP($A$1&CECCZ&$G$2&CompressorOnly&$C42,CZ03CycleOnOff,8,0),IF(CECCZ="CZ04",VLOOKUP($A$1&CECCZ&$G$2&CompressorOnly&$C42,CZ04CycleOnOff,8,0),IF(CECCZ="CZ12",VLOOKUP($A$1&CECCZ&$G$2&CompressorOnly&$C42,CZ12CycleOnOff,8,0),IF(CECCZ="CZ13",VLOOKUP($A$1&CECCZ&$G$2&CompressorOnly&$C42,CZ13CycleOnOff,8,0))))) -> #NAME? | I42: =(E42*G42+H42)/100*DutyCycleMinutes/60 -> #REF! | J42: =I42*D42 -> #REF!
B43: =#REF! -> #REF! | C43: 1 | D43: =#REF! -> #REF! | E43: =#REF! -> #REF! | F43: =IF(E43<75,1,IF(AND(E43>=75, E43<95),2,IF(E43>=95,3))) -> #REF! | G43: =IF($B$1="CZ03",VLOOKUP($A$1&CECCZ&$G$2&CompressorOnly&$C43,CZ03CycleOnOff,7,0),IF($B$1="CZ04",VLOOKUP($A$1&CECCZ&$G$2&CompressorOnly&$C43,CZ04CycleOnOff,7,0),IF(CECCZ="CZ12",VLOOKUP($A$1&CECCZ&$G$2&CompressorOnly&$C43,CZ12CycleOnOff,7,0),IF(CECCZ="CZ13",VLOOKUP($A$1&CECCZ&$G$2&CompressorOnly&$C43,CZ13CycleOnOff,7,0))))) -> #NAME? | H43: =IF(CECCZ="CZ03",VLOOKUP($A$1&CECCZ&$G$2&CompressorOnly&$C43,CZ03CycleOnOff,8,0),IF(CECCZ="CZ04",VLOOKUP($A$1&CECCZ&$G$2&CompressorOnly&$C43,CZ04CycleOnOff,8,0),IF(CECCZ="CZ12",VLOOKUP($A$1&CECCZ&$G$2&CompressorOnly&$C43,CZ12CycleOnOff,8,0),IF(CECCZ="CZ13",VLOOKUP($A$1&CECCZ&$G$2&CompressorOnly&$C43,CZ13CycleOnOff,8,0))))) -> #NAME? | I43: =(E43*G43+H43)/100*DutyCycleMinutes/60 -> #REF! | J43: =I43*D43 -> #REF!
B44: =#REF! -> #REF! | C44: 1 | D44: =#REF! -> #REF! | E44: =#REF! -> #REF! | F44: =IF(E44<75,1,IF(AND(E44>=75, E44<95),2,IF(E44>=95,3))) -> #REF! | G44: =IF($B$1="CZ03",VLOOKUP($A$1&CECCZ&$G$2&CompressorOnly&$C44,CZ03CycleOnOff,7,0),IF($B$1="CZ04",VLOOKUP($A$1&CECCZ&$G$2&CompressorOnly&$C44,CZ04CycleOnOff,7,0),IF(CECCZ="CZ12",VLOOKUP($A$1&CECCZ&$G$2&CompressorOnly&$C44,CZ12CycleOnOff,7,0),IF(CECCZ="CZ13",VLOOKUP($A$1&CECCZ&$G$2&CompressorOnly&$C44,CZ13CycleOnOff,7,0))))) -> #NAME? | H44: =IF(CECCZ="CZ03",VLOOKUP($A$1&CECCZ&$G$2&CompressorOnly&$C44,CZ03CycleOnOff,8,0),IF(CECCZ="CZ04",VLOOKUP($A$1&CECCZ&$G$2&CompressorOnly&$C44,CZ04CycleOnOff,8,0),IF(CECCZ="CZ12",VLOOKUP($A$1&CECCZ&$G$2&CompressorOnly&$C44,CZ12CycleOnOff,8,0),IF(CECCZ="CZ13",VLOOKUP($A$1&CECCZ&$G$2&CompressorOnly&$C44,CZ13CycleOnOff,8,0))))) -> #NAME? | I44: =(E44*G44+H44)/100*DutyCycleMinutes/60 -> #REF! | J44: =I44*D44 -> #REF!
B45: =#REF! -> #REF! | C45: 2 | D45: =#REF! -> #REF! | E45: =#REF! -> #REF! | F45: =IF(E45<75,1,IF(AND(E45>=75, E45<95),2,IF(E45>=95,3))) -> #REF! | G45: =IF($B$1="CZ03",VLOOKUP($A$1&CECCZ&$G$2&CompressorOnly&$C45,CZ03CycleOnOff,7,0),IF($B$1="CZ04",VLOOKUP($A$1&CECCZ&$G$2&CompressorOnly&$C45,CZ04CycleOnOff,7,0),IF(CECCZ="CZ12",VLOOKUP($A$1&CECCZ&$G$2&CompressorOnly&$C45,CZ12CycleOnOff,7,0),IF(CECCZ="CZ13",VLOOKUP($A$1&CECCZ&$G$2&CompressorOnly&$C45,CZ13CycleOnOff,7,0))))) -> #NAME? | H45: =IF(CECCZ="CZ03",VLOOKUP($A$1&CECCZ&$G$2&CompressorOnly&$C45,CZ03CycleOnOff,8,0),IF(CECCZ="CZ04",VLOOKUP($A$1&CECCZ&$G$2&CompressorOnly&$C45,CZ04CycleOnOff,8,0),IF(CECCZ="CZ12",VLOOKUP($A$1&CECCZ&$G$2&CompressorOnly&$C45,CZ12CycleOnOff,8,0),IF(CECCZ="CZ13",VLOOKUP($A$1&CECCZ&$G$2&CompressorOnly&$C45,CZ13CycleOnOff,8,0))))) -> #NAME? | I45: =(E45*G45+H45)/100*DutyCycleMinutes/60 -> #REF! | J45: =I45*D45 -> #REF!
B46: =#REF! -> #REF! | C46: 2 | D46: =#REF! -> #REF! | E46: =#REF! -> #REF! | F46: =IF(E46<75,1,IF(AND(E46>=75, E46<95),2,IF(E46>=95,3))) -> #REF! | G46: =IF($B$1="CZ03",VLOOKUP($A$1&CECCZ&$G$2&CompressorOnly&$C46,CZ03CycleOnOff,7,0),IF($B$1="CZ04",VLOOKUP($A$1&CECCZ&$G$2&CompressorOnly&$C46,CZ04CycleOnOff,7,0),IF(CECCZ="CZ12",VLOOKUP($A$1&CECCZ&$G$2&CompressorOnly&$C46,CZ12CycleOnOff,7,0),IF(CECCZ="CZ13",VLOOKUP($A$1&CECCZ&$G$2&CompressorOnly&$C46,CZ13CycleOnOff,7,0))))) -> #NAME? | H46: =IF(CECCZ="CZ03",VLOOKUP($A$1&CECCZ&$G$2&CompressorOnly&$C46,CZ03CycleOnOff,8,0),IF(CECCZ="CZ04",VLOOKUP($A$1&CECCZ&$G$2&CompressorOnly&$C46,CZ04CycleOnOff,8,0),IF(CECCZ="CZ12",VLOOKUP($A$1&CECCZ&$G$2&CompressorOnly&$C46,CZ12CycleOnOff,8,0),IF(CECCZ="CZ13",VLOOKUP($A$1&CECCZ&$G$2&CompressorOnly&$C46,CZ13CycleOnOff,8,0))))) -> #NAME? | I46: =(E46*G46+H46)/100*DutyCycleMinutes/60 -> #REF! | J46: =I46*D46 -> #REF!
B47: =#REF! -> #REF! | C47: 2 | D47: =#REF! -> #REF! | E47: =#REF! -> #REF! | F47: =IF(E47<75,1,IF(AND(E47>=75, E47<95),2,IF(E47>=95,3))) -> #REF! | G47: =IF($B$1="CZ03",VLOOKUP($A$1&CECCZ&$G$2&CompressorOnly&$C47,CZ03CycleOnOff,7,0),IF($B$1="CZ04",VLOOKUP($A$1&CECCZ&$G$2&CompressorOnly&$C47,CZ04CycleOnOff,7,0),IF(CECCZ="CZ12",VLOOKUP($A$1&CECCZ&$G$2&CompressorOnly&$C47,CZ12CycleOnOff,7,0),IF(CECCZ="CZ13",VLOOKUP($A$1&CECCZ&$G$2&CompressorOnly&$C47,CZ13CycleOnOff,7,0))))) -> #NAME? | H47: =IF(CECCZ="CZ03",VLOOKUP($A$1&CECCZ&$G$2&CompressorOnly&$C47,CZ03CycleOnOff,8,0),IF(CECCZ="CZ04",VLOOKUP($A$1&CECCZ&$G$2&CompressorOnly&$C47,CZ04CycleOnOff,8,0),IF(CECCZ="CZ12",VLOOKUP($A$1&CECCZ&$G$2&CompressorOnly&$C47,CZ12CycleOnOff,8,0),IF(CECCZ="CZ13",VLOOKUP($A$1&CECCZ&$G$2&CompressorOnly&$C47,CZ13CycleOnOff,8,0))))) -> #NAME? | I47: =(E47*G47+H47)/100*DutyCycleMinutes/60 -> #REF! | J47: =I47*D47 -> #REF!
B48: =#REF! -> #REF! | C48: 2 | D48: =#REF! -> #REF! | E48: =#REF! -> #REF! | F48: =IF(E48<75,1,IF(AND(E48>=75, E48<95),2,IF(E48>=95,3))) -> #REF! | G48: =IF($B$1="CZ03",VLOOKUP($A$1&CECCZ&$G$2&CompressorOnly&$C48,CZ03CycleOnOff,7,0),IF($B$1="CZ04",VLOOKUP($A$1&CECCZ&$G$2&CompressorOnly&$C48,CZ04CycleOnOff,7,0),IF(CECCZ="CZ12",VLOOKUP($A$1&CECCZ&$G$2&CompressorOnly&$C48,CZ12CycleOnOff,7,0),IF(CECCZ="CZ13",VLOOKUP($A$1&CECCZ&$G$2&CompressorOnly&$C48,CZ13CycleOnOff,7,0))))) -> #NAME? | H48: =IF(CECCZ="CZ03",VLOOKUP($A$1&CECCZ&$G$2&CompressorOnly&$C48,CZ03CycleOnOff,8,0),IF(CECCZ="CZ04",VLOOKUP($A$1&CECCZ&$G$2&CompressorOnly&$C48,CZ04CycleOnOff,8,0),IF(CECCZ="CZ12",VLOOKUP($A$1&CECCZ&$G$2&CompressorOnly&$C48,CZ12CycleOnOff,8,0),IF(CECCZ="CZ13",VLOOKUP($A$1&CECCZ&$G$2&CompressorOnly&$C48,CZ13CycleOnOff,8,0))))) -> #NAME? | I48: =(E48*G48+H48)/100*DutyCycleMinutes/60 -> #REF! | J48: =I48*D48 -> #REF!
...

Sheet GTA Calculation
A1: ='User Inputs and DR Shed Results'!B15 -> MediumOffice | B1: =CITYCZ -> n/a | C1: =ASHRAECZ -> 5A | D1: MA
A2: measureId | B2: Precool (°F) | C2: Temp Reset (°F) | D2: DR Event Hour (2PM to 6PM) | E2: slope1_pct | F2: intercept1_pct | G2: slope2_pct | H2: intercept2_pct | I2: slope1_W_ft2 | J2: intercept1_W_ft2 | K2: slope2_W_ft2 | L2: intercept2_W_ft2 | M2: oat | N2: power | O2: DR% | P2: DR (kW) | Q2: DR_W/ft2
A3: =$D$1&$A$1& B3& C3&D3 -> MAMediumOffice021 | B3: =PrecoolDegrees -> 0 | C3: =TempResetDegrees -> 2 | D3: 1 | E3: =VLOOKUP($A3,GTALoadShed,5,0) -> 0.18420911 | F3: =VLOOKUP($A3,GTALoadShed,6,0) -> -11.378267 | G3: =VLOOKUP($A3,GTALoadShed,7,0) -> 0.67482956 | H3: =VLOOKUP($A3,GTALoadShed,8,0) -> -48.067594 | I3: =VLOOKUP($A3,GTALoadShed,11,0) -> 0.00466623 | J3: =VLOOKUP($A3,GTALoadShed,12,0) -> -0.27525381 | K3: =VLOOKUP($A3,GTALoadShed,13,0) -> 0.02401971 | L3: =VLOOKUP($A3,GTALoadShed,14,0) -> -1.738912 | M3: ='User Inputs and DR Shed Results'!B19 -> 100 | N3: ='User Inputs and DR Shed Results'!C19 -> 200 | O3: =IF(M3<75,M3*E3+F3,M3*G3+H3)/100 -> 0.19415362 | P3: =N3*O3 -> 38.830724 | Q3: =IF(M3<75,M3*I3+J3,M3*K3+L3) -> 0.66305901
A4: =$D$1&$A$1& B4& C4&D4 -> MAMediumOffice022 | B4: =PrecoolDegrees -> 0 | C4: =TempResetDegrees -> 2 | D4: 2 | E4: =VLOOKUP($A4,GTALoadShed,5,0) -> 0.20084993 | F4: =VLOOKUP($A4,GTALoadShed,6,0) -> -11.955881 | G4: =VLOOKUP($A4,GTALoadShed,7,0) -> 0.57600708 | H4: =VLOOKUP($A4,GTALoadShed,8,0) -> -39.559346 | I4: =VLOOKUP($A4,GTALoadShed,11,0) -> 0.005419852 | J4: =VLOOKUP($A4,GTALoadShed,12,0) -> -0.31982299 | K4: =VLOOKUP($A4,GTALoadShed,13,0) -> 0.020036085 | L4: =VLOOKUP($A4,GTALoadShed,14,0) -> -1.412057 | M4: ='User Inputs and DR Shed Results'!B20 -> 98 | N4: ='User Inputs and DR Shed Results'!C20 -> 230 | O4: =IF(M4<75,M4*E4+F4,M4*G4+H4)/100 -> 0.16889348 | P4: =N4*O4 -> 38.8455 | Q4: =IF(M4<75,M4*I4+J4,M4*K4+L4) -> 0.5514793
A5: =$D$1&$A$1& B5& C5&D5 -> MAMediumOffice023 | B5: =PrecoolDegrees -> 0 | C5: =TempResetDegrees -> 2 | D5: 3 | E5: =VLOOKUP($A5,GTALoadShed,5,0) -> 0.21857673 | F5: =VLOOKUP($A5,GTALoadShed,6,0) -> -12.839549 | G5: =VLOOKUP($A5,GTALoadShed,7,0) -> 0.54745263 | H5: =VLOOKUP($A5,GTALoadShed,8,0) -> -37.182723 | I5: =VLOOKUP($A5,GTALoadShed,11,0) -> 0.0061879733 | J5: =VLOOKUP($A5,GTALoadShed,12,0) -> -0.35760201 | K5: =VLOOKUP($A5,GTALoadShed,13,0) -> 0.019650201 | L5: =VLOOKUP($A5,GTALoadShed,14,0) -> -1.3704882 | M5: ='User Inputs and DR Shed Results'!B21 -> 87 | N5: ='User Inputs and DR Shed Results'!C21 -> 240 | O5: =IF(M5<75,M5*E5+F5,M5*G5+H5)/100 -> 0.10445656 | P5: =N5*O5 -> 25.069574 | Q5: =IF(M5<75,M5*I5+J5,M5*K5+L5) -> 0.33907924
A6: =$D$1&$A$1& B6& C6&D6 -> MAMediumOffice024 | B6: =PrecoolDegrees -> 0 | C6: =TempResetDegrees -> 2 | D6: 4 | E6: =VLOOKUP($A6,GTALoadShed,5,0) -> 0.1182332 | F6: =VLOOKUP($A6,GTALoadShed,6,0) -> -7.3471989 | G6: =VLOOKUP($A6,GTALoadShed,7,0) -> 0.47611389 | H6: =VLOOKUP($A6,GTALoadShed,8,0) -> -33.449919 | I6: =VLOOKUP($A6,GTALoadShed,11,0) -> 0.0019996008 | J6: =VLOOKUP($A6,GTALoadShed,12,0) -> -0.10594209 | K6: =VLOOKUP($A6,GTALoadShed,13,0) -> 0.015025252 | L6: =VLOOKUP($A6,GTALoadShed,14,0) -> -1.0802832 | M6: ='User Inputs and DR Shed Results'!B22 -> 87 | N6: ='User Inputs and DR Shed Results'!C22 -> 230 | O6: =IF(M6<75,M6*E6+F6,M6*G6+H6)/100 -> 0.079719893 | P6: =N6*O6 -> 18.335575 | Q6: =IF(M6<75,M6*I6+J6,M6*K6+L6) -> 0.22691376

Sheet shed_database
A1: measureId | B1: measureId2 | C1: baseTstat | D1: startTime | E1: endTime | F1: precool | G1: reset | H1: hour | I1: slope1_pct | J1: intercept1_pct | K1: slope2_pct | L1: intercept2_pct | M1: slope1_W_ft2 | N1: intercept1_W_ft2 | O1: slope2_W_ft2 | P1: intercept2_W_ft2
A2: SmallOffice_Pre1980_2A_74_16_19_0_0 | B2: =A2&"_"&H2 -> SmallOffice_Pre1980_2A_74_16_19_0_0_16 | C2: 74 | D2: 16 | E2: 19 | F2: 0 | G2: 0 | H2: 16 | I2: 0 | J2: 0 | K2: 0 | L2: 0 | M2: 0 | N2: 0 | O2: 0 | P2: 0
A3: SmallOffice_Pre1980_2A_74_16_19_0_0 | B3: =A3&"_"&H3 -> SmallOffice_Pre1980_2A_74_16_19_0_0_17 | C3: 74 | D3: 16 | E3: 19 | F3: 0 | G3: 0 | H3: 17 | I3: 0 | J3: 0 | K3: 0 | L3: 0 | M3: 0 | N3: 0 | O3: 0 | P3: 0
A4: SmallOffice_Pre1980_2A_74_16_19_0_0 | B4: =A4&"_"&H4 -> SmallOffice_Pre1980_2A_74_16_19_0_0_18 | C4: 74 | D4: 16 | E4: 19 | F4: 0 | G4: 0 | H4: 18 | I4: 0 | J4: 0 | K4: 0 | L4: 0 | M4: 0 | N4: 0 | O4: 0 | P4: 0
A5: SmallOffice_Pre1980_2A_74_16_19_0_2 | B5: =A5&"_"&H5 -> SmallOffice_Pre1980_2A_74_16_19_0_2_16 | C5: 74 | D5: 16 | E5: 19 | F5: 0 | G5: 2 | H5: 16 | I5: 0.00074813554 | J5: 0.017053734 | K5: 9.8279213e-05 | L5: 0.066896805 | M5: 0.00580892 | N5: -0.10387654 | O5: 0.0067073022 | P5: -0.16722888
A6: SmallOffice_Pre1980_2A_74_16_19_0_2 | B6: =A6&"_"&H6 -> SmallOffice_Pre1980_2A_74_16_19_0_2_17 | C6: 74 | D6: 16 | E6: 19 | F6: 0 | G6: 2 | H6: 17 | I6: -9.0733876e-05 | J6: 0.072972357 | K6: -0.00021347488 | L6: 0.086494715 | M6: 0.003007843 | N6: -0.013116458 | O6: 0.0045997751 | P6: -0.1248645
A7: SmallOffice_Pre1980_2A_74_16_19_0_2 | B7: =A7&"_"&H7 -> SmallOffice_Pre1980_2A_74_16_19_0_2_18 | C7: 74 | D7: 16 | E7: 19 | F7: 0 | G7: 2 | H7: 18 | I7: 0.0009148615 | J7: 0.0045978646 | K7: -0.00028385155 | L7: 0.095823277 | M7: 0.0048141499 | N7: -0.17255955 | O7: 0.0039173659 | P7: -0.10111933
A8: SmallOffice_Pre1980_2A_74_16_19_0_4 | B8: =A8&"_"&H8 -> SmallOffice_Pre1980_2A_74_16_19_0_4_16 | C8: 74 | D8: 16 | E8: 19 | F8: 0 | G8: 4 | H8: 16 | I8: 0.0015883204 | J8: 0.028551868 | K8: -0.00034673577 | L8: 0.17969604 | M8: 0.012085841 | N8: -0.2365843 | O8: 0.010384087 | P8: -0.080180972
A9: SmallOffice_Pre1980_2A_74_16_19_0_4 | B9: =A9&"_"&H9 -> SmallOffice_Pre1980_2A_74_16_19_0_4_17 | C9: 74 | D9: 16 | E9: 19 | F9: 0 | G9: 4 | H9: 17 | I9: 9.9061806e-05 | J9: 0.1221107 | K9: -0.00044003507 | L9: 0.17227506 | M9: 0.0066737927 | N9: -0.084541545 | O9: 0.0089216613 | P9: -0.23305925
A10: SmallOffice_Pre1980_2A_74_16_19_0_4 | B10: =A10&"_"&H10 -> SmallOffice_Pre1980_2A_74_16_19_0_4_18 | C10: 74 | D10: 16 | E10: 19 | F10: 0 | G10: 4 | H10: 18 | I10: 0.0021061564 | J10: -0.01682104 | K10: -0.00043236801 | L10: 0.17746493 | M10: 0.010038275 | N10: -0.38966019 | O10: 0.0080574993 | P10: -0.22951069
A11: SmallOffice_Pre1980_2A_74_16_19_0_6 | B11: =A11&"_"&H11 -> SmallOffice_Pre1980_2A_74_16_19_0_6_16 | C11: 74 | D11: 16 | E11: 19 | F11: 0 | G11: 6 | H11: 16 | I11: 0.0022712006 | J11: 0.031463578 | K11: 0.0012453619 | L11: 0.11601324 | M11: 0.016992663 | N11: -0.35887305 | O11: 0.025249904 | P11: -0.95544724
A12: SmallOffice_Pre1980_2A_74_16_19_0_6 | B12: =A12&"_"&H12 -> SmallOffice_Pre1980_2A_74_16_19_0_6_17 | C12: 74 | D12: 16 | E12: 19 | F12: 0 | G12: 6 | H12: 17 | I12: 0.00033660407 | J12: 0.16140983 | K12: -0.00023171962 | L12: 0.21793679 | M12: 0.010172877 | N12: -0.1635308 | O12: 0.014767887 | P12: -0.48185501
A13: SmallOffice_Pre1980_2A_74_16_19_0_6 | B13: =A13&"_"&H13 -> SmallOffice_Pre1980_2A_74_16_19_0_6_18 | C13: 74 | D13: 16 | E13: 19 | F13: 0 | G13: 6 | H13: 18 | I13: 0.0037511796 | J13: -0.076821386 | K13: -0.00036167859 | L13: 0.23695197 | M13: 0.016029661 | N13: -0.67658244 | O13: 0.012677273 | P13: -0.40957433
