Workbook
Name CEUSLargeOffice: 'Climate Zones'!#REF!
Name CEUSRetail: 'Climate Zones'!#REF!
Name CEUSSmallOffice: 'Climate Zones'!#REF!
Name CompressorOnly: 'User Inputs and DR Shed Results'!#REF!
Name CycleAvailPerc: 'User Inputs and DR Shed Results'!#REF!
Name DutyCycleMinutes: 'User Inputs and DR Shed Results'!#REF!
Name HvacDR: 'User Inputs and DR Shed Results'!#REF!
Name LargeOffice: 'Climate Zones'!#REF!
Name Retail: 'Climate Zones'!#REF!
Name SelectedEquations: 'Cycle Calculation'!#REF!
Name SmallOffice: 'Climate Zones'!#REF!
Name CECCZ: 'User Inputs and DR Shed Results'!$C$13
Name PGECZ: 'User Inputs and DR Shed Results'!$B$12
Name CZ04TempReset: 'LoadShed Database'!$K$2:$T$105
Name CZ03TempReset: 'LoadShed Database'!$A$2:$J$105
Name TempResetDegrees: 'User Inputs and DR Shed Results'!$B$21
Name AvailPerc: 'User Inputs and DR Shed Results'!$B$19
Name CZ13TempReset: 'LoadShed Database'!$AE$2:$AN$105
Name CZ04CycleOnOff: 'LoadShed Database'!$K$107:$T$136
Name BuildingType: 'User Inputs and DR Shed Results'!$B$5
Name CZ12CycleOnOff: 'LoadShed Database'!$U$107:$AD$136
Name NewCustomer: 'User Inputs and DR Shed Results'!$B$8
Name HvacDRTYPE: 'Category Lists'!$N$4:$N$5
Name CZ13CycleOnOff: 'LoadShed Database'!$AE$107:$AN$136
Name CZ03CycleOnOff: 'LoadShed Database'!$A$107:$J$136
Name PrecoolDegrees: 'User Inputs and DR Shed Results'!$B$20
Name CZ12TempReset: 'LoadShed Database'!$U$2:$AD$105

Sheet Welcome to DR Tool
B1: ADR Estimation Tool Framework
B27: Instructions for LBNL ADR Tool V2.1:
B28: This tool provides DR shed magnitudes for a range of OATs for one of the major DR strategies: 1) HVAC Temp Reset (Precool with Zone Temp Setback).
B29: Step 1: Copy 15-min electricity meter data into the "IDAR Meter Data" sheet. First column is date and time in format "MM/DD/YYYY HH:MM". Second column is meter demand in units of kW in any number format.
B30: Step 2: In the "User Inputs and DR Shed Results" sheet's "ADR Site Description" block: 1. Enter the site name (if desired), 2. Select building type--Office or Retail, 3. Select HVAC type--Rooftop unit(s) or Central Plant and 4. Enter the site's zip code.
B31: Step 3:If HVAC temp reset is strategy of intereset, in the "User Inputs and DR Shed Results" sheet's "HVAC Temp Reset DR Shed Capacity Calculation": 1. Enter the percent of the floor area of the building for which the HVAC temp reset will be applied (0-100), 2. Select the "Precool Period Temp Offset"; either 0 or -2 °F, and 3. Select the "DR Event Period Temp Offset", either 2, 4, or 6 °F.
B32: Estimated kW sheds are calculated in tables and figures in "User Inputs and DR Shed Results".
B33: Temperature ranges shown in HVAC Temp Reset DR Shed Estimates (kW) are Peak Outside Air Temperatures on weekdays in the following ranges: 1 (60-65°F), 2 (65-70°F), 3 (70-75°F), 4 (75-80°F), 5 (80-85°F), 6 (85-90°F), and 7 (Above 90°F).
B35: Note: Only weekdays are selected for DR shed calculations. Weekends, holidays and ADR days in 2015 (if customer has enrolled into 2015 ADR programs) are excluded.

Sheet IDAR Meter Data
B1: Date
A2: 42125 | B2: 232
A3: 42125.01 | B3: 232
A4: 42125.021 | B4: 207
A5: 42125.031 | B5: 224
A6: 42125.042 | B6: 208
A7: 42125.052 | B7: 208
A8: 42125.062 | B8: 196
A9: 42125.073 | B9: 205
A10: 42125.083 | B10: 196
A11: 42125.094 | B11: 205
A12: 42125.104 | B12: 187
A13: 42125.115 | B13: 185
... A17665: 42308.99 | B17665: 92

Sheet User Inputs and DR Shed Results
A2: User Inputs
A3: ADR Site Description | B3: Data | C3: Note
A4: Name | B4: {id:smallofficecz03-26}
A5: Building Type | B5: Office
A6: HVAC Type | B6: Central Plant | C6: RTU Duty Cycling is not available for HVAC Type "Central Plant".
A7: Zipcode | B7: 94720
A8: NewCustomers | B8: Yes
A10: Peak Demand (kW) | B10: =MAX('IDAR Meter Data'!B:B) -> 322 | C10: From meter data
A11: County | B11: =IFERROR(VLOOKUP(B7,'Climate Zones'!A1:F2557,2,0),"") -> Alameda
A12: PG&E Climate Zone | B12: =IFERROR(VLOOKUP(B7,'Climate Zones'!A2:F2558,4,0),"") -> 4
A13: CEC Climate Zone | B13: =IFERROR(VLOOKUP(B7,'Climate Zones'!A3:F2559,3,0),"") -> 3 | C13: =IF(B13<10,"CZ0"&B13,"CZ"&B13) -> CZ03
A14: Building Size | B14: =IF(B5="Office",IF(B10<200,"SmallOffice",IF(AND(B10>=200,B10<500),"MediumOffice",IF(B10>=500,"LargeOffice"))),IF(B10>0,"Retail")) -> MediumOffice
A17: DR Shed Results of HVAC Temperature Setpoint Reset
A18: HVAC Temp Reset DR Shed Capacity Calculation
A19: Percent of Bldg Floor Area that Temp Reset will Apply (0-100) | B19: 100
A20: Precool Period Temp Offset (°F) | B20: 0
A21: DR Event Period Temp Offset (°F) | B21: 4
A22: Average DR Potential (kW) | B22: =AVERAGE(C28:C34)*AvailPerc/100 -> 25.794371
A23: Min DR Potential (kW) | B23: =MIN(C28:C34)*AvailPerc/100 -> 22.482497
A24: Max DR Potential (kW) | B24: =MAX(C28:C34)*AvailPerc/100 -> 28.712178
A26: HVAC Temp Reset DR Shed Estimates (kW) for Peak Temps in Building's Climate Zone
A27: Temperature Range | B27: Peak OAT (F) | C27: Estimated kW Shed
A28: =CSSB!L3 -> 1 | B28: =CSSB!M3 -> 61.692639 | C28: =AVERAGE('DR Calculation'!J3:J18) -> 22.482497
A29: =CSSB!L4 -> 2 | B29: =CSSB!M4 -> 67.609237 | C29: =AVERAGE('DR Calculation'!J21:J36) -> 23.309812
A30: =CSSB!L5 -> 3 | B30: =CSSB!M5 -> 72.139614 | C30: =AVERAGE('DR Calculation'!J39:J54) -> 24.500756
A31: =CSSB!L6 -> 4 | B31: =CSSB!M6 -> 76.924252 | C31: =AVERAGE('DR Calculation'!J57:J72) -> 25.738436
A32: =CSSB!L7 -> 5 | B32: =CSSB!M7 -> 82.146235 | C32: =AVERAGE('DR Calculation'!J75:J90) -> 28.712178
A33: =CSSB!L8 -> 6 | B33: =CSSB!M8 -> 87.56052 | C33: =AVERAGE('DR Calculation'!J93:J108) -> 28.009207
A34: =CSSB!L9 -> 7 | B34: =CSSB!M9 -> 90.794444 | C34: =AVERAGE('DR Calculation'!J111:J126) -> 27.807713

Sheet CSSB
A1: Date | B1: Date | C1: weekday | D1: Hour | E1: Demand | F1: OAT | G1: TempRange | I1: Holiday and ADR Days | L1: Summary of Load and OAT in Summer
A2: 42125.042 | B2: =DATE(YEAR(A2),MONTH(A2),DAY(A2)) -> 42125 | C2: =IF(NewCustomer="Yes", IF(COUNTIF($I$2:$I$11,B2)>0,0,WEEKDAY(B2,2)),IF(COUNTIF($I$2:$I$21,B2)>0,0,WEEKDAY(B2,2))) -> 5 | D2: =HOUR(A2) -> 1 | E2: =IFERROR(VLOOKUP(A2,'IDAR Meter Data'!$A:$B,2,1),"") -> 208 | F2: =IF(CECCZ="CZ03",'Outside Temp'!B2,IF(CECCZ="CZ04",'Outside Temp'!B3,IF(CECCZ="CZ12",'Outside Temp'!B4, IF(CECCZ="CZ13",'Outside Temp'!B5)))) -> 63.733333 | G2: =IF(F2<=65,1,IF(AND(F2<=70,F2>65),2,IF(AND(F2<=75,F2>70),3,IF(AND(F2<=80,F2>75),4,IF(AND(F2<=85,F2>80),5,IF(AND(F2<=90,F2>85),6,IF(AND(F2<=95,F2>90),7,IF(F2>95,8)))))))) -> 1 | I2: 42005 | J2: New Years' Day | L2: Temp Ranges | M2: Average of OAT | N2: Average of Demand
A3: 42125.052 | B3: =DATE(YEAR(A3),MONTH(A3),DAY(A3)) -> 42125 | C3: =IF(NewCustomer="Yes", IF(COUNTIF($I$2:$I$11,B3)>0,0,WEEKDAY(B3,2)),IF(COUNTIF($I$2:$I$21,B3)>0,0,WEEKDAY(B3,2))) -> 5 | D3: =HOUR(A3) -> 1 | E3: =IFERROR(VLOOKUP(A3,'IDAR Meter Data'!$A:$B,2,1),"") -> 208 | F3: =IF(CECCZ="CZ03",'Outside Temp'!B3,IF(CECCZ="CZ04",'Outside Temp'!B4,IF(CECCZ="CZ12",'Outside Temp'!B5, IF(CECCZ="CZ13",'Outside Temp'!B6)))) -> 62.733333 | G3: =IF(F3<=65,1,IF(AND(F3<=70,F3>65),2,IF(AND(F3<=75,F3>70),3,IF(AND(F3<=80,F3>75),4,IF(AND(F3<=85,F3>80),5,IF(AND(F3<=90,F3>85),6,IF(AND(F3<=95,F3>90),7,IF(F3>95,8)))))))) -> 1 | I3: 42023 | J3: Martin Luther King | L3: 1 | M3: =AVERAGEIFS($F$2:$F$17661,$C$2:$C$17661,">=1",$C$2:$C$17661,"<=5",$G$2:$G$17661,"=1",$D$2:$D$17661,">=12",$D$2:$D$17661,"<=17") -> 61.692639 | N3: =AVERAGEIFS($E$2:$E$17661,$C$2:$C$17661,">=1",$C$2:$C$17661,"<=5",$G$2:$G$17661,"=1",$D$2:$D$17661,">=12",$D$2:$D$17661,"<=17") -> 224.63356
A4: 42125.062 | B4: =DATE(YEAR(A4),MONTH(A4),DAY(A4)) -> 42125 | C4: =IF(NewCustomer="Yes", IF(COUNTIF($I$2:$I$11,B4)>0,0,WEEKDAY(B4,2)),IF(COUNTIF($I$2:$I$21,B4)>0,0,WEEKDAY(B4,2))) -> 5 | D4: =HOUR(A4) -> 1 | E4: =IFERROR(VLOOKUP(A4,'IDAR Meter Data'!$A:$B,2,1),"") -> 196 | F4: =IF(CECCZ="CZ03",'Outside Temp'!B4,IF(CECCZ="CZ04",'Outside Temp'!B5,IF(CECCZ="CZ12",'Outside Temp'!B6, IF(CECCZ="CZ13",'Outside Temp'!B7)))) -> 61.733333 | G4: =IF(F4<=65,1,IF(AND(F4<=70,F4>65),2,IF(AND(F4<=75,F4>70),3,IF(AND(F4<=80,F4>75),4,IF(AND(F4<=85,F4>80),5,IF(AND(F4<=90,F4>85),6,IF(AND(F4<=95,F4>90),7,IF(F4>95,8)))))))) -> 1 | I4: 42051 | J4: Washington's Birthday | L4: 2 | M4: =AVERAGEIFS($F$2:$F$17661,$C$2:$C$17661,">=1",$C$2:$C$17661,"<=5",$G$2:$G$17661,"=2",$D$2:$D$17661,">=12",$D$2:$D$17661,"<=17") -> 67.609237 | N4: =AVERAGEIFS($E$2:$E$17661,$C$2:$C$17661,">=1",$C$2:$C$17661,"<=5",$G$2:$G$17661,"=2",$D$2:$D$17661,">=12",$D$2:$D$17661,"<=17") -> 227.47394
A5: 42125.073 | B5: =DATE(YEAR(A5),MONTH(A5),DAY(A5)) -> 42125 | C5: =IF(NewCustomer="Yes", IF(COUNTIF($I$2:$I$11,B5)>0,0,WEEKDAY(B5,2)),IF(COUNTIF($I$2:$I$21,B5)>0,0,WEEKDAY(B5,2))) -> 5 | D5: =HOUR(A5) -> 1 | E5: =IFERROR(VLOOKUP(A5,'IDAR Meter Data'!$A:$B,2,1),"") -> 205 | F5: =IF(CECCZ="CZ03",'Outside Temp'!B5,IF(CECCZ="CZ04",'Outside Temp'!B6,IF(CECCZ="CZ12",'Outside Temp'!B7, IF(CECCZ="CZ13",'Outside Temp'!B8)))) -> 60.733333 | G5: =IF(F5<=65,1,IF(AND(F5<=70,F5>65),2,IF(AND(F5<=75,F5>70),3,IF(AND(F5<=80,F5>75),4,IF(AND(F5<=85,F5>80),5,IF(AND(F5<=90,F5>85),6,IF(AND(F5<=95,F5>90),7,IF(F5>95,8)))))))) -> 1 | I5: 42149 | J5: Memorial Day | L5: 3 | M5: =AVERAGEIFS($F$2:$F$17661,$C$2:$C$17661,">=1",$C$2:$C$17661,"<=5",$G$2:$G$17661,"=3",$D$2:$D$17661,">=12",$D$2:$D$17661,"<=17") -> 72.139614 | N5: =AVERAGEIFS($E$2:$E$17661,$C$2:$C$17661,">=1",$C$2:$C$17661,"<=5",$G$2:$G$17661,"=3",$D$2:$D$17661,">=12",$D$2:$D$17661,"<=17") -> 234.90573
A6: 42125.083 | B6: =DATE(YEAR(A6),MONTH(A6),DAY(A6)) -> 42125 | C6: =IF(NewCustomer="Yes", IF(COUNTIF($I$2:$I$11,B6)>0,0,WEEKDAY(B6,2)),IF(COUNTIF($I$2:$I$21,B6)>0,0,WEEKDAY(B6,2))) -> 5 | D6: =HOUR(A6) -> 2 | E6: =IFERROR(VLOOKUP(A6,'IDAR Meter Data'!$A:$B,2,1),"") -> 196 | F6: =IF(CECCZ="CZ03",'Outside Temp'!B6,IF(CECCZ="CZ04",'Outside Temp'!B7,IF(CECCZ="CZ12",'Outside Temp'!B8, IF(CECCZ="CZ13",'Outside Temp'!B9)))) -> 59.933333 | G6: =IF(F6<=65,1,IF(AND(F6<=70,F6>65),2,IF(AND(F6<=75,F6>70),3,IF(AND(F6<=80,F6>75),4,IF(AND(F6<=85,F6>80),5,IF(AND(F6<=90,F6>85),6,IF(AND(F6<=95,F6>90),7,IF(F6>95,8)))))))) -> 1 | I6: 42188 | J6: Independence Day | L6: 4 | M6: =AVERAGEIFS($F$2:$F$17661,$C$2:$C$17661,">=1",$C$2:$C$17661,"<=5",$G$2:$G$17661,"=4",$D$2:$D$17661,">=12",$D$2:$D$17661,"<=17") -> 76.924252 | N6: =AVERAGEIFS($E$2:$E$17661,$C$2:$C$17661,">=1",$C$2:$C$17661,"<=5",$G$2:$G$17661,"=4",$D$2:$D$17661,">=12",$D$2:$D$17661,"<=17") -> 242.28767
A7: 42125.094 | B7: =DATE(YEAR(A7),MONTH(A7),DAY(A7)) -> 42125 | C7: =IF(NewCustomer="Yes", IF(COUNTIF($I$2:$I$11,B7)>0,0,WEEKDAY(B7,2)),IF(COUNTIF($I$2:$I$21,B7)>0,0,WEEKDAY(B7,2))) -> 5 | D7: =HOUR(A7) -> 2 | E7: =IFERROR(VLOOKUP(A7,'IDAR Meter Data'!$A:$B,2,1),"") -> 205 | F7: =IF(CECCZ="CZ03",'Outside Temp'!B7,IF(CECCZ="CZ04",'Outside Temp'!B8,IF(CECCZ="CZ12",'Outside Temp'!B9, IF(CECCZ="CZ13",'Outside Temp'!B10)))) -> 59.683333 | G7: =IF(F7<=65,1,IF(AND(F7<=70,F7>65),2,IF(AND(F7<=75,F7>70),3,IF(AND(F7<=80,F7>75),4,IF(AND(F7<=85,F7>80),5,IF(AND(F7<=90,F7>85),6,IF(AND(F7<=95,F7>90),7,IF(F7>95,8)))))))) -> 1 | I7: 42254 | J7: Labor Day | L7: 5 | M7: =AVERAGEIFS($F$2:$F$17661,$C$2:$C$17661,">=1",$C$2:$C$17661,"<=5",$G$2:$G$17661,"=5",$D$2:$D$17661,">=12",$D$2:$D$17661,"<=17") -> 82.146235 | N7: =AVERAGEIFS($E$2:$E$17661,$C$2:$C$17661,">=1",$C$2:$C$17661,"<=5",$G$2:$G$17661,"=5",$D$2:$D$17661,">=12",$D$2:$D$17661,"<=17") -> 265.02439
A8: 42125.104 | B8: =DATE(YEAR(A8),MONTH(A8),DAY(A8)) -> 42125 | C8: =IF(NewCustomer="Yes", IF(COUNTIF($I$2:$I$11,B8)>0,0,WEEKDAY(B8,2)),IF(COUNTIF($I$2:$I$21,B8)>0,0,WEEKDAY(B8,2))) -> 5 | D8: =HOUR(A8) -> 2 | E8: =IFERROR(VLOOKUP(A8,'IDAR Meter Data'!$A:$B,2,1),"") -> 187 | F8: =IF(CECCZ="CZ03",'Outside Temp'!B8,IF(CECCZ="CZ04",'Outside Temp'!B9,IF(CECCZ="CZ12",'Outside Temp'!B10, IF(CECCZ="CZ13",'Outside Temp'!B11)))) -> 59.433333 | G8: =IF(F8<=65,1,IF(AND(F8<=70,F8>65),2,IF(AND(F8<=75,F8>70),3,IF(AND(F8<=80,F8>75),4,IF(AND(F8<=85,F8>80),5,IF(AND(F8<=90,F8>85),6,IF(AND(F8<=95,F8>90),7,IF(F8>95,8)))))))) -> 1 | I8: 42289 | J8: Columbus Day | L8: 6 | M8: =AVERAGEIFS($F$2:$F$17661,$C$2:$C$17661,">=1",$C$2:$C$17661,"<=5",$G$2:$G$17661,"=6",$D$2:$D$17661,">=12",$D$2:$D$17661,"<=17") -> 87.56052 | N8: =AVERAGEIFS($E$2:$E$17661,$C$2:$C$17661,">=1",$C$2:$C$17661,"<=5",$G$2:$G$17661,"=6",$D$2:$D$17661,">=12",$D$2:$D$17661,"<=17") -> 253.42553
A9: 42125.115 | B9: =DATE(YEAR(A9),MONTH(A9),DAY(A9)) -> 42125 | C9: =IF(NewCustomer="Yes", IF(COUNTIF($I$2:$I$11,B9)>0,0,WEEKDAY(B9,2)),IF(COUNTIF($I$2:$I$21,B9)>0,0,WEEKDAY(B9,2))) -> 5 | D9: =HOUR(A9) -> 2 | E9: =IFERROR(VLOOKUP(A9,'IDAR Meter Data'!$A:$B,2,1),"") -> 185 | F9: =IF(CECCZ="CZ03",'Outside Temp'!B9,IF(CECCZ="CZ04",'Outside Temp'!B10,IF(CECCZ="CZ12",'Outside Temp'!B11, IF(CECCZ="CZ13",'Outside Temp'!B12)))) -> 59.183333 | G9: =IF(F9<=65,1,IF(AND(F9<=70,F9>65),2,IF(AND(F9<=75,F9>70),3,IF(AND(F9<=80,F9>75),4,IF(AND(F9<=85,F9>80),5,IF(AND(F9<=90,F9>85),6,IF(AND(F9<=95,F9>90),7,IF(F9>95,8)))))))) -> 1 | I9: 42319 | J9: Veterans Day | L9: 7 | M9: =AVERAGEIFS($F$2:$F$17661,$C$2:$C$17661,">=1",$C$2:$C$17661,"<=5",$G$2:$G$17661,"=7",$D$2:$D$17661,">=12",$D$2:$D$17661,"<=17") -> 90.794444 | N9: =AVERAGEIFS($E$2:$E$17661,$C$2:$C$17661,">=1",$C$2:$C$17661,"<=5",$G$2:$G$17661,"=7",$D$2:$D$17661,">=12",$D$2:$D$17661,"<=17") -> 248.66667
A10: 42125.125 | B10: =DATE(YEAR(A10),MONTH(A10),DAY(A10)) -> 42125 | C10: =IF(NewCustomer="Yes", IF(COUNTIF($I$2:$I$11,B10)>0,0,WEEKDAY(B10,2)),IF(COUNTIF($I$2:$I$21,B10)>0,0,WEEKDAY(B10,2))) -> 5 | D10: =HOUR(A10) -> 3 | E10: =IFERROR(VLOOKUP(A10,'IDAR Meter Data'!$A:$B,2,1),"") -> 169 | F10: =IF(CECCZ="CZ03",'Outside Temp'!B10,IF(CECCZ="CZ04",'Outside Temp'!B11,IF(CECCZ="CZ12",'Outside Temp'!B12, IF(CECCZ="CZ13",'Outside Temp'!B13)))) -> 58.933333 | G10: =IF(F10<=65,1,IF(AND(F10<=70,F10>65),2,IF(AND(F10<=75,F10>70),3,IF(AND(F10<=80,F10>75),4,IF(AND(F10<=85,F10>80),5,IF(AND(F10<=90,F10>85),6,IF(AND(F10<=95,F10>90),7,IF(F10>95,8)))))))) -> 1 | I10: 42334 | J10: Thanksgiving Day
A11: 42125.135 | B11: =DATE(YEAR(A11),MONTH(A11),DAY(A11)) -> 42125 | C11: =IF(NewCustomer="Yes", IF(COUNTIF($I$2:$I$11,B11)>0,0,WEEKDAY(B11,2)),IF(COUNTIF($I$2:$I$21,B11)>0,0,WEEKDAY(B11,2))) -> 5 | D11: =HOUR(A11) -> 3 | E11: =IFERROR(VLOOKUP(A11,'IDAR Meter Data'!$A:$B,2,1),"") -> 180 | F11: =IF(CECCZ="CZ03",'Outside Temp'!B11,IF(CECCZ="CZ04",'Outside Temp'!B12,IF(CECCZ="CZ12",'Outside Temp'!B13, IF(CECCZ="CZ13",'Outside Temp'!B14)))) -> 58.683333 | G11: =IF(F11<=65,1,IF(AND(F11<=70,F11>65),2,IF(AND(F11<=75,F11>70),3,IF(AND(F11<=80,F11>75),4,IF(AND(F11<=85,F11>80),5,IF(AND(F11<=90,F11>85),6,IF(AND(F11<=95,F11>90),7,IF(F11>95,8)))))))) -> 1 | I11: 42363 | J11: Christmas Day
A12: 42125.146 | B12: =DATE(YEAR(A12),MONTH(A12),DAY(A12)) -> 42125 | C12: =IF(NewCustomer="Yes", IF(COUNTIF($I$2:$I$11,B12)>0,0,WEEKDAY(B12,2)),IF(COUNTIF($I$2:$I$21,B12)>0,0,WEEKDAY(B12,2))) -> 5 | D12: =HOUR(A12) -> 3 | E12: =IFERROR(VLOOKUP(A12,'IDAR Meter Data'!$A:$B,2,1),"") -> 171 | F12: =IF(CECCZ="CZ03",'Outside Temp'!B12,IF(CECCZ="CZ04",'Outside Temp'!B13,IF(CECCZ="CZ12",'Outside Temp'!B14, IF(CECCZ="CZ13",'Outside Temp'!B15)))) -> 58.433333 | G12: =IF(F12<=65,1,IF(AND(F12<=70,F12>65),2,IF(AND(F12<=75,F12>70),3,IF(AND(F12<=80,F12>75),4,IF(AND(F12<=85,F12>80),5,IF(AND(F12<=90,F12>85),6,IF(AND(F12<=95,F12>90),7,IF(F12>95,8)))))))) -> 1 | I12: 42167 | J12: 2015 ADR Days | L12: range_id | M12: avg_temp | N12: avg_demand
A13: 42125.156 | B13: =DATE(YEAR(A13),MONTH(A13),DAY(A13)) -> 42125 | C13: =IF(NewCustomer="Yes", IF(COUNTIF($I$2:$I$11,B13)>0,0,WEEKDAY(B13,2)),IF(COUNTIF($I$2:$I$21,B13)>0,0,WEEKDAY(B13,2))) -> 5 | D13: =HOUR(A13) -> 3 | E13: =IFERROR(VLOOKUP(A13,'IDAR Meter Data'!$A:$B,2,1),"") -> 180 | F13: =IF(CECCZ="CZ03",'Outside Temp'!B13,IF(CECCZ="CZ04",'Outside Temp'!B14,IF(CECCZ="CZ12",'Outside Temp'!B15, IF(CECCZ="CZ13",'Outside Temp'!B16)))) -> 58.183333 | G13: =IF(F13<=65,1,IF(AND(F13<=70,F13>65),2,IF(AND(F13<=75,F13>70),3,IF(AND(F13<=80,F13>75),4,IF(AND(F13<=85,F13>80),5,IF(AND(F13<=90,F13>85),6,IF(AND(F13<=95,F13>90),7,IF(F13>95,8)))))))) -> 1 | I13: 42180 | J13: 2015 ADR Days | L13: 1 | M13: 61.678659 | N13: 225.05376
A14: 42125.167 | B14: =DATE(YEAR(A14),MONTH(A14),DAY(A14)) -> 42125 | C14: =IF(NewCustomer="Yes", IF(COUNTIF($I$2:$I$11,B14)>0,0,WEEKDAY(B14,2)),IF(COUNTIF($I$2:$I$21,B14)>0,0,WEEKDAY(B14,2))) -> 5 | D14: =HOUR(A14) -> 4 | E14: =IFERROR(VLOOKUP(A14,'IDAR Meter Data'!$A:$B,2,1),"") -> 163 | F14: =IF(CECCZ="CZ03",'Outside Temp'!B14,IF(CECCZ="CZ04",'Outside Temp'!B15,IF(CECCZ="CZ12",'Outside Temp'!B16, IF(CECCZ="CZ13",'Outside Temp'!B17)))) -> 58 | G14: =IF(F14<=65,1,IF(AND(F14<=70,F14>65),2,IF(AND(F14<=75,F14>70),3,IF(AND(F14<=80,F14>75),4,IF(AND(F14<=85,F14>80),5,IF(AND(F14<=90,F14>85),6,IF(AND(F14<=95,F14>90),7,IF(F14>95,8)))))))) -> 1 | I14: 42181 | J14: 2015 ADR Days | L14: 2 | M14: 67.586186 | N14: 228.06927
A15: 42125.177 | B15: =DATE(YEAR(A15),MONTH(A15),DAY(A15)) -> 42125 | C15: =IF(NewCustomer="Yes", IF(COUNTIF($I$2:$I$11,B15)>0,0,WEEKDAY(B15,2)),IF(COUNTIF($I$2:$I$21,B15)>0,0,WEEKDAY(B15,2))) -> 5 | D15: =HOUR(A15) -> 4 | E15: =IFERROR(VLOOKUP(A15,'IDAR Meter Data'!$A:$B,2,1),"") -> 174 | F15: =IF(CECCZ="CZ03",'Outside Temp'!B15,IF(CECCZ="CZ04",'Outside Temp'!B16,IF(CECCZ="CZ12",'Outside Temp'!B17, IF(CECCZ="CZ13",'Outside Temp'!B18)))) -> 58 | G15: =IF(F15<=65,1,IF(AND(F15<=70,F15>65),2,IF(AND(F15<=75,F15>70),3,IF(AND(F15<=80,F15>75),4,IF(AND(F15<=85,F15>80),5,IF(AND(F15<=90,F15>85),6,IF(AND(F15<=95,F15>90),7,IF(F15>95,8)))))))) -> 1 | I15: 42186 | J15: 2015 ADR Days | L15: 3 | M15: 72.143406 | N15: 234.61406
A16: 42125.188 | B16: =DATE(YEAR(A16),MONTH(A16),DAY(A16)) -> 42125 | C16: =IF(NewCustomer="Yes", IF(COUNTIF($I$2:$I$11,B16)>0,0,WEEKDAY(B16,2)),IF(COUNTIF($I$2:$I$21,B16)>0,0,WEEKDAY(B16,2))) -> 5 | D16: =HOUR(A16) -> 4 | E16: =IFERROR(VLOOKUP(A16,'IDAR Meter Data'!$A:$B,2,1),"") -> 172 | F16: =IF(CECCZ="CZ03",'Outside Temp'!B16,IF(CECCZ="CZ04",'Outside Temp'!B17,IF(CECCZ="CZ12",'Outside Temp'!B18, IF(CECCZ="CZ13",'Outside Temp'!B19)))) -> 58 | G16: =IF(F16<=65,1,IF(AND(F16<=70,F16>65),2,IF(AND(F16<=75,F16>70),3,IF(AND(F16<=80,F16>75),4,IF(AND(F16<=85,F16>80),5,IF(AND(F16<=90,F16>85),6,IF(AND(F16<=95,F16>90),7,IF(F16>95,8)))))))) -> 1 | I16: 42213 | J16: 2015 ADR Days | L16: 4 | M16: 76.927068 | N16: 241.85308
A17: 42125.198 | B17: =DATE(YEAR(A17),MONTH(A17),DAY(A17)) -> 42125 | C17: =IF(NewCustomer="Yes", IF(COUNTIF($I$2:$I$11,B17)>0,0,WEEKDAY(B17,2)),IF(COUNTIF($I$2:$I$21,B17)>0,0,WEEKDAY(B17,2))) -> 5 | D17: =HOUR(A17) -> 4 | E17: =IFERROR(VLOOKUP(A17,'IDAR Meter Data'!$A:$B,2,1),"") -> 167 | F17: =IF(CECCZ="CZ03",'Outside Temp'!B17,IF(CECCZ="CZ04",'Outside Temp'!B18,IF(CECCZ="CZ12",'Outside Temp'!B19, IF(CECCZ="CZ13",'Outside Temp'!B20)))) -> 58 | G17: =IF(F17<=65,1,IF(AND(F17<=70,F17>65),2,IF(AND(F17<=75,F17>70),3,IF(AND(F17<=80,F17>75),4,IF(AND(F17<=85,F17>80),5,IF(AND(F17<=90,F17>85),6,IF(AND(F17<=95,F17>90),7,IF(F17>95,8)))))))) -> 1 | I17: 42214 | J17: 2015 ADR Days | L17: 5 | M17: 82.151587 | N17: 265.62025
A18: 42125.208 | B18: =DATE(YEAR(A18),MONTH(A18),DAY(A18)) -> 42125 | C18: =IF(NewCustomer="Yes", IF(COUNTIF($I$2:$I$11,B18)>0,0,WEEKDAY(B18,2)),IF(COUNTIF($I$2:$I$21,B18)>0,0,WEEKDAY(B18,2))) -> 5 | D18: =HOUR(A18) -> 5 | E18: =IFERROR(VLOOKUP(A18,'IDAR Meter Data'!$A:$B,2,1),"") -> 166 | F18: =IF(CECCZ="CZ03",'Outside Temp'!B18,IF(CECCZ="CZ04",'Outside Temp'!B19,IF(CECCZ="CZ12",'Outside Temp'!B20, IF(CECCZ="CZ13",'Outside Temp'!B21)))) -> 58.066667 | G18: =IF(F18<=65,1,IF(AND(F18<=70,F18>65),2,IF(AND(F18<=75,F18>70),3,IF(AND(F18<=80,F18>75),4,IF(AND(F18<=85,F18>80),5,IF(AND(F18<=90,F18>85),6,IF(AND(F18<=95,F18>90),7,IF(F18>95,8)))))))) -> 1 | I18: 42215 | J18: 2015 ADR Days | L18: 6 | M18: 87.592995 | N18: 251.02174
A19: 42125.219 | B19: =DATE(YEAR(A19),MONTH(A19),DAY(A19)) -> 42125 | C19: =IF(NewCustomer="Yes", IF(COUNTIF($I$2:$I$11,B19)>0,0,WEEKDAY(B19,2)),IF(COUNTIF($I$2:$I$21,B19)>0,0,WEEKDAY(B19,2))) -> 5 | D19: =HOUR(A19) -> 5 | E19: =IFERROR(VLOOKUP(A19,'IDAR Meter Data'!$A:$B,2,1),"") -> 163 | F19: =IF(CECCZ="CZ03",'Outside Temp'!B19,IF(CECCZ="CZ04",'Outside Temp'!B20,IF(CECCZ="CZ12",'Outside Temp'!B21, IF(CECCZ="CZ13",'Outside Temp'!B22)))) -> 58.316667 | G19: =IF(F19<=65,1,IF(AND(F19<=70,F19>65),2,IF(AND(F19<=75,F19>70),3,IF(AND(F19<=80,F19>75),4,IF(AND(F19<=85,F19>80),5,IF(AND(F19<=90,F19>85),6,IF(AND(F19<=95,F19>90),7,IF(F19>95,8)))))))) -> 1 | I19: 42233 | J19: 2015 ADR Days | L19: 7 | M19: 90.794444 | N19: 253.66667
A20: 42125.229 | B20: =DATE(YEAR(A20),MONTH(A20),DAY(A20)) -> 42125 | C20: =IF(NewCustomer="Yes", IF(COUNTIF($I$2:$I$11,B20)>0,0,WEEKDAY(B20,2)),IF(COUNTIF($I$2:$I$21,B20)>0,0,WEEKDAY(B20,2))) -> 5 | D20: =HOUR(A20) -> 5 | E20: =IFERROR(VLOOKUP(A20,'IDAR Meter Data'!$A:$B,2,1),"") -> 161 | F20: =IF(CECCZ="CZ03",'Outside Temp'!B20,IF(CECCZ="CZ04",'Outside Temp'!B21,IF(CECCZ="CZ12",'Outside Temp'!B22, IF(CECCZ="CZ13",'Outside Temp'!B23)))) -> 58.566667 | G20: =IF(F20<=65,1,IF(AND(F20<=70,F20>65),2,IF(AND(F20<=75,F20>70),3,IF(AND(F20<=80,F20>75),4,IF(AND(F20<=85,F20>80),5,IF(AND(F20<=90,F20>85),6,IF(AND(F20<=95,F20>90),7,IF(F20>95,8)))))))) -> 1 | I20: 42234 | J20: 2015 ADR Days
A21: 42125.24 | B21: =DATE(YEAR(A21),MONTH(A21),DAY(A21)) -> 42125 | C21: =IF(NewCustomer="Yes", IF(COUNTIF($I$2:$I$11,B21)>0,0,WEEKDAY(B21,2)),IF(COUNTIF($I$2:$I$21,B21)>0,0,WEEKDAY(B21,2))) -> 5 | D21: =HOUR(A21) -> 5 | E21: =IFERROR(VLOOKUP(A21,'IDAR Meter Data'!$A:$B,2,1),"") -> 169 | F21: =IF(CECCZ="CZ03",'Outside Temp'!B21,IF(CECCZ="CZ04",'Outside Temp'!B22,IF(CECCZ="CZ12",'Outside Temp'!B23, IF(CECCZ="CZ13",'Outside Temp'!B24)))) -> 58.816667 | G21: =IF(F21<=65,1,IF(AND(F21<=70,F21>65),2,IF(AND(F21<=75,F21>70),3,IF(AND(F21<=80,F21>75),4,IF(AND(F21<=85,F21>80),5,IF(AND(F21<=90,F21>85),6,IF(AND(F21<=95,F21>90),7,IF(F21>95,8)))))))) -> 1 | I21: 42243 | J21: 2015 ADR Days
A22: 42125.25 | B22: =DATE(YEAR(A22),MONTH(A22),DAY(A22)) -> 42125 | C22: =IF(NewCustomer="Yes", IF(COUNTIF($I$2:$I$11,B22)>0,0,WEEKDAY(B22,2)),IF(COUNTIF($I$2:$I$21,B22)>0,0,WEEKDAY(B22,2))) -> 5 | D22: =HOUR(A22) -> 6 | E22: =IFERROR(VLOOKUP(A22,'IDAR Meter Data'!$A:$B,2,1),"") -> 158 | F22: =IF(CECCZ="CZ03",'Outside Temp'!B22,IF(CECCZ="CZ04",'Outside Temp'!B23,IF(CECCZ="CZ12",'Outside Temp'!B24, IF(CECCZ="CZ13",'Outside Temp'!B25)))) -> 59.266667 | G22: =IF(F22<=65,1,IF(AND(F22<=70,F22>65),2,IF(AND(F22<=75,F22>70),3,IF(AND(F22<=80,F22>75),4,IF(AND(F22<=85,F22>80),5,IF(AND(F22<=90,F22>85),6,IF(AND(F22<=95,F22>90),7,IF(F22>95,8)))))))) -> 1
A23: 42125.26 | B23: =DATE(YEAR(A23),MONTH(A23),DAY(A23)) -> 42125 | C23: =IF(NewCustomer="Yes", IF(COUNTIF($I$2:$I$11,B23)>0,0,WEEKDAY(B23,2)),IF(COUNTIF($I$2:$I$21,B23)>0,0,WEEKDAY(B23,2))) -> 5 | D23: =HOUR(A23) -> 6 | E23: =IFERROR(VLOOKUP(A23,'IDAR Meter Data'!$A:$B,2,1),"") -> 167 | F23: =IF(CECCZ="CZ03",'Outside Temp'!B23,IF(CECCZ="CZ04",'Outside Temp'!B24,IF(CECCZ="CZ12",'Outside Temp'!B25, IF(CECCZ="CZ13",'Outside Temp'!B26)))) -> 60.266667 | G23: =IF(F23<=65,1,IF(AND(F23<=70,F23>65),2,IF(AND(F23<=75,F23>70),3,IF(AND(F23<=80,F23>75),4,IF(AND(F23<=85,F23>80),5,IF(AND(F23<=90,F23>85),6,IF(AND(F23<=95,F23>90),7,IF(F23>95,8)))))))) -> 1
A24: 42125.271 | B24: =DATE(YEAR(A24),MONTH(A24),DAY(A24)) -> 42125 | C24: =IF(NewCustomer="Yes", IF(COUNTIF($I$2:$I$11,B24)>0,0,WEEKDAY(B24,2)),IF(COUNTIF($I$2:$I$21,B24)>0,0,WEEKDAY(B24,2))) -> 5 | D24: =HOUR(A24) -> 6 | E24: =IFERROR(VLOOKUP(A24,'IDAR Meter Data'!$A:$B,2,1),"") -> 173 | F24: =IF(CECCZ="CZ03",'Outside Temp'!B24,IF(CECCZ="CZ04",'Outside Temp'!B25,IF(CECCZ="CZ12",'Outside Temp'!B26, IF(CECCZ="CZ13",'Outside Temp'!B27)))) -> 61.266667 | G24: =IF(F24<=65,1,IF(AND(F24<=70,F24>65),2,IF(AND(F24<=75,F24>70),3,IF(AND(F24<=80,F24>75),4,IF(AND(F24<=85,F24>80),5,IF(AND(F24<=90,F24>85),6,IF(AND(F24<=95,F24>90),7,IF(F24>95,8)))))))) -> 1
A25: 42125.281 | B25: =DATE(YEAR(A25),MONTH(A25),DAY(A25)) -> 42125 | C25: =IF(NewCustomer="Yes", IF(COUNTIF($I$2:$I$11,B25)>0,0,WEEKDAY(B25,2)),IF(COUNTIF($I$2:$I$21,B25)>0,0,WEEKDAY(B25,2))) -> 5 | D25: =HOUR(A25) -> 6 | E25: =IFERROR(VLOOKUP(A25,'IDAR Meter Data'!$A:$B,2,1),"") -> 164 | F25: =IF(CECCZ="CZ03",'Outside Temp'!B25,IF(CECCZ="CZ04",'Outside Temp'!B26,IF(CECCZ="CZ12",'Outside Temp'!B27, IF(CECCZ="CZ13",'Outside Temp'!B28)))) -> 62.266667 | G25: =IF(F25<=65,1,IF(AND(F25<=70,F25>65),2,IF(AND(F25<=75,F25>70),3,IF(AND(F25<=80,F25>75),4,IF(AND(F25<=85,F25>80),5,IF(AND(F25<=90,F25>85),6,IF(AND(F25<=95,F25>90),7,IF(F25>95,8)))))))) -> 1
A26: 42125.292 | B26: =DATE(YEAR(A26),MONTH(A26),DAY(A26)) -> 42125 | C26: =IF(NewCustomer="Yes", IF(COUNTIF($I$2:$I$11,B26)>0,0,WEEKDAY(B26,2)),IF(COUNTIF($I$2:$I$21,B26)>0,0,WEEKDAY(B26,2))) -> 5 | D26: =HOUR(A26) -> 7 | E26: =IFERROR(VLOOKUP(A26,'IDAR Meter Data'!$A:$B,2,1),"") -> 176 | F26: =IF(CECCZ="CZ03",'Outside Temp'!B26,IF(CECCZ="CZ04",'Outside Temp'!B27,IF(CECCZ="CZ12",'Outside Temp'!B28, IF(CECCZ="CZ13",'Outside Temp'!B29)))) -> 63.4 | G26: =IF(F26<=65,1,IF(AND(F26<=70,F26>65),2,IF(AND(F26<=75,F26>70),3,IF(AND(F26<=80,F26>75),4,IF(AND(F26<=85,F26>80),5,IF(AND(F26<=90,F26>85),6,IF(AND(F26<=95,F26>90),7,IF(F26>95,8)))))))) -> 1
A27: 42125.302 | B27: =DATE(YEAR(A27),MONTH(A27),DAY(A27)) -> 42125 | C27: =IF(NewCustomer="Yes", IF(COUNTIF($I$2:$I$11,B27)>0,0,WEEKDAY(B27,2)),IF(COUNTIF($I$2:$I$21,B27)>0,0,WEEKDAY(B27,2))) -> 5 | D27: =HOUR(A27) -> 7 | E27: =IFERROR(VLOOKUP(A27,'IDAR Meter Data'!$A:$B,2,1),"") -> 168 | F27: =IF(CECCZ="CZ03",'Outside Temp'!B27,IF(CECCZ="CZ04",'Outside Temp'!B28,IF(CECCZ="CZ12",'Outside Temp'!B29, IF(CECCZ="CZ13",'Outside Temp'!B30)))) -> 64.9 | G27: =IF(F27<=65,1,IF(AND(F27<=70,F27>65),2,IF(AND(F27<=75,F27>70),3,IF(AND(F27<=80,F27>75),4,IF(AND(F27<=85,F27>80),5,IF(AND(F27<=90,F27>85),6,IF(AND(F27<=95,F27>90),7,IF(F27>95,8)))))))) -> 1
A28: 42125.312 | B28: =DATE(YEAR(A28),MONTH(A28),DAY(A28)) -> 42125 | C28: =IF(NewCustomer="Yes", IF(COUNTIF($I$2:$I$11,B28)>0,0,WEEKDAY(B28,2)),IF(COUNTIF($I$2:$I$21,B28)>0,0,WEEKDAY(B28,2))) -> 5 | D28: =HOUR(A28) -> 7 | E28: =IFERROR(VLOOKUP(A28,'IDAR Meter Data'!$A:$B,2,1),"") -> 179 | F28: =IF(CECCZ="CZ03",'Outside Temp'!B28,IF(CECCZ="CZ04",'Outside Temp'!B29,IF(CECCZ="CZ12",'Outside Temp'!B30, IF(CECCZ="CZ13",'Outside Temp'!B31)))) -> 66.4 | G28: =IF(F28<=65,1,IF(AND(F28<=70,F28>65),2,IF(AND(F28<=75,F28>70),3,IF(AND(F28<=80,F28>75),4,IF(AND(F28<=85,F28>80),5,IF(AND(F28<=90,F28>85),6,IF(AND(F28<=95,F28>90),7,IF(F28>95,8)))))))) -> 2
A29: 42125.323 | B29: =DATE(YEAR(A29),MONTH(A29),DAY(A29)) -> 42125 | C29: =IF(NewCustomer="Yes", IF(COUNTIF($I$2:$I$11,B29)>0,0,WEEKDAY(B29,2)),IF(COUNTIF($I$2:$I$21,B29)>0,0,WEEKDAY(B29,2))) -> 5 | D29: =HOUR(A29) -> 7 | E29: =IFERROR(VLOOKUP(A29,'IDAR Meter Data'!$A:$B,2,1),"") -> 178 | F29: =IF(CECCZ="CZ03",'Outside Temp'!B29,IF(CECCZ="CZ04",'Outside Temp'!B30,IF(CECCZ="CZ12",'Outside Temp'!B31, IF(CECCZ="CZ13",'Outside Temp'!B32)))) -> 67.9 | G29: =IF(F29<=65,1,IF(AND(F29<=70,F29>65),2,IF(AND(F29<=75,F29>70),3,IF(AND(F29<=80,F29>75),4,IF(AND(F29<=85,F29>80),5,IF(AND(F29<=90,F29>85),6,IF(AND(F29<=95,F29>90),7,IF(F29>95,8)))))))) -> 2
A30: 42125.333 | B30: =DATE(YEAR(A30),MONTH(A30),DAY(A30)) -> 42125 | C30: =IF(NewCustomer="Yes", IF(COUNTIF($I$2:$I$11,B30)>0,0,WEEKDAY(B30,2)),IF(COUNTIF($I$2:$I$21,B30)>0,0,WEEKDAY(B30,2))) -> 5 | D30: =HOUR(A30) -> 8 | E30: =IFERROR(VLOOKUP(A30,'IDAR Meter Data'!$A:$B,2,1),"") -> 183 | F30: =IF(CECCZ="CZ03",'Outside Temp'!B30,IF(CECCZ="CZ04",'Outside Temp'!B31,IF(CECCZ="CZ12",'Outside Temp'!B32, IF(CECCZ="CZ13",'Outside Temp'!B33)))) -> 68.8 | G30: =IF(F30<=65,1,IF(AND(F30<=70,F30>65),2,IF(AND(F30<=75,F30>70),3,IF(AND(F30<=80,F30>75),4,IF(AND(F30<=85,F30>80),5,IF(AND(F30<=90,F30>85),6,IF(AND(F30<=95,F30>90),7,IF(F30>95,8)))))))) -> 2
A31: 42125.344 | B31: =DATE(YEAR(A31),MONTH(A31),DAY(A31)) -> 42125 | C31: =IF(NewCustomer="Yes", IF(COUNTIF($I$2:$I$11,B31)>0,0,WEEKDAY(B31,2)),IF(COUNTIF($I$2:$I$21,B31)>0,0,WEEKDAY(B31,2))) -> 5 | D31: =HOUR(A31) -> 8 | E31: =IFERROR(VLOOKUP(A31,'IDAR Meter Data'!$A:$B,2,1),"") -> 223 | F31: =IF(CECCZ="CZ03",'Outside Temp'!B31,IF(CECCZ="CZ04",'Outside Temp'!B32,IF(CECCZ="CZ12",'Outside Temp'!B33, IF(CECCZ="CZ13",'Outside Temp'!B34)))) -> 68.05 | G31: =IF(F31<=65,1,IF(AND(F31<=70,F31>65),2,IF(AND(F31<=75,F31>70),3,IF(AND(F31<=80,F31>75),4,IF(AND(F31<=85,F31>80),5,IF(AND(F31<=90,F31>85),6,IF(AND(F31<=95,F31>90),7,IF(F31>95,8)))))))) -> 2
A32: 42125.354 | B32: =DATE(YEAR(A32),MONTH(A32),DAY(A32)) -> 42125 | C32: =IF(NewCustomer="Yes", IF(COUNTIF($I$2:$I$11,B32)>0,0,WEEKDAY(B32,2)),IF(COUNTIF($I$2:$I$21,B32)>0,0,WEEKDAY(B32,2))) -> 5 | D32: =HOUR(A32) -> 8 | E32: =IFERROR(VLOOKUP(A32,'IDAR Meter Data'!$A:$B,2,1),"") -> 210 | F32: =IF(CECCZ="CZ03",'Outside Temp'!B32,IF(CECCZ="CZ04",'Outside Temp'!B33,IF(CECCZ="CZ12",'Outside Temp'!B34, IF(CECCZ="CZ13",'Outside Temp'!B35)))) -> 67.3 | G32: =IF(F32<=65,1,IF(AND(F32<=70,F32>65),2,IF(AND(F32<=75,F32>70),3,IF(AND(F32<=80,F32>75),4,IF(AND(F32<=85,F32>80),5,IF(AND(F32<=90,F32>85),6,IF(AND(F32<=95,F32>90),7,IF(F32>95,8)))))))) -> 2
A33: 42125.365 | B33: =DATE(YEAR(A33),MONTH(A33),DAY(A33)) -> 42125 | C33: =IF(NewCustomer="Yes", IF(COUNTIF($I$2:$I$11,B33)>0,0,WEEKDAY(B33,2)),IF(COUNTIF($I$2:$I$21,B33)>0,0,WEEKDAY(B33,2))) -> 5 | D33: =HOUR(A33) -> 8 | E33: =IFERROR(VLOOKUP(A33,'IDAR Meter Data'!$A:$B,2,1),"") -> 251 | F33: =IF(CECCZ="CZ03",'Outside Temp'!B33,IF(CECCZ="CZ04",'Outside Temp'!B34,IF(CECCZ="CZ12",'Outside Temp'!B35, IF(CECCZ="CZ13",'Outside Temp'!B36)))) -> 66.55 | G33: =IF(F33<=65,1,IF(AND(F33<=70,F33>65),2,IF(AND(F33<=75,F33>70),3,IF(AND(F33<=80,F33>75),4,IF(AND(F33<=85,F33>80),5,IF(AND(F33<=90,F33>85),6,IF(AND(F33<=95,F33>90),7,IF(F33>95,8)))))))) -> 2
... A17661: 42308.99 | B17661: =DATE(YEAR(A17661),MONTH(A17661),DAY(A17661)) -> 42308 | C17661: =IF(NewCustomer="Yes", IF(COUNTIF($I$2:$I$11,B17661)>0,0,WEEKDAY(B17661,2)),IF(COUNTIF($I$2:$I$21,B17661)>0,0,WEEKDAY(B17661,2))) -> 6 | D17661: =HOUR(A17661) -> 23 | E17661: =IFERROR(VLOOKUP(A17661,'IDAR Meter Data'!$A:$B,2,1),"") -> 92 | F17661: =IF(CECCZ="CZ03",'Outside Temp'!B17661,IF(CECCZ="CZ04",'Outside Temp'!B17662,IF(CECCZ="CZ12",'Outside Temp'!B17663, IF(CECCZ="CZ13",'Outside Temp'!B17664)))) -> 61 | G17661: =IF(F17661<=65,1,IF(AND(F17661<=70,F17661>65),2,IF(AND(F17661<=75,F17661>70),3,IF(AND(F17661<=80,F17661>75),4,IF(AND(F17661<=85,F17661>80),5,IF(AND(F17661<=90,F17661>85),6,IF(AND(F17661<=95,F17661>90),7,IF(F17661>95,8)))))))) -> 1

Sheet DR Calculation
A1: ='User Inputs and DR Shed Results'!B14 -> MediumOffice | B1: =CECCZ -> CZ03 | G1: precool | H1: temp reset
B2: TempRange | C2: hour | D2: power | E2: oat | F2: range | G2: =PrecoolDegrees -> 0 | H2: =TempResetDegrees -> 4 | I2: DR% | J2: DR (kW)
B3: =CSSB!$L$3 -> 1 | C3: 1 | D3: =CSSB!$N$3 -> 224.63356 | E3: =CSSB!$M$3 -> 61.692639 | F3: =IF(E3<75,1,IF(AND(E3>=75, E3<95),2,IF(E3>=95,3))) -> 1 | G3: =IF($B$1="CZ03",VLOOKUP(CECCZ&$A$1&$G$2&$H$2&$C3,CZ03TempReset,7,0),IF($B$1="CZ04",VLOOKUP(CECCZ&$A$1&$G$2&$H$2&$C3,CZ04TempReset,7,0),IF(CECCZ="CZ12",VLOOKUP(CECCZ&$A$1&$G$2&$H$2&$C3,CZ12TempReset,7,0),IF(CECCZ="CZ13",VLOOKUP(CECCZ&$A$1&$G$2&$H$2&$C3,CZ13TempReset,7,0))))) -> 0.1920332 | H3: =IF($B$1="CZ03",VLOOKUP(CECCZ&$A$1&$G$2&$H$2&$C3,CZ03TempReset,8,0),IF($B$1="CZ04",VLOOKUP(CECCZ&$A$1&$G$2&$H$2&$C3,CZ04TempReset,8,0),IF(CECCZ="CZ12",VLOOKUP(CECCZ&$A$1&$G$2&$H$2&$C3,CZ12TempReset,8,0),IF(CECCZ="CZ13",VLOOKUP(CECCZ&$A$1&$G$2&$H$2&$C3,CZ13TempReset,8,0))))) -> -4.7190127 | I3: =(E3*G3+H3)/100 -> 0.07128022 | J3: =D3*I3 -> 16.01193
B4: =CSSB!$L$3 -> 1 | C4: 1 | D4: =CSSB!$N$3 -> 224.63356 | E4: =CSSB!$M$3 -> 61.692639 | F4: =IF(E4<75,1,IF(AND(E4>=75, E4<95),2,IF(E4>=95,3))) -> 1 | G4: =IF($B$1="CZ03",VLOOKUP(CECCZ&$A$1&$G$2&$H$2&$C4,CZ03TempReset,7,0),IF($B$1="CZ04",VLOOKUP(CECCZ&$A$1&$G$2&$H$2&$C4,CZ04TempReset,7,0),IF(CECCZ="CZ12",VLOOKUP(CECCZ&$A$1&$G$2&$H$2&$C4,CZ12TempReset,7,0),IF(CECCZ="CZ13",VLOOKUP(CECCZ&$A$1&$G$2&$H$2&$C4,CZ13TempReset,7,0))))) -> 0.1920332 | H4: =IF($B$1="CZ03",VLOOKUP(CECCZ&$A$1&$G$2&$H$2&$C4,CZ03TempReset,8,0),IF($B$1="CZ04",VLOOKUP(CECCZ&$A$1&$G$2&$H$2&$C4,CZ04TempReset,8,0),IF(CECCZ="CZ12",VLOOKUP(CECCZ&$A$1&$G$2&$H$2&$C4,CZ12TempReset,8,0),IF(CECCZ="CZ13",VLOOKUP(CECCZ&$A$1&$G$2&$H$2&$C4,CZ13TempReset,8,0))))) -> -4.7190127 | I4: =(E4*G4+H4)/100 -> 0.07128022 | J4: =D4*I4 -> 16.01193
B5: =CSSB!$L$3 -> 1 | C5: 1 | D5: =CSSB!$N$3 -> 224.63356 | E5: =CSSB!$M$3 -> 61.692639 | F5: =IF(E5<75,1,IF(AND(E5>=75, E5<95),2,IF(E5>=95,3))) -> 1 | G5: =IF($B$1="CZ03",VLOOKUP(CECCZ&$A$1&$G$2&$H$2&$C5,CZ03TempReset,7,0),IF($B$1="CZ04",VLOOKUP(CECCZ&$A$1&$G$2&$H$2&$C5,CZ04TempReset,7,0),IF(CECCZ="CZ12",VLOOKUP(CECCZ&$A$1&$G$2&$H$2&$C5,CZ12TempReset,7,0),IF(CECCZ="CZ13",VLOOKUP(CECCZ&$A$1&$G$2&$H$2&$C5,CZ13TempReset,7,0))))) -> 0.1920332 | H5: =IF($B$1="CZ03",VLOOKUP(CECCZ&$A$1&$G$2&$H$2&$C5,CZ03TempReset,8,0),IF($B$1="CZ04",VLOOKUP(CECCZ&$A$1&$G$2&$H$2&$C5,CZ04TempReset,8,0),IF(CECCZ="CZ12",VLOOKUP(CECCZ&$A$1&$G$2&$H$2&$C5,CZ12TempReset,8,0),IF(CECCZ="CZ13",VLOOKUP(CECCZ&$A$1&$G$2&$H$2&$C5,CZ13TempReset,8,0))))) -> -4.7190127 | I5: =(E5*G5+H5)/100 -> 0.07128022 | J5: =D5*I5 -> 16.01193
B6: =CSSB!$L$3 -> 1 | C6: 1 | D6: =CSSB!$N$3 -> 224.63356 | E6: =CSSB!$M$3 -> 61.692639 | F6: =IF(E6<75,1,IF(AND(E6>=75, E6<95),2,IF(E6>=95,3))) -> 1 | G6: =IF($B$1="CZ03",VLOOKUP(CECCZ&$A$1&$G$2&$H$2&$C6,CZ03TempReset,7,0),IF($B$1="CZ04",VLOOKUP(CECCZ&$A$1&$G$2&$H$2&$C6,CZ04TempReset,7,0),IF(CECCZ="CZ12",VLOOKUP(CECCZ&$A$1&$G$2&$H$2&$C6,CZ12TempReset,7,0),IF(CECCZ="CZ13",VLOOKUP(CECCZ&$A$1&$G$2&$H$2&$C6,CZ13TempReset,7,0))))) -> 0.1920332 | H6: =IF($B$1="CZ03",VLOOKUP(CECCZ&$A$1&$G$2&$H$2&$C6,CZ03TempReset,8,0),IF($B$1="CZ04",VLOOKUP(CECCZ&$A$1&$G$2&$H$2&$C6,CZ04TempReset,8,0),IF(CECCZ="CZ12",VLOOKUP(CECCZ&$A$1&$G$2&$H$2&$C6,CZ12TempReset,8,0),IF(CECCZ="CZ13",VLOOKUP(CECCZ&$A$1&$G$2&$H$2&$C6,CZ13TempReset,8,0))))) -> -4.7190127 | I6: =(E6*G6+H6)/100 -> 0.07128022 | J6: =D6*I6 -> 16.01193
B7: =CSSB!$L$3 -> 1 | C7: 2 | D7: =CSSB!$N$3 -> 224.63356 | E7: =CSSB!$M$3 -> 61.692639 | F7: =IF(E7<75,1,IF(AND(E7>=75, E7<95),2,IF(E7>=95,3))) -> 1 | G7: =IF($B$1="CZ03",VLOOKUP(CECCZ&$A$1&$G$2&$H$2&$C7,CZ03TempReset,7,0),IF($B$1="CZ04",VLOOKUP(CECCZ&$A$1&$G$2&$H$2&$C7,CZ04TempReset,7,0),IF(CECCZ="CZ12",VLOOKUP(CECCZ&$A$1&$G$2&$H$2&$C7,CZ12TempReset,7,0),IF(CECCZ="CZ13",VLOOKUP(CECCZ&$A$1&$G$2&$H$2&$C7,CZ13TempReset,7,0))))) -> 0.021673981 | H7: =IF($B$1="CZ03",VLOOKUP(CECCZ&$A$1&$G$2&$H$2&$C7,CZ03TempReset,8,0),IF($B$1="CZ04",VLOOKUP(CECCZ&$A$1&$G$2&$H$2&$C7,CZ04TempReset,8,0),IF(CECCZ="CZ12",VLOOKUP(CECCZ&$A$1&$G$2&$H$2&$C7,CZ12TempReset,8,0),IF(CECCZ="CZ13",VLOOKUP(CECCZ&$A$1&$G$2&$H$2&$C7,CZ13TempReset,8,0))))) -> 9.8639142 | I7: =(E7*G7+H7)/100 -> 0.11201039 | J7: =D7*I7 -> 25.161294
B8: =CSSB!$L$3 -> 1 | C8: 2 | D8: =CSSB!$N$3 -> 224.63356 | E8: =CSSB!$M$3 -> 61.692639 | F8: =IF(E8<75,1,IF(AND(E8>=75, E8<95),2,IF(E8>=95,3))) -> 1 | G8: =IF($B$1="CZ03",VLOOKUP(CECCZ&$A$1&$G$2&$H$2&$C8,CZ03TempReset,7,0),IF($B$1="CZ04",VLOOKUP(CECCZ&$A$1&$G$2&$H$2&$C8,CZ04TempReset,7,0),IF(CECCZ="CZ12",VLOOKUP(CECCZ&$A$1&$G$2&$H$2&$C8,CZ12TempReset,7,0),IF(CECCZ="CZ13",VLOOKUP(CECCZ&$A$1&$G$2&$H$2&$C8,CZ13TempReset,7,0))))) -> 0.021673981 | H8: =IF($B$1="CZ03",VLOOKUP(CECCZ&$A$1&$G$2&$H$2&$C8,CZ03TempReset,8,0),IF($B$1="CZ04",VLOOKUP(CECCZ&$A$1&$G$2&$H$2&$C8,CZ04TempReset,8,0),IF(CECCZ="CZ12",VLOOKUP(CECCZ&$A$1&$G$2&$H$2&$C8,CZ12TempReset,8,0),IF(CECCZ="CZ13",VLOOKUP(CECCZ&$A$1&$G$2&$H$2&$C8,CZ13TempReset,8,0))))) -> 9.8639142 | I8: =(E8*G8+H8)/100 -> 0.11201039 | J8: =D8*I8 -> 25.161294
B9: =CSSB!$L$3 -> 1 | C9: 2 | D9: =CSSB!$N$3 -> 224.63356 | E9: =CSSB!$M$3 -> 61.692639 | F9: =IF(E9<75,1,IF(AND(E9>=75, E9<95),2,IF(E9>=95,3))) -> 1 | G9: =IF($B$1="CZ03",VLOOKUP(CECCZ&$A$1&$G$2&$H$2&$C9,CZ03TempReset,7,0),IF($B$1="CZ04",VLOOKUP(CECCZ&$A$1&$G$2&$H$2&$C9,CZ04TempReset,7,0),IF(CECCZ="CZ12",VLOOKUP(CECCZ&$A$1&$G$2&$H$2&$C9,CZ12TempReset,7,0),IF(CECCZ="CZ13",VLOOKUP(CECCZ&$A$1&$G$2&$H$2&$C9,CZ13TempReset,7,0))))) -> 0.021673981 | H9: =IF($B$1="CZ03",VLOOKUP(CECCZ&$A$1&$G$2&$H$2&$C9,CZ03TempReset,8,0),IF($B$1="CZ04",VLOOKUP(CECCZ&$A$1&$G$2&$H$2&$C9,CZ04TempReset,8,0),IF(CECCZ="CZ12",VLOOKUP(CECCZ&$A$1&$G$2&$H$2&$C9,CZ12TempReset,8,0),IF(CECCZ="CZ13",VLOOKUP(CECCZ&$A$1&$G$2&$H$2&$C9,CZ13TempReset,8,0))))) -> 9.8639142 | I9: =(E9*G9+H9)/100 -> 0.11201039 | J9: =D9*I9 -> 25.161294
B10: =CSSB!$L$3 -> 1 | C10: 2 | D10: =CSSB!$N$3 -> 224.63356 | E10: =CSSB!$M$3 -> 61.692639 | F10: =IF(E10<75,1,IF(AND(E10>=75, E10<95),2,IF(E10>=95,3))) -> 1 | G10: =IF($B$1="CZ03",VLOOKUP(CECCZ&$A$1&$G$2&$H$2&$C10,CZ03TempReset,7,0),IF($B$1="CZ04",VLOOKUP(CECCZ&$A$1&$G$2&$H$2&$C10,CZ04TempReset,7,0),IF(CECCZ="CZ12",VLOOKUP(CECCZ&$A$1&$G$2&$H$2&$C10,CZ12TempReset,7,0),IF(CECCZ="CZ13",VLOOKUP(CECCZ&$A$1&$G$2&$H$2&$C10,CZ13TempReset,7,0))))) -> 0.021673981 | H10: =IF($B$1="CZ03",VLOOKUP(CECCZ&$A$1&$G$2&$H$2&$C10,CZ03TempReset,8,0),IF($B$1="CZ04",VLOOKUP(CECCZ&$A$1&$G$2&$H$2&$C10,CZ04TempReset,8,0),IF(CECCZ="CZ12",VLOOKUP(CECCZ&$A$1&$G$2&$H$2&$C10,CZ12TempReset,8,0),IF(CECCZ="CZ13",VLOOKUP(CECCZ&$A$1&$G$2&$H$2&$C10,CZ13TempReset,8,0))))) -> 9.8639142 | I10: =(E10*G10+H10)/100 -> 0.11201039 | J10: =D10*I10 -> 25.161294
B11: =CSSB!$L$3 -> 1 | C11: 3 | D11: =CSSB!$N$3 -> 224.63356 | E11: =CSSB!$M$3 -> 61.692639 | F11: =IF(E11<75,1,IF(AND(E11>=75, E11<95),2,IF(E11>=95,3))) -> 1 | G11: =IF($B$1="CZ03",VLOOKUP(CECCZ&$A$1&$G$2&$H$2&$C11,CZ03TempReset,7,0),IF($B$1="CZ04",VLOOKUP(CECCZ&$A$1&$G$2&$H$2&$C11,CZ04TempReset,7,0),IF(CECCZ="CZ12",VLOOKUP(CECCZ&$A$1&$G$2&$H$2&$C11,CZ12TempReset,7,0),IF(CECCZ="CZ13",VLOOKUP(CECCZ&$A$1&$G$2&$H$2&$C11,CZ13TempReset,7,0))))) -> -0.011327212 | H11: =IF($B$1="CZ03",VLOOKUP(CECCZ&$A$1&$G$2&$H$2&$C11,CZ03TempReset,8,0),IF($B$1="CZ04",VLOOKUP(CECCZ&$A$1&$G$2&$H$2&$C11,CZ04TempReset,8,0),IF(CECCZ="CZ12",VLOOKUP(CECCZ&$A$1&$G$2&$H$2&$C11,CZ12TempReset,8,0),IF(CECCZ="CZ13",VLOOKUP(CECCZ&$A$1&$G$2&$H$2&$C11,CZ13TempReset,8,0))))) -> 12.447046 | I11: =(E11*G11+H11)/100 -> 0.1174824 | J11: =D11*I11 -> 26.39049
B12: =CSSB!$L$3 -> 1 | C12: 3 | D12: =CSSB!$N$3 -> 224.63356 | E12: =CSSB!$M$3 -> 61.692639 | F12: =IF(E12<75,1,IF(AND(E12>=75, E12<95),2,IF(E12>=95,3))) -> 1 | G12: =IF($B$1="CZ03",VLOOKUP(CECCZ&$A$1&$G$2&$H$2&$C12,CZ03TempReset,7,0),IF($B$1="CZ04",VLOOKUP(CECCZ&$A$1&$G$2&$H$2&$C12,CZ04TempReset,7,0),IF(CECCZ="CZ12",VLOOKUP(CECCZ&$A$1&$G$2&$H$2&$C12,CZ12TempReset,7,0),IF(CECCZ="CZ13",VLOOKUP(CECCZ&$A$1&$G$2&$H$2&$C12,CZ13TempReset,7,0))))) -> -0.011327212 | H12: =IF($B$1="CZ03",VLOOKUP(CECCZ&$A$1&$G$2&$H$2&$C12,CZ03TempReset,8,0),IF($B$1="CZ04",VLOOKUP(CECCZ&$A$1&$G$2&$H$2&$C12,CZ04TempReset,8,0),IF(CECCZ="CZ12",VLOOKUP(CECCZ&$A$1&$G$2&$H$2&$C12,CZ12TempReset,8,0),IF(CECCZ="CZ13",VLOOKUP(CECCZ&$A$1&$G$2&$H$2&$C12,CZ13TempReset,8,0))))) -> 12.447046 | I12: =(E12*G12+H12)/100 -> 0.1174824 | J12: =D12*I12 -> 26.39049
B13: =CSSB!$L$3 -> 1 | C13: 3 | D13: =CSSB!$N$3 -> 224.63356 | E13: =CSSB!$M$3 -> 61.692639 | F13: =IF(E13<75,1,IF(AND(E13>=75, E13<95),2,IF(E13>=95,3))) -> 1 | G13: =IF($B$1="CZ03",VLOOKUP(CECCZ&$A$1&$G$2&$H$2&$C13,CZ03TempReset,7,0),IF($B$1="CZ04",VLOOKUP(CECCZ&$A$1&$G$2&$H$2&$C13,CZ04TempReset,7,0),IF(CECCZ="CZ12",VLOOKUP(CECCZ&$A$1&$G$2&$H$2&$C13,CZ12TempReset,7,0),IF(CECCZ="CZ13",VLOOKUP(CECCZ&$A$1&$G$2&$H$2&$C13,CZ13TempReset,7,0))))) -> -0.011327212 | H13: =IF($B$1="CZ03",VLOOKUP(CECCZ&$A$1&$G$2&$H$2&$C13,CZ03TempReset,8,0),IF($B$1="CZ04",VLOOKUP(CECCZ&$A$1&$G$2&$H$2&$C13,CZ04TempReset,8,0),IF(CECCZ="CZ12",VLOOKUP(CECCZ&$A$1&$G$2&$H$2&$C13,CZ12TempReset,8,0),IF(CECCZ="CZ13",VLOOKUP(CECCZ&$A$1&$G$2&$H$2&$C13,CZ13TempReset,8,0))))) -> 12.447046 | I13: =(E13*G13+H13)/100 -> 0.1174824 | J13: =D13*I13 -> 26.39049
B14: =CSSB!$L$3 -> 1 | C14: 3 | D14: =CSSB!$N$3 -> 224.63356 | E14: =CSSB!$M$3 -> 61.692639 | F14: =IF(E14<75,1,IF(AND(E14>=75, E14<95),2,IF(E14>=95,3))) -> 1 | G14: =IF($B$1="CZ03",VLOOKUP(CECCZ&$A$1&$G$2&$H$2&$C14,CZ03TempReset,7,0),IF($B$1="CZ04",VLOOKUP(CECCZ&$A$1&$G$2&$H$2&$C14,CZ04TempReset,7,0),IF(CECCZ="CZ12",VLOOKUP(CECCZ&$A$1&$G$2&$H$2&$C14,CZ12TempReset,7,0),IF(CECCZ="CZ13",VLOOKUP(CECCZ&$A$1&$G$2&$H$2&$C14,CZ13TempReset,7,0))))) -> -0.011327212 | H14: =IF($B$1="CZ03",VLOOKUP(CECCZ&$A$1&$G$2&$H$2&$C14,CZ03TempReset,8,0),IF($B$1="CZ04",VLOOKUP(CECCZ&$A$1&$G$2&$H$2&$C14,CZ04TempReset,8,0),IF(CECCZ="CZ12",VLOOKUP(CECCZ&$A$1&$G$2&$H$2&$C14,CZ12TempReset,8,0),IF(CECCZ="CZ13",VLOOKUP(CECCZ&$A$1&$G$2&$H$2&$C14,CZ13TempReset,8,0))))) -> 12.447046 | I14: =(E14*G14+H14)/100 -> 0.1174824 | J14: =D14*I14 -> 26.39049
... B18: =CSSB!$L$3 -> 1 | C18: 4 | D18: =CSSB!$N$3 -> 224.63356 | E18: =CSSB!$M$3 -> 61.692639 | F18: =IF(E18<75,1,IF(AND(E18>=75, E18<95),2,IF(E18>=95,3))) -> 1 | G18: =IF($B$1="CZ03",VLOOKUP(CECCZ&$A$1&$G$2&$H$2&$C18,CZ03TempReset,7,0),IF($B$1="CZ04",VLOOKUP(CECCZ&$A$1&$G$2&$H$2&$C18,CZ04TempReset,7,0),IF(CECCZ="CZ12",VLOOKUP(CECCZ&$A$1&$G$2&$H$2&$C18,CZ12TempReset,7,0),IF(CECCZ="CZ13",VLOOKUP(CECCZ&$A$1&$G$2&$H$2&$C18,CZ13TempReset,7,0))))) -> -0.040987151 | H18: =IF($B$1="CZ03",VLOOKUP(CECCZ&$A$1&$G$2&$H$2&$C18,CZ03TempReset,8,0),IF($B$1="CZ04",VLOOKUP(CECCZ&$A$1&$G$2&$H$2&$C18,CZ04TempReset,8,0),IF(CECCZ="CZ12",VLOOKUP(CECCZ&$A$1&$G$2&$H$2&$C18,CZ12TempReset,8,0),IF(CECCZ="CZ13",VLOOKUP(CECCZ&$A$1&$G$2&$H$2&$C18,CZ13TempReset,8,0))))) -> 12.485388 | I18: =(E18*G18+H18)/100 -> 0.099567823 | J18: =D18*I18 -> 22.366275
B20: TempRange | C20: hour | D20: power | E20: oat | F20: range | G20: =PrecoolDegrees -> 0 | H20: =TempResetDegrees -> 4 | I20: DR% | J20: DR (kW)
B21: =CSSB!$L$4 -> 2 | C21: 1 | D21: =CSSB!$N$4 -> 227.47394 | E21: =CSSB!$M$4 -> 67.609237 | F21: =IF(E21<75,1,IF(AND(E21>=75, E21<95),2,IF(E21>=95,3))) -> 1 | G21: =IF($B$1="CZ03",VLOOKUP(CECCZ&$A$1&$G$2&$H$2&$C21,CZ03TempReset,7,0),IF($B$1="CZ04",VLOOKUP(CECCZ&$A$1&$G$2&$H$2&$C21,CZ04TempReset,7,0),IF(CECCZ="CZ12",VLOOKUP(CECCZ&$A$1&$G$2&$H$2&$C21,CZ12TempReset,7,0),IF(CECCZ="CZ13",VLOOKUP(CECCZ&$A$1&$G$2&$H$2&$C21,CZ13TempReset,7,0))))) -> 0.1920332 | H21: =IF($B$1="CZ03",VLOOKUP(CECCZ&$A$1&$G$2&$H$2&$C21,CZ03TempReset,8,0),IF($B$1="CZ04",VLOOKUP(CECCZ&$A$1&$G$2&$H$2&$C21,CZ04TempReset,8,0),IF(CECCZ="CZ12",VLOOKUP(CECCZ&$A$1&$G$2&$H$2&$C21,CZ12TempReset,8,0),IF(CECCZ="CZ13",VLOOKUP(CECCZ&$A$1&$G$2&$H$2&$C21,CZ13TempReset,8,0))))) -> -4.7190127 | I21: =(E21*G21+H21)/100 -> 0.082642053 | J21: =D21*I21 -> 18.798913
B22: =CSSB!$L$4 -> 2 | C22: 1 | D22: =CSSB!$N$4 -> 227.47394 | E22: =CSSB!$M$4 -> 67.609237 | F22: =IF(E22<75,1,IF(AND(E22>=75, E22<95),2,IF(E22>=95,3))) -> 1 | G22: =IF($B$1="CZ03",VLOOKUP(CECCZ&$A$1&$G$2&$H$2&$C22,CZ03TempReset,7,0),IF($B$1="CZ04",VLOOKUP(CECCZ&$A$1&$G$2&$H$2&$C22,CZ04TempReset,7,0),IF(CECCZ="CZ12",VLOOKUP(CECCZ&$A$1&$G$2&$H$2&$C22,CZ12TempReset,7,0),IF(CECCZ="CZ13",VLOOKUP(CECCZ&$A$1&$G$2&$H$2&$C22,CZ13TempReset,7,0))))) -> 0.1920332 | H22: =IF($B$1="CZ03",VLOOKUP(CECCZ&$A$1&$G$2&$H$2&$C22,CZ03TempReset,8,0),IF($B$1="CZ04",VLOOKUP(CECCZ&$A$1&$G$2&$H$2&$C22,CZ04TempReset,8,0),IF(CECCZ="CZ12",VLOOKUP(CECCZ&$A$1&$G$2&$H$2&$C22,CZ12TempReset,8,0),IF(CECCZ="CZ13",VLOOKUP(CECCZ&$A$1&$G$2&$H$2&$C22,CZ13TempReset,8,0))))) -> -4.7190127 | I22: =(E22*G22+H22)/100 -> 0.082642053 | J22: =D22*I22 -> 18.798913
B23: =CSSB!$L$4 -> 2 | C23: 1 | D23: =CSSB!$N$4 -> 227.47394 | E23: =CSSB!$M$4 -> 67.609237 | F23: =IF(E23<75,1,IF(AND(E23>=75, E23<95),2,IF(E23>=95,3))) -> 1 | G23: =IF($B$1="CZ03",VLOOKUP(CECCZ&$A$1&$G$2&$H$2&$C23,CZ03TempReset,7,0),IF($B$1="CZ04",VLOOKUP(CECCZ&$A$1&$G$2&$H$2&$C23,CZ04TempReset,7,0),IF(CECCZ="CZ12",VLOOKUP(CECCZ&$A$1&$G$2&$H$2&$C23,CZ12TempReset,7,0),IF(CECCZ="CZ13",VLOOKUP(CECCZ&$A$1&$G$2&$H$2&$C23,CZ13TempReset,7,0))))) -> 0.1920332 | H23: =IF($B$1="CZ03",VLOOKUP(CECCZ&$A$1&$G$2&$H$2&$C23,CZ03TempReset,8,0),IF($B$1="CZ04",VLOOKUP(CECCZ&$A$1&$G$2&$H$2&$C23,CZ04TempReset,8,0),IF(CECCZ="CZ12",VLOOKUP(CECCZ&$A$1&$G$2&$H$2&$C23,CZ12TempReset,8,0),IF(CECCZ="CZ13",VLOOKUP(CECCZ&$A$1&$G$2&$H$2&$C23,CZ13TempReset,8,0))))) -> -4.7190127 | I23: =(E23*G23+H23)/100 -> 0.082642053 | J23: =D23*I23 -> 18.798913
B24: =CSSB!$L$4 -> 2 | C24: 1 | D24: =CSSB!$N$4 -> 227.47394 | E24: =CSSB!$M$4 -> 67.609237 | F24: =IF(E24<75,1,IF(AND(E24>=75, E24<95),2,IF(E24>=95,3))) -> 1 | G24: =IF($B$1="CZ03",VLOOKUP(CECCZ&$A$1&$G$2&$H$2&$C24,CZ03TempReset,7,0),IF($B$1="CZ04",VLOOKUP(CECCZ&$A$1&$G$2&$H$2&$C24,CZ04TempReset,7,0),IF(CECCZ="CZ12",VLOOKUP(CECCZ&$A$1&$G$2&$H$2&$C24,CZ12TempReset,7,0),IF(CECCZ="CZ13",VLOOKUP(CECCZ&$A$1&$G$2&$H$2&$C24,CZ13TempReset,7,0))))) -> 0.1920332 | H24: =IF($B$1="CZ03",VLOOKUP(CECCZ&$A$1&$G$2&$H$2&$C24,CZ03TempReset,8,0),IF($B$1="CZ04",VLOOKUP(CECCZ&$A$1&$G$2&$H$2&$C24,CZ04TempReset,8,0),IF(CECCZ="CZ12",VLOOKUP(CECCZ&$A$1&$G$2&$H$2&$C24,CZ12TempReset,8,0),IF(CECCZ="CZ13",VLOOKUP(CECCZ&$A$1&$G$2&$H$2&$C24,CZ13TempReset,8,0))))) -> -4.7190127 | I24: =(E24*G24+H24)/100 -> 0.082642053 | J24: =D24*I24 -> 18.798913
B25: =CSSB!$L$4 -> 2 | C25: 2 | D25: =CSSB!$N$4 -> 227.47394 | E25: =CSSB!$M$4 -> 67.609237 | F25: =IF(E25<75,1,IF(AND(E25>=75, E25<95),2,IF(E25>=95,3))) -> 1 | G25: =IF($B$1="CZ03",VLOOKUP(CECCZ&$A$1&$G$2&$H$2&$C25,CZ03TempReset,7,0),IF($B$1="CZ04",VLOOKUP(CECCZ&$A$1&$G$2&$H$2&$C25,CZ04TempReset,7,0),IF(CECCZ="CZ12",VLOOKUP(CECCZ&$A$1&$G$2&$H$2&$C25,CZ12TempReset,7,0),IF(CECCZ="CZ13",VLOOKUP(CECCZ&$A$1&$G$2&$H$2&$C25,CZ13TempReset,7,0))))) -> 0.021673981 | H25: =IF($B$1="CZ03",VLOOKUP(CECCZ&$A$1&$G$2&$H$2&$C25,CZ03TempReset,8,0),IF($B$1="CZ04",VLOOKUP(CECCZ&$A$1&$G$2&$H$2&$C25,CZ04TempReset,8,0),IF(CECCZ="CZ12",VLOOKUP(CECCZ&$A$1&$G$2&$H$2&$C25,CZ12TempReset,8,0),IF(CECCZ="CZ13",VLOOKUP(CECCZ&$A$1&$G$2&$H$2&$C25,CZ13TempReset,8,0))))) -> 9.8639142 | I25: =(E25*G25+H25)/100 -> 0.11329276 | J25: =D25*I25 -> 25.771149
B26: =CSSB!$L$4 -> 2 | C26: 2 | D26: =CSSB!$N$4 -> 227.47394 | E26: =CSSB!$M$4 -> 67.609237 | F26: =IF(E26<75,1,IF(AND(E26>=75, E26<95),2,IF(E26>=95,3))) -> 1 | G26: =IF($B$1="CZ03",VLOOKUP(CECCZ&$A$1&$G$2&$H$2&$C26,CZ03TempReset,7,0),IF($B$1="CZ04",VLOOKUP(CECCZ&$A$1&$G$2&$H$2&$C26,CZ04TempReset,7,0),IF(CECCZ="CZ12",VLOOKUP(CECCZ&$A$1&$G$2&$H$2&$C26,CZ12TempReset,7,0),IF(CECCZ="CZ13",VLOOKUP(CECCZ&$A$1&$G$2&$H$2&$C26,CZ13TempReset,7,0))))) -> 0.021673981 | H26: =IF($B$1="CZ03",VLOOKUP(CECCZ&$A$1&$G$2&$H$2&$C26,CZ03TempReset,8,0),IF($B$1="CZ04",VLOOKUP(CECCZ&$A$1&$G$2&$H$2&$C26,CZ04TempReset,8,0),IF(CECCZ="CZ12",VLOOKUP(CECCZ&$A$1&$G$2&$H$2&$C26,CZ12TempReset,8,0),IF(CECCZ="CZ13",VLOOKUP(CECCZ&$A$1&$G$2&$H$2&$C26,CZ13TempReset,8,0))))) -> 9.8639142 | I26: =(E26*G26+H26)/100 -> 0.11329276 | J26: =D26*I26 -> 25.771149
B27: =CSSB!$L$4 -> 2 | C27: 2 | D27: =CSSB!$N$4 -> 227.47394 | E27: =CSSB!$M$4 -> 67.609237 | F27: =IF(E27<75,1,IF(AND(E27>=75, E27<95),2,IF(E27>=95,3))) -> 1 | G27: =IF($B$1="CZ03",VLOOKUP(CECCZ&$A$1&$G$2&$H$2&$C27,CZ03TempReset,7,0),IF($B$1="CZ04",VLOOKUP(CECCZ&$A$1&$G$2&$H$2&$C27,CZ04TempReset,7,0),IF(CECCZ="CZ12",VLOOKUP(CECCZ&$A$1&$G$2&$H$2&$C27,CZ12TempReset,7,0),IF(CECCZ="CZ13",VLOOKUP(CECCZ&$A$1&$G$2&$H$2&$C27,CZ13TempReset,7,0))))) -> 0.021673981 | H27: =IF($B$1="CZ03",VLOOKUP(CECCZ&$A$1&$G$2&$H$2&$C27,CZ03TempReset,8,0),IF($B$1="CZ04",VLOOKUP(CECCZ&$A$1&$G$2&$H$2&$C27,CZ04TempReset,8,0),IF(CECCZ="CZ12",VLOOKUP(CECCZ&$A$1&$G$2&$H$2&$C27,CZ12TempReset,8,0),IF(CECCZ="CZ13",VLOOKUP(CECCZ&$A$1&$G$2&$H$2&$C27,CZ13TempReset,8,0))))) -> 9.8639142 | I27: =(E27*G27+H27)/100 -> 0.11329276 | J27: =D27*I27 -> 25.771149
B28: =CSSB!$L$4 -> 2 | C28: 2 | D28: =CSSB!$N$4 -> 227.47394 | E28: =CSSB!$M$4 -> 67.609237 | F28: =IF(E28<75,1,IF(AND(E28>=75, E28<95),2,IF(E28>=95,3))) -> 1 | G28: =IF($B$1="CZ03",VLOOKUP(CECCZ&$A$1&$G$2&$H$2&$C28,CZ03TempReset,7,0),IF($B$1="CZ04",VLOOKUP(CECCZ&$A$1&$G$2&$H$2&$C28,CZ04TempReset,7,0),IF(CECCZ="CZ12",VLOOKUP(CECCZ&$A$1&$G$2&$H$2&$C28,CZ12TempReset,7,0),IF(CECCZ="CZ13",VLOOKUP(CECCZ&$A$1&$G$2&$H$2&$C28,CZ13TempReset,7,0))))) -> 0.021673981 | H28: =IF($B$1="CZ03",VLOOKUP(CECCZ&$A$1&$G$2&$H$2&$C28,CZ03TempReset,8,0),IF($B$1="CZ04",VLOOKUP(CECCZ&$A$1&$G$2&$H$2&$C28,CZ04TempReset,8,0),IF(CECCZ="CZ12",VLOOKUP(CECCZ&$A$1&$G$2&$H$2&$C28,CZ12TempReset,8,0),IF(CECCZ="CZ13",VLOOKUP(CECCZ&$A$1&$G$2&$H$2&$C28,CZ13TempReset,8,0))))) -> 9.8639142 | I28: =(E28*G28+H28)/100 -> 0.11329276 | J28: =D28*I28 -> 25.771149
B29: =CSSB!$L$4 -> 2 | C29: 3 | D29: =CSSB!$N$4 -> 227.47394 | E29: =CSSB!$M$4 -> 67.609237 | F29: =IF(E29<75,1,IF(AND(E29>=75, E29<95),2,IF(E29>=95,3))) -> 1 | G29: =IF($B$1="CZ03",VLOOKUP(CECCZ&$A$1&$G$2&$H$2&$C29,CZ03TempReset,7,0),IF($B$1="CZ04",VLOOKUP(CECCZ&$A$1&$G$2&$H$2&$C29,CZ04TempReset,7,0),IF(CECCZ="CZ12",VLOOKUP(CECCZ&$A$1&$G$2&$H$2&$C29,CZ12TempReset,7,0),IF(CECCZ="CZ13",VLOOKUP(CECCZ&$A$1&$G$2&$H$2&$C29,CZ13TempReset,7,0))))) -> -0.011327212 | H29: =IF($B$1="CZ03",VLOOKUP(CECCZ&$A$1&$G$2&$H$2&$C29,CZ03TempReset,8,0),IF($B$1="CZ04",VLOOKUP(CECCZ&$A$1&$G$2&$H$2&$C29,CZ04TempReset,8,0),IF(CECCZ="CZ12",VLOOKUP(CECCZ&$A$1&$G$2&$H$2&$C29,CZ12TempReset,8,0),IF(CECCZ="CZ13",VLOOKUP(CECCZ&$A$1&$G$2&$H$2&$C29,CZ13TempReset,8,0))))) -> 12.447046 | I29: =(E29*G29+H29)/100 -> 0.11681222 | J29: =D29*I29 -> 26.571735
B30: =CSSB!$L$4 -> 2 | C30: 3 | D30: =CSSB!$N$4 -> 227.47394 | E30: =CSSB!$M$4 -> 67.609237 | F30: =IF(E30<75,1,IF(AND(E30>=75, E30<95),2,IF(E30>=95,3))) -> 1 | G30: =IF($B$1="CZ03",VLOOKUP(CECCZ&$A$1&$G$2&$H$2&$C30,CZ03TempReset,7,0),IF($B$1="CZ04",VLOOKUP(CECCZ&$A$1&$G$2&$H$2&$C30,CZ04TempReset,7,0),IF(CECCZ="CZ12",VLOOKUP(CECCZ&$A$1&$G$2&$H$2&$C30,CZ12TempReset,7,0),IF(CECCZ="CZ13",VLOOKUP(CECCZ&$A$1&$G$2&$H$2&$C30,CZ13TempReset,7,0))))) -> -0.011327212 | H30: =IF($B$1="CZ03",VLOOKUP(CECCZ&$A$1&$G$2&$H$2&$C30,CZ03TempReset,8,0),IF($B$1="CZ04",VLOOKUP(CECCZ&$A$1&$G$2&$H$2&$C30,CZ04TempReset,8,0),IF(CECCZ="CZ12",VLOOKUP(CECCZ&$A$1&$G$2&$H$2&$C30,CZ12TempReset,8,0),IF(CECCZ="CZ13",VLOOKUP(CECCZ&$A$1&$G$2&$H$2&$C30,CZ13TempReset,8,0))))) -> 12.447046 | I30: =(E30*G30+H30)/100 -> 0.11681222 | J30: =D30*I30 -> 26.571735
B31: =CSSB!$L$4 -> 2 | C31: 3 | D31: =CSSB!$N$4 -> 227.47394 | E31: =CSSB!$M$4 -> 67.609237 | F31: =IF(E31<75,1,IF(AND(E31>=75, E31<95),2,IF(E31>=95,3))) -> 1 | G31: =IF($B$1="CZ03",VLOOKUP(CECCZ&$A$1&$G$2&$H$2&$C31,CZ03TempReset,7,0),IF($B$1="CZ04",VLOOKUP(CECCZ&$A$1&$G$2&$H$2&$C31,CZ04TempReset,7,0),IF(CECCZ="CZ12",VLOOKUP(CECCZ&$A$1&$G$2&$H$2&$C31,CZ12TempReset,7,0),IF(CECCZ="CZ13",VLOOKUP(CECCZ&$A$1&$G$2&$H$2&$C31,CZ13TempReset,7,0))))) -> -0.011327212 | H31: =IF($B$1="CZ03",VLOOKUP(CECCZ&$A$1&$G$2&$H$2&$C31,CZ03TempReset,8,0),IF($B$1="CZ04",VLOOKUP(CECCZ&$A$1&$G$2&$H$2&$C31,CZ04TempReset,8,0),IF(CECCZ="CZ12",VLOOKUP(CECCZ&$A$1&$G$2&$H$2&$C31,CZ12TempReset,8,0),IF(CECCZ="CZ13",VLOOKUP(CECCZ&$A$1&$G$2&$H$2&$C31,CZ13TempReset,8,0))))) -> 12.447046 | I31: =(E31*G31+H31)/100 -> 0.11681222 | J31: =D31*I31 -> 26.571735
B32: =CSSB!$L$4 -> 2 | C32: 3 | D32: =CSSB!$N$4 -> 227.47394 | E32: =CSSB!$M$4 -> 67.609237 | F32: =IF(E32<75,1,IF(AND(E32>=75, E32<95),2,IF(E32>=95,3))) -> 1 | G32: =IF($B$1="CZ03",VLOOKUP(CECCZ&$A$1&$G$2&$H$2&$C32,CZ03TempReset,7,0),IF($B$1="CZ04",VLOOKUP(CECCZ&$A$1&$G$2&$H$2&$C32,CZ04TempReset,7,0),IF(CECCZ="CZ12",VLOOKUP(CECCZ&$A$1&$G$2&$H$2&$C32,CZ12TempReset,7,0),IF(CECCZ="CZ13",VLOOKUP(CECCZ&$A$1&$G$2&$H$2&$C32,CZ13TempReset,7,0))))) -> -0.011327212 | H32: =IF($B$1="CZ03",VLOOKUP(CECCZ&$A$1&$G$2&$H$2&$C32,CZ03TempReset,8,0),IF($B$1="CZ04",VLOOKUP(CECCZ&$A$1&$G$2&$H$2&$C32,CZ04TempReset,8,0),IF(CECCZ="CZ12",VLOOKUP(CECCZ&$A$1&$G$2&$H$2&$C32,CZ12TempReset,8,0),IF(CECCZ="CZ13",VLOOKUP(CECCZ&$A$1&$G$2&$H$2&$C32,CZ13TempReset,8,0))))) -> 12.447046 | I32: =(E32*G32+H32)/100 -> 0.11681222 | J32: =D32*I32 -> 26.571735
... B36: =CSSB!$L$4 -> 2 | C36: 4 | D36: =CSSB!$N$4 -> 227.47394 | E36: =CSSB!$M$4 -> 67.609237 | F36: =IF(E36<75,1,IF(AND(E36>=75, E36<95),2,IF(E36>=95,3))) -> 1 | G36: =IF($B$1="CZ03",VLOOKUP(CECCZ&$A$1&$G$2&$H$2&$C36,CZ03TempReset,7,0),IF($B$1="CZ04",VLOOKUP(CECCZ&$A$1&$G$2&$H$2&$C36,CZ04TempReset,7,0),IF(CECCZ="CZ12",VLOOKUP(CECCZ&$A$1&$G$2&$H$2&$C36,CZ12TempReset,7,0),IF(CECCZ="CZ13",VLOOKUP(CECCZ&$A$1&$G$2&$H$2&$C36,CZ13TempReset,7,0))))) -> -0.040987151 | H36: =IF($B$1="CZ03",VLOOKUP(CECCZ&$A$1&$G$2&$H$2&$C36,CZ03TempReset,8,0),IF($B$1="CZ04",VLOOKUP(CECCZ&$A$1&$G$2&$H$2&$C36,CZ04TempReset,8,0),IF(CECCZ="CZ12",VLOOKUP(CECCZ&$A$1&$G$2&$H$2&$C36,CZ12TempReset,8,0),IF(CECCZ="CZ13",VLOOKUP(CECCZ&$A$1&$G$2&$H$2&$C36,CZ13TempReset,8,0))))) -> 12.485388 | I36: =(E36*G36+H36)/100 -> 0.097142778 | J36: =D36*I36 -> 22.09745
B38: TempRange | C38: hour | D38: power | E38: oat | F38: range | G38: =PrecoolDegrees -> 0 | H38: =TempResetDegrees -> 4 | I38: DR% | J38: DR (kW)
B39: =CSSB!$L$5 -> 3 | C39: 1 | D39: =CSSB!$N$5 -> 234.90573 | E39: =CSSB!$M$5 -> 72.139614 | F39: =IF(E39<75,1,IF(AND(E39>=75, E39<95),2,IF(E39>=95,3))) -> 1 | G39: =IF($B$1="CZ03",VLOOKUP(CECCZ&$A$1&$G$2&$H$2&$C39,CZ03TempReset,7,0),IF($B$1="CZ04",VLOOKUP(CECCZ&$A$1&$G$2&$H$2&$C39,CZ04TempReset,7,0),IF(CECCZ="CZ12",VLOOKUP(CECCZ&$A$1&$G$2&$H$2&$C39,CZ12TempReset,7,0),IF(CECCZ="CZ13",VLOOKUP(CECCZ&$A$1&$G$2&$H$2&$C39,CZ13TempReset,7,0))))) -> 0.1920332 | H39: =IF($B$1="CZ03",VLOOKUP(CECCZ&$A$1&$G$2&$H$2&$C39,CZ03TempReset,8,0),IF($B$1="CZ04",VLOOKUP(CECCZ&$A$1&$G$2&$H$2&$C39,CZ04TempReset,8,0),IF(CECCZ="CZ12",VLOOKUP(CECCZ&$A$1&$G$2&$H$2&$C39,CZ12TempReset,8,0),IF(CECCZ="CZ13",VLOOKUP(CECCZ&$A$1&$G$2&$H$2&$C39,CZ13TempReset,8,0))))) -> -4.7190127 | I39: =(E39*G39+H39)/100 -> 0.091341882 | J39: =D39*I39 -> 21.456732
B40: =CSSB!$L$5 -> 3 | C40: 1 | D40: =CSSB!$N$5 -> 234.90573 | E40: =CSSB!$M$5 -> 72.139614 | F40: =IF(E40<75,1,IF(AND(E40>=75, E40<95),2,IF(E40>=95,3))) -> 1 | G40: =IF($B$1="CZ03",VLOOKUP(CECCZ&$A$1&$G$2&$H$2&$C40,CZ03TempReset,7,0),IF($B$1="CZ04",VLOOKUP(CECCZ&$A$1&$G$2&$H$2&$C40,CZ04TempReset,7,0),IF(CECCZ="CZ12",VLOOKUP(CECCZ&$A$1&$G$2&$H$2&$C40,CZ12TempReset,7,0),IF(CECCZ="CZ13",VLOOKUP(CECCZ&$A$1&$G$2&$H$2&$C40,CZ13TempReset,7,0))))) -> 0.1920332 | H40: =IF($B$1="CZ03",VLOOKUP(CECCZ&$A$1&$G$2&$H$2&$C40,CZ03TempReset,8,0),IF($B$1="CZ04",VLOOKUP(CECCZ&$A$1&$G$2&$H$2&$C40,CZ04TempReset,8,0),IF(CECCZ="CZ12",VLOOKUP(CECCZ&$A$1&$G$2&$H$2&$C40,CZ12TempReset,8,0),IF(CECCZ="CZ13",VLOOKUP(CECCZ&$A$1&$G$2&$H$2&$C40,CZ13TempReset,8,0))))) -> -4.7190127 | I40: =(E40*G40+H40)/100 -> 0.091341882 | J40: =D40*I40 -> 21.456732
B41: =CSSB!$L$5 -> 3 | C41: 1 | D41: =CSSB!$N$5 -> 234.90573 | E41: =CSSB!$M$5 -> 72.139614 | F41: =IF(E41<75,1,IF(AND(E41>=75, E41<95),2,IF(E41>=95,3))) -> 1 | G41: =IF($B$1="CZ03",VLOOKUP(CECCZ&$A$1&$G$2&$H$2&$C41,CZ03TempReset,7,0),IF($B$1="CZ04",VLOOKUP(CECCZ&$A$1&$G$2&$H$2&$C41,CZ04TempReset,7,0),IF(CECCZ="CZ12",VLOOKUP(CECCZ&$A$1&$G$2&$H$2&$C41,CZ12TempReset,7,0),IF(CECCZ="CZ13",VLOOKUP(CECCZ&$A$1&$G$2&$H$2&$C41,CZ13TempReset,7,0))))) -> 0.1920332 | H41: =IF($B$1="CZ03",VLOOKUP(CECCZ&$A$1&$G$2&$H$2&$C41,CZ03TempReset,8,0),IF($B$1="CZ04",VLOOKUP(CECCZ&$A$1&$G$2&$H$2&$C41,CZ04TempReset,8,0),IF(CECCZ="CZ12",VLOOKUP(CECCZ&$A$1&$G$2&$H$2&$C41,CZ12TempReset,8,0),IF(CECCZ="CZ13",VLOOKUP(CECCZ&$A$1&$G$2&$H$2&$C41,CZ13TempReset,8,0))))) -> -4.7190127 | I41: =(E41*G41+H41)/100 -> 0.091341882 | J41: =D41*I41 -> 21.456732
B42: =CSSB!$L$5 -> 3 | C42: 1 | D42: =CSSB!$N$5 -> 234.90573 | E42: =CSSB!$M$5 -> 72.139614 | F42: =IF(E42<75,1,IF(AND(E42>=75, E42<95),2,IF(E42>=95,3))) -> 1 | G42: =IF($B$1="CZ03",VLOOKUP(CECCZ&$A$1&$G$2&$H$2&$C42,CZ03TempReset,7,0),IF($B$1="CZ04",VLOOKUP(CECCZ&$A$1&$G$2&$H$2&$C42,CZ04TempReset,7,0),IF(CECCZ="CZ12",VLOOKUP(CECCZ&$A$1&$G$2&$H$2&$C42,CZ12TempReset,7,0),IF(CECCZ="CZ13",VLOOKUP(CECCZ&$A$1&$G$2&$H$2&$C42,CZ13TempReset,7,0))))) -> 0.1920332 | H42: =IF($B$1="CZ03",VLOOKUP(CECCZ&$A$1&$G$2&$H$2&$C42,CZ03TempReset,8,0),IF($B$1="CZ04",VLOOKUP(CECCZ&$A$1&$G$2&$H$2&$C42,CZ04TempReset,8,0),IF(CECCZ="CZ12",VLOOKUP(CECCZ&$A$1&$G$2&$H$2&$C42,CZ12TempReset,8,0),IF(CECCZ="CZ13",VLOOKUP(CECCZ&$A$1&$G$2&$H$2&$C42,CZ13TempReset,8,0))))) -> -4.7190127 | I42: =(E42*G42+H42)/100 -> 0.091341882 | J42: =D42*I42 -> 21.456732
B43: =CSSB!$L$5 -> 3 | C43: 2 | D43: =CSSB!$N$5 -> 234.90573 | E43: =CSSB!$M$5 -> 72.139614 | F43: =IF(E43<75,1,IF(AND(E43>=75, E43<95),2,IF(E43>=95,3))) -> 1 | G43: =IF($B$1="CZ03",VLOOKUP(CECCZ&$A$1&$G$2&$H$2&$C43,CZ03TempReset,7,0),IF($B$1="CZ04",VLOOKUP(CECCZ&$A$1&$G$2&$H$2&$C43,CZ04TempReset,7,0),IF(CECCZ="CZ12",VLOOKUP(CECCZ&$A$1&$G$2&$H$2&$C43,CZ12TempReset,7,0),IF(CECCZ="CZ13",VLOOKUP(CECCZ&$A$1&$G$2&$H$2&$C43,CZ13TempReset,7,0))))) -> 0.021673981 | H43: =IF($B$1="CZ03",VLOOKUP(CECCZ&$A$1&$G$2&$H$2&$C43,CZ03TempReset,8,0),IF($B$1="CZ04",VLOOKUP(CECCZ&$A$1&$G$2&$H$2&$C43,CZ04TempReset,8,0),IF(CECCZ="CZ12",VLOOKUP(CECCZ&$A$1&$G$2&$H$2&$C43,CZ12TempReset,8,0),IF(CECCZ="CZ13",VLOOKUP(CECCZ&$A$1&$G$2&$H$2&$C43,CZ13TempReset,8,0))))) -> 9.8639142 | I43: =(E43*G43+H43)/100 -> 0.11427467 | J43: =D43*I43 -> 26.843775
B44: =CSSB!$L$5 -> 3 | C44: 2 | D44: =CSSB!$N$5 -> 234.90573 | E44: =CSSB!$M$5 -> 72.139614 | F44: =IF(E44<75,1,IF(AND(E44>=75, E44<95),2,IF(E44>=95,3))) -> 1 | G44: =IF($B$1="CZ03",VLOOKUP(CECCZ&$A$1&$G$2&$H$2&$C44,CZ03TempReset,7,0),IF($B$1="CZ04",VLOOKUP(CECCZ&$A$1&$G$2&$H$2&$C44,CZ04TempReset,7,0),IF(CECCZ="CZ12",VLOOKUP(CECCZ&$A$1&$G$2&$H$2&$C44,CZ12TempReset,7,0),IF(CECCZ="CZ13",VLOOKUP(CECCZ&$A$1&$G$2&$H$2&$C44,CZ13TempReset,7,0))))) -> 0.021673981 | H44: =IF($B$1="CZ03",VLOOKUP(CECCZ&$A$1&$G$2&$H$2&$C44,CZ03TempReset,8,0),IF($B$1="CZ04",VLOOKUP(CECCZ&$A$1&$G$2&$H$2&$C44,CZ04TempReset,8,0),IF(CECCZ="CZ12",VLOOKUP(CECCZ&$A$1&$G$2&$H$2&$C44,CZ12TempReset,8,0),IF(CECCZ="CZ13",VLOOKUP(CECCZ&$A$1&$G$2&$H$2&$C44,CZ13TempReset,8,0))))) -> 9.8639142 | I44: =(E44*G44+H44)/100 -> 0.11427467 | J44: =D44*I44 -> 26.843775
B45: =CSSB!$L$5 -> 3 | C45: 2 | D45: =CSSB!$N$5 -> 234.90573 | E45: =CSSB!$M$5 -> 72.139614 | F45: =IF(E45<75,1,IF(AND(E45>=75, E45<95),2,IF(E45>=95,3))) -> 1 | G45: =IF($B$1="CZ03",VLOOKUP(CECCZ&$A$1&$G$2&$H$2&$C45,CZ03TempReset,7,0),IF($B$1="CZ04",VLOOKUP(CECCZ&$A$1&$G$2&$H$2&$C45,CZ04TempReset,7,0),IF(CECCZ="CZ12",VLOOKUP(CECCZ&$A$1&$G$2&$H$2&$C45,CZ12TempReset,7,0),IF(CECCZ="CZ13",VLOOKUP(CECCZ&$A$1&$G$2&$H$2&$C45,CZ13TempReset,7,0))))) -> 0.021673981 | H45: =IF($B$1="CZ03",VLOOKUP(CECCZ&$A$1&$G$2&$H$2&$C45,CZ03TempReset,8,0),IF($B$1="CZ04",VLOOKUP(CECCZ&$A$1&$G$2&$H$2&$C45,CZ04TempReset,8,0),IF(CECCZ="CZ12",VLOOKUP(CECCZ&$A$1&$G$2&$H$2&$C45,CZ12TempReset,8,0),IF(CECCZ="CZ13",VLOOKUP(CECCZ&$A$1&$G$2&$H$2&$C45,CZ13TempReset,8,0))))) -> 9.8639142 | I45: =(E45*G45+H45)/100 -> 0.11427467 | J45: =D45*I45 -> 26.843775
B46: =CSSB!$L$5 -> 3 | C46: 2 | D46: =CSSB!$N$5 -> 234.90573 | E46: =CSSB!$M$5 -> 72.139614 | F46: =IF(E46<75,1,IF(AND(E46>=75, E46<95),2,IF(E46>=95,3))) -> 1 | G46: =IF($B$1="CZ03",VLOOKUP(CECCZ&$A$1&$G$2&$H$2&$C46,CZ03TempReset,7,0),IF($B$1="CZ04",VLOOKUP(CECCZ&$A$1&$G$2&$H$2&$C46,CZ04TempReset,7,0),IF(CECCZ="CZ12",VLOOKUP(CECCZ&$A$1&$G$2&$H$2&$C46,CZ12TempReset,7,0),IF(CECCZ="CZ13",VLOOKUP(CECCZ&$A$1&$G$2&$H$2&$C46,CZ13TempReset,7,0))))) -> 0.021673981 | H46: =IF($B$1="CZ03",VLOOKUP(CECCZ&$A$1&$G$2&$H$2&$C46,CZ03TempReset,8,0),IF($B$1="CZ04",VLOOKUP(CECCZ&$A$1&$G$2&$H$2&$C46,CZ04TempReset,8,0),IF(CECCZ="CZ12",VLOOKUP(CECCZ&$A$1&$G$2&$H$2&$C46,CZ12TempReset,8,0),IF(CECCZ="CZ13",VLOOKUP(CECCZ&$A$1&$G$2&$H$2&$C46,CZ13TempReset,8,0))))) -> 9.8639142 | I46: =(E46*G46+H46)/100 -> 0.11427467 | J46: =D46*I46 -> 26.843775
B47: =CSSB!$L$5 -> 3 | C47: 3 | D47: =CSSB!$N$5 -> 234.90573 | E47: =CSSB!$M$5 -> 72.139614 | F47: =IF(E47<75,1,IF(AND(E47>=75, E47<95),2,IF(E47>=95,3))) -> 1 | G47: =IF($B$1="CZ03",VLOOKUP(CECCZ&$A$1&$G$2&$H$2&$C47,CZ03TempReset,7,0),IF($B$1="CZ04",VLOOKUP(CECCZ&$A$1&$G$2&$H$2&$C47,CZ04TempReset,7,0),IF(CECCZ="CZ12",VLOOKUP(CECCZ&$A$1&$G$2&$H$2&$C47,CZ12TempReset,7,0),IF(CECCZ="CZ13",VLOOKUP(CECCZ&$A$1&$G$2&$H$2&$C47,CZ13TempReset,7,0))))) -> -0.011327212 | H47: =IF($B$1="CZ03",VLOOKUP(CECCZ&$A$1&$G$2&$H$2&$C47,CZ03TempReset,8,0),IF($B$1="CZ04",VLOOKUP(CECCZ&$A$1&$G$2&$H$2&$C47,CZ04TempReset,8,0),IF(CECCZ="CZ12",VLOOKUP(CECCZ&$A$1&$G$2&$H$2&$C47,CZ12TempReset,8,0),IF(CECCZ="CZ13",VLOOKUP(CECCZ&$A$1&$G$2&$H$2&$C47,CZ13TempReset,8,0))))) -> 12.447046 | I47: =(E47*G47+H47)/100 -> 0.11629905 | J47: =D47*I47 -> 27.319314
